Workbook

Sheet Note
A1: ชื่อสถานศึกษา | B1: วิทยาลัยการอาชีพแม่สะเรียง
A2: ปีงบประมาณ | B2: 2565

Sheet ประมาณการายจ่าย
D1: ประมาณการรายจ่าย ปีงบประมาณ | F1: =Note!$B$2 -> 2565 | G1: =Note!$B$1 -> วิทยาลัยการอาชีพแม่สะเรียง
D2: เงินงบประมาณ | G2: เงินอุดหนุน | M2: งบรายจ่ายอื่น | N2: เงิน บกศ. | P2: รวม
D3: ปวช. | E3: ปวส. | F3: ระยะสั้น | G3: อุดหนุน | H3: หนังสือ | I3: เครื่องแบบ | J3: กิจกรรม | K3: อุปกรณ์ | L3: เครื่องมือ | M3: โครงการ | N3: เงินรายได้ | O3: เงินรับฝาก
C4: รับมา | P4: =SUM(D4:O4) -> 0
C5: จัดสรรไป | D5: =SUM(D9:D120) -> 0 | E5: =SUM(E9:E120) -> 0 | F5: =SUM(F9:F120) -> 0 | G5: =SUM(G9:G120) -> 0 | H5: =SUM(H9:H120) -> 0 | I5: =SUM(I9:I120) -> 0 | J5: =SUM(J9:J120) -> 0 | K5: =SUM(K9:K120) -> 0 | ... O5: =SUM(O9:O120) -> 0 | P5: =SUM(D5:O5) -> 0
C6: คงเหลือ | D6: =D4-D5 -> 0 | E6: =E4-E5 -> 0 | F6: =F4-F5 -> 0 | G6: =G4-G5 -> 0 | H6: =H4-H5 -> 0 | I6: =I4-I5 -> 0 | J6: =J4-J5 -> 0 | K6: =K4-K5 -> 0 | ... P6: =P4-P5 -> 0
D8: ปวช. | E8: ปวส. | F8: ระยะสั้น | G8: อุดหนุน | H8: หนังสือ | I8: เครื่องแบบ | J8: กิจกรรม | K8: อุปกรณ์ | L8: เครื่องมือ | M8: โครงการ | N8: เงินรายได้ | O8: เงินรับฝาก | P8: รวม
A9: 1. งบบุคลากร
A10: =Note!$B$2 -> 2565 | B10: 101 | C10: เงินเดือนพนักงานราชการ
A11: =Note!$B$2 -> 2565 | B11: 102
A12: =Note!$B$2 -> 2565 | B12: 103
A13: =Note!$B$2 -> 2565 | B13: 104
A14: =Note!$B$2 -> 2565 | B14: 105
A15: 2. งบดำเนินงาน (ค่าตอบแทน)
A16: =Note!$B$2 -> 2565 | B16: 201 | C16: ค่าตอบแทนพิเศษพนักงานราชการ
A17: =Note!$B$2 -> 2565 | B17: 202 | C17: ค่าสอนเกินภาระงาน
A18: =Note!$B$2 -> 2565 | B18: 203 | C18: ค่าธุรการนอกเวลา
A19: =Note!$B$2 -> 2565 | B19: 204 | C19: ค่าสอนภาคฤดูร้อน
A20: =Note!$B$2 -> 2565 | B20: 205 | C20: ค่าสอนเทียบโอน
A21: =Note!$B$2 -> 2565 | B21: 206 | C21: ค่าจ้างครูรายเดือน
A22: =Note!$B$2 -> 2565 | B22: 207 | C22: ค่าจ้างเจ้าหน้าที่รายเดือน
A23: =Note!$B$2 -> 2565 | B23: 208 | C23: ค่าครองชีพครูรายเดือน
A24: =Note!$B$2 -> 2565 | B24: 209 | C24: ค่าครองชีพเจ้าหน้าที่รายเดือน
A25: =Note!$B$2 -> 2565 | B25: 210
A26: =Note!$B$2 -> 2565 | B26: 211
A27: =Note!$B$2 -> 2565 | B27: 212
A28: =Note!$B$2 -> 2565 | B28: 213
A29: =Note!$B$2 -> 2565 | B29: 214
A30: 3. งบดำเนินงาน (ค่าใช้สอย)
A31: =Note!$B$2 -> 2565 | B31: 301 | C31: ค่าจ้างซ่อมครุภัณฑ์การศึกษาและสำนักงาน
A32: =Note!$B$2 -> 2565 | B32: 302 | C32: ค่าซ่อมยานพาหนะ
A33: =Note!$B$2 -> 2565 | B33: 303 | C33: ค่าจ้างติดตั้ง ซ่อมแซมระบบสาธารณูปโภค
A34: =Note!$B$2 -> 2565 | B34: 304 | C34: ค่าจ้างซ่อมอาคารสถานที่/พัฒนาสิ่งแวดล้อม
A35: =Note!$B$2 -> 2565 | B35: 305 | C35: ค่าเบี้ยเลี้ยง พาหนะเดิอนทาง และที่พัก
A36: =Note!$B$2 -> 2565 | B36: 306 | C36: ค่าสมทบประกันสังคม(พนักงานราชการ)
A37: =Note!$B$2 -> 2565 | B37: 307 | C37: ค่าสมทบประกันสังคม(ครูรายเดือน)
A38: =Note!$B$2 -> 2565 | B38: 308 | C38: ค่าสมทบประกันสังคม(เจ้าหน้าที่รายเดือน)
A39: =Note!$B$2 -> 2565 | B39: 309 | C39: ค่าใช้สอยอื่นๆ(ไม่เกิน50,000/ครั้ง/รายการ)
A40: =Note!$B$2 -> 2565 | B40: 310
A41: =Note!$B$2 -> 2565 | B41: 311
...

Sheet งปม.เข้า
E1: รายการรายรับ ปีงบประมาณ | G1: =Note!$B$2 -> 2565 | H1: =Note!$B$1 -> วิทยาลัยการอาชีพแม่สะเรียง
E2: เงินงบประมาณ | H2: เงินอุดหนุน | N2: งบรายจ่ายอื่น | O2: เงิน บกศ. | Q2: รวม
E3: ปวช. | F3: ปวส. | G3: ระยะสั้น | H3: อุดหนุน | I3: หนังสือ | J3: เครื่องแบบ | K3: กิจกรรม | L3: อุปกรณ์ | M3: เครื่องมือ | N3: โครงการ | O3: เงินรายได้ | P3: เงินรับฝาก
D4: รวมรายรับ | E4: =SUM(E7:E106) -> 1284440 | F4: =SUM(F7:F106) -> 316100 | G4: =SUM(G7:G106) -> 81600 | H4: =SUM(H7:H106) -> 1731550 | I4: =SUM(I7:I106) -> 551000 | J4: =SUM(J7:J106) -> 0 | K4: =SUM(K7:K106) -> 261725 | L4: =SUM(L7:L106) -> 126730 | ... P4: =SUM(P7:P106) -> 0 | Q4: =SUM(E4:P4) -> 4563745
A6: ลำดับ | B6: วันที่ เดือน พ.ศ. | C6: เอกสารการจัดสรร | D6: รหัสเอกสาร | E6: ปวช. | F6: ปวส. | G6: ระยะสั้น | H6: อุดหนุน | I6: หนังสือ | J6: เครื่องแบบ | K6: กิจกรรม | L6: อุปกรณ์ | M6: เครื่องมือ | N6: โครงการ | O6: เงินรายได้ | P6: เงินรับฝาก | Q6: รวม
A7: 1 | B7: 3 ตุลาคม 2565 | C7: งบประมาณ ปวช. | D7: 2566001 | E7: 168400 | Q7: =SUM(E7:P7) -> 168400
A8: 2 | B8: ธันวาคม 2564 | C8: งบกิจกรรมพัฒนาผู้เรียน | K8: 261725 | Q8: =SUM(E8:P8) -> 261725
A9: 3 | B9: ธันวาคม 2564 | C9: งบค่าจัดการเรียนการสอน | H9: 1731550 | Q9: =SUM(E9:P9) -> 1731550
A10: 4 | B10: ธันวาคม 2564 | C10: งบค่าหนังสือเรียน | I10: 551000 | Q10: =SUM(E10:P10) -> 551000
A11: 5 | B11: ธันวาคม 2564 | C11: งบค่าอุปกรณ์การเรียน | L11: 126730 | Q11: =SUM(E11:P11) -> 126730
A12: 6 | B12: 24 พ.ย. 64 | C12: งบประมาณ ปวส. | F12: 316100 | Q12: =SUM(E12:P12) -> 316100
A13: 7 | B13: 24 พ.ย. 64 | C13: งบประมาณ ระยะสั้น | G13: 81600 | Q13: =SUM(E13:P13) -> 81600
A14: 8 | B14: 24 พ.ย. 64 | C14: งบประมาณ ค่าสาธารณูปโภค | E14: 240000 | Q14: =SUM(E14:P14) -> 240000
A15: 9 | B15: 20 ต.ค. 64 | C15: ค่าตอบแทนพนักงานราชการ | E15: 844350 | Q15: =SUM(E15:P15) -> 844350
A16: 10 | B16: 3 พ.ย. 64 | C16: ประกันสังคมพนักงานราชการ | E16: 31690 | Q16: =SUM(E16:P16) -> 31690
A17: 11 | B17: กุมภาพันธ์ 2565 | C17: โครงการเร่งประสิทธิภาพการสอนฯ | N17: 94800 | Q17: =SUM(E17:P17) -> 94800
A18: 12 | B18: กุมภาพันธ์ 2565 | C18: โครงการจัดหาบุคลากรสนับสนุนเพื่อคืนครูฯ | N18: 58800 | Q18: =SUM(E18:P18) -> 58800
A19: 13 | B19: ธันวาคม 2564 | C19: กิจกรรมอาชีวะอาสา ร่วมด้วยช่วยประชาชน | N19: 41000 | Q19: =SUM(E19:P19) -> 41000
A20: 14 | B20: มกราคม 65 | C20: โครงการอนุรักษ์พันธุกรรมพืชฯ | N20: 16000 | Q20: =SUM(E20:P20) -> 16000
A21: 15 | Q21: =SUM(E21:P21) -> 0
A22: 16 | Q22: =SUM(E22:P22) -> 0
A23: 17 | Q23: =SUM(E23:P23) -> 0
A24: 18 | Q24: =SUM(E24:P24) -> 0
A25: 19 | Q25: =SUM(E25:P25) -> 0
A26: 20 | Q26: =SUM(E26:P26) -> 0
A27: 21 | Q27: =SUM(E27:P27) -> 0
A28: 22 | Q28: =SUM(E28:P28) -> 0
A29: 23 | Q29: =SUM(E29:P29) -> 0
A30: 24 | Q30: =SUM(E30:P30) -> 0
A31: 25 | Q31: =SUM(E31:P31) -> 0
A32: 26 | Q32: =SUM(E32:P32) -> 0
... A106: 100 | Q106: =SUM(E106:P106) -> 0

Sheet จัดสรร งปม.
D1: รายการจัดสรรรายจ่ายปี งปม. | F1: =Note!$B$2 -> 2565 | G1: =Note!$B$1 -> วิทยาลัยการอาชีพแม่สะเรียง
D2: เงินงบประมาณ | G2: เงินอุดหนุน | M2: งบรายจ่ายอื่น | N2: เงิน บกศ. | P2: รวม | Q2: =NOW() -> 46006.466
D3: ปวช. | E3: ปวส. | F3: ระยะสั้น | G3: อุดหนุน | H3: หนังสือ | I3: เครื่องแบบ | J3: กิจกรรม | K3: อุปกรณ์ | L3: เครื่องมือ | M3: โครงการ | N3: เงินรายได้ | O3: เงินรับฝาก | Q3: สรุปรายการจ่ายจากยอดจัดสสร
C4: รับมา | D4: =งปม.เข้า!E4 -> 1284440 | E4: =งปม.เข้า!F4 -> 316100 | F4: =งปม.เข้า!G4 -> 81600 | G4: =งปม.เข้า!H4 -> 1731550 | H4: =งปม.เข้า!I4 -> 551000 | I4: =งปม.เข้า!J4 -> 0 | J4: =งปม.เข้า!K4 -> 261725 | K4: =งปม.เข้า!L4 -> 126730 | ... O4: =งปม.เข้า!P4 -> 0 | P4: =SUM(D4:O4) -> 4563745 | Q4: ใช้ไปแล้ว | R4: ร้อยละ | S4: เหลือ
C5: จัดสรรไป | D5: =SUM(D9:D120) -> 19685 | E5: =SUM(E9:E120) -> 0 | F5: =SUM(F9:F120) -> 0 | G5: =SUM(G9:G120) -> 0 | H5: =SUM(H9:H120) -> 0 | I5: =SUM(I9:I120) -> 0 | J5: =SUM(J9:J120) -> 0 | K5: =SUM(K9:K120) -> 0 | ... O5: =SUM(O9:O120) -> 0 | P5: =SUM(D5:O5) -> 19685 | Q5: =SUM(Q10:Q120) -> 4317 | R5: =(100/P5)*Q5 -> 21.930404 | S5: =SUM(S10:S120) -> 15368
C6: คงเหลือ | D6: =D4-D5 -> 1264755 | E6: =E4-E5 -> 316100 | F6: =F4-F5 -> 81600 | G6: =G4-G5 -> 1731550 | H6: =H4-H5 -> 551000 | I6: =I4-I5 -> 0 | J6: =J4-J5 -> 261725 | K6: =K4-K5 -> 126730 | ... P6: =P4-P5 -> 4544060
D8: ปวช. | E8: ปวส. | F8: ระยะสั้น | G8: อุดหนุน | H8: หนังสือ | I8: เครื่องแบบ | J8: กิจกรรม | K8: อุปกรณ์ | L8: เครื่องมือ | M8: โครงการ | N8: เงินรายได้ | O8: เงินรับฝาก | P8: รวม | Q8: ใช้ไปแล้ว | R8: ร้อยละ | S8: เหลือ
A9: 1. งบบุคลากร
A10: =Note!$B$2 -> 2565 | B10: 101 | C10: เงินเดือนพนักงานราชการ | D10: 1000 | P10: =SUM(D10:O10) -> 1000 | Q10: ='101'!$Q$6 -> 500 | R10: =(100/P10)*Q10 -> 50 | S10: =P10-Q10 -> 500
A11: =Note!$B$2 -> 2565 | B11: 102 | C11: สำรอง 1 | D11: 1000 | P11: =SUM(D11:O11) -> 1000 | Q11: ='102'!$Q$6 -> 250 | R11: =(100/P11)*Q11 -> 25 | S11: =P11-Q11 -> 750
A12: =Note!$B$2 -> 2565 | B12: 103 | C12: สำรอง 2 | D12: 1010 | P12: =SUM(D12:O12) -> 1010 | Q12: ='103'!$Q$6 -> 50 | R12: =(100/P12)*Q12 -> 4.950495 | S12: =P12-Q12 -> 960
A13: =Note!$B$2 -> 2565 | B13: 104 | C13: สำรอง 3 | D13: 1000 | P13: =SUM(D13:O13) -> 1000 | Q13: ='104'!$Q$6 -> 150 | R13: =(100/P13)*Q13 -> 15 | S13: =P13-Q13 -> 850
A14: =Note!$B$2 -> 2565 | B14: 105 | C14: สำรอง 4 | D14: 1000 | P14: =SUM(D14:O14) -> 1000 | Q14: ='105'!$Q$6 -> 120 | R14: =(100/P14)*Q14 -> 12 | S14: =P14-Q14 -> 880
A15: 2. งบดำเนินงาน (ค่าตอบแทน)
A16: =Note!$B$2 -> 2565 | B16: 201 | C16: ค่าตอบแทนพิเศษพนักงานราชการ | D16: 110 | P16: =SUM(D16:O16) -> 110 | Q16: ='201'!$Q$6 -> 35 | R16: =(100/P16)*Q16 -> 31.818182 | S16: =P16-Q16 -> 75
A17: =Note!$B$2 -> 2565 | B17: 202 | C17: ค่าสอนเกินภาระงาน | D17: 120 | P17: =SUM(D17:O17) -> 120 | Q17: ='202'!$Q$6 -> 40 | R17: =(100/P17)*Q17 -> 33.333333 | S17: =P17-Q17 -> 80
A18: =Note!$B$2 -> 2565 | B18: 203 | C18: ค่าธุรการนอกเวลา | D18: 130 | P18: =SUM(D18:O18) -> 130 | Q18: ='203'!$Q$6 -> 32 | R18: =(100/P18)*Q18 -> 24.615385 | S18: =P18-Q18 -> 98
A19: =Note!$B$2 -> 2565 | B19: 204 | C19: ค่าสอนภาคฤดูร้อน | D19: 140 | P19: =SUM(D19:O19) -> 140 | Q19: ='204'!$Q$6 -> 33 | R19: =(100/P19)*Q19 -> 23.571429 | S19: =P19-Q19 -> 107
A20: =Note!$B$2 -> 2565 | B20: 205 | C20: ค่าสอนเทียบโอน | D20: 150 | P20: =SUM(D20:O20) -> 150 | Q20: ='205'!$Q$6 -> 32 | R20: =(100/P20)*Q20 -> 21.333333 | S20: =P20-Q20 -> 118
A21: =Note!$B$2 -> 2565 | B21: 206 | C21: ค่าจ้างครูรายเดือน | D21: 160 | P21: =SUM(D21:O21) -> 160 | Q21: ='206'!$Q$6 -> 30 | R21: =(100/P21)*Q21 -> 18.75 | S21: =P21-Q21 -> 130
A22: =Note!$B$2 -> 2565 | B22: 207 | C22: ค่าจ้างเจ้าหน้าที่รายเดือน | D22: 170 | P22: =SUM(D22:O22) -> 170 | Q22: ='207'!$Q$6 -> 70 | R22: =(100/P22)*Q22 -> 41.176471 | S22: =P22-Q22 -> 100
A23: =Note!$B$2 -> 2565 | B23: 208 | C23: ค่าครองชีพครูรายเดือน | D23: 180 | P23: =SUM(D23:O23) -> 180 | Q23: ='208'!$Q$6 -> 80 | R23: =(100/P23)*Q23 -> 44.444444 | S23: =P23-Q23 -> 100
A24: =Note!$B$2 -> 2565 | B24: 209 | C24: ค่าครองชีพเจ้าหน้าที่รายเดือน | D24: 190 | P24: =SUM(D24:O24) -> 190 | Q24: ='209'!$Q$6 -> 90 | R24: =(100/P24)*Q24 -> 47.368421 | S24: =P24-Q24 -> 100
A25: =Note!$B$2 -> 2565 | B25: 210 | C25: สำรอง 1 | D25: 200 | P25: =SUM(D25:O25) -> 200 | Q25: ='210'!$Q$6 -> 50 | R25: =(100/P25)*Q25 -> 25 | S25: =P25-Q25 -> 150
A26: =Note!$B$2 -> 2565 | B26: 211 | C26: สำรอง 2 | D26: 210 | P26: =SUM(D26:O26) -> 210 | Q26: ='211'!$Q$6 -> 10 | R26: =(100/P26)*Q26 -> 4.7619048 | S26: =P26-Q26 -> 200
A27: =Note!$B$2 -> 2565 | B27: 212 | C27: สำรอง 3 | D27: 220 | P27: =SUM(D27:O27) -> 220 | Q27: ='212'!$Q$6 -> 20 | R27: =(100/P27)*Q27 -> 9.0909091 | S27: =P27-Q27 -> 200
A28: =Note!$B$2 -> 2565 | B28: 213 | C28: สำรอง 4 | D28: 230 | P28: =SUM(D28:O28) -> 230 | Q28: ='213'!$Q$6 -> 30 | R28: =(100/P28)*Q28 -> 13.043478 | S28: =P28-Q28 -> 200
A29: =Note!$B$2 -> 2565 | B29: 214 | C29: สำรอง 5 | D29: 240 | P29: =SUM(D29:O29) -> 240 | Q29: ='214'!$Q$6 -> 40 | R29: =(100/P29)*Q29 -> 16.666667 | S29: =P29-Q29 -> 200
A30: 3. งบดำเนินงาน (ค่าใช้สอย)
A31: =Note!$B$2 -> 2565 | B31: 301 | C31: ค่าจ้างซ่อมครุภัณฑ์การศึกษาและสำนักงาน | D31: 110 | P31: =SUM(D31:O31) -> 110 | Q31: ='301'!$Q$6 -> 10 | R31: =(100/P31)*Q31 -> 9.0909091 | S31: =P31-Q31 -> 100
A32: =Note!$B$2 -> 2565 | B32: 302 | C32: ค่าซ่อมยานพาหนะ | D32: 120 | P32: =SUM(D32:O32) -> 120 | Q32: ='302'!$Q$6 -> 20 | R32: =(100/P32)*Q32 -> 16.666667 | S32: =P32-Q32 -> 100
A33: =Note!$B$2 -> 2565 | B33: 303 | C33: ค่าจ้างติดตั้ง ซ่อมแซมระบบสาธารณูปโภค | D33: 130 | P33: =SUM(D33:O33) -> 130 | Q33: ='303'!$Q$6 -> 30 | R33: =(100/P33)*Q33 -> 23.076923 | S33: =P33-Q33 -> 100
A34: =Note!$B$2 -> 2565 | B34: 304 | C34: ค่าจ้างซ่อมอาคารสถานที่/พัฒนาสิ่งแวดล้อม | D34: 140 | P34: =SUM(D34:O34) -> 140 | Q34: ='304'!$Q$6 -> 40 | R34: =(100/P34)*Q34 -> 28.571429 | S34: =P34-Q34 -> 100
A35: =Note!$B$2 -> 2565 | B35: 305 | C35: ค่าเบี้ยเลี้ยง พาหนะเดิอนทาง และที่พัก | D35: 150 | P35: =SUM(D35:O35) -> 150 | Q35: ='305'!$Q$6 -> 50 | R35: =(100/P35)*Q35 -> 33.333333 | S35: =P35-Q35 -> 100
A36: =Note!$B$2 -> 2565 | B36: 306 | C36: ค่าสมทบประกันสังคม(พนักงานราชการ) | D36: 160 | P36: =SUM(D36:O36) -> 160 | Q36: ='306'!$Q$6 -> 60 | R36: =(100/P36)*Q36 -> 37.5 | S36: =P36-Q36 -> 100
A37: =Note!$B$2 -> 2565 | B37: 307 | C37: ค่าสมทบประกันสังคม(ครูรายเดือน) | D37: 170 | P37: =SUM(D37:O37) -> 170 | Q37: ='307'!$Q$6 -> 70 | R37: =(100/P37)*Q37 -> 41.176471 | S37: =P37-Q37 -> 100
A38: =Note!$B$2 -> 2565 | B38: 308 | C38: ค่าสมทบประกันสังคม(เจ้าหน้าที่รายเดือน) | D38: 180 | P38: =SUM(D38:O38) -> 180 | Q38: ='308'!$Q$6 -> 80 | R38: =(100/P38)*Q38 -> 44.444444 | S38: =P38-Q38 -> 100
A39: =Note!$B$2 -> 2565 | B39: 309 | C39: ค่าใช้สอยอื่นๆ(ไม่เกิน50,000/ครั้ง/รายการ) | D39: 190 | P39: =SUM(D39:O39) -> 190 | Q39: ='309'!$Q$6 -> 90 | R39: =(100/P39)*Q39 -> 47.368421 | S39: =P39-Q39 -> 100
A40: =Note!$B$2 -> 2565 | B40: 310 | C40: สำรอง 1 | D40: 200 | P40: =SUM(D40:O40) -> 200 | Q40: ='310'!$Q$6 -> 50 | R40: =(100/P40)*Q40 -> 25 | S40: =P40-Q40 -> 150
A41: =Note!$B$2 -> 2565 | B41: 311 | C41: สำรอง 2 | D41: 210 | P41: =SUM(D41:O41) -> 210 | Q41: ='311'!$Q$6 -> 10 | R41: =(100/P41)*Q41 -> 4.7619048 | S41: =P41-Q41 -> 200
...

Sheet 101
A1: กลับไปที่หน้าจัดสรร งปม.
E2: =Note!$B$1 -> วิทยาลัยการอาชีพแม่สะเรียง
E3: เงินงบประมาณ | H3: เงินอุดหนุน | N3: งบรายจ่ายอื่น | O3: เงิน บกศ. | Q3: รวม
E4: ปวช. | F4: ปวส. | G4: ระยะสั้น | H4: อุดหนุน | I4: หนังสือ | J4: เครื่องแบบ | K4: กิจกรรม | L4: อุปกรณ์ | M4: เครื่องมือ | N4: โครงการ | O4: เงินรายได้ | P4: เงินรับฝาก
D5: ได้รับมา | E5: ='จัดสรร งปม.'!D10 -> 1000 | F5: ='จัดสรร งปม.'!E10 -> 0 | G5: ='จัดสรร งปม.'!F10 -> 0 | H5: ='จัดสรร งปม.'!G10 -> 0 | I5: ='จัดสรร งปม.'!H10 -> 0 | J5: ='จัดสรร งปม.'!I10 -> 0 | K5: ='จัดสรร งปม.'!J10 -> 0 | L5: ='จัดสรร งปม.'!K10 -> 0 | ... Q5: ='จัดสรร งปม.'!P10 -> 1000
D6: ใช้ไปแล้ว | E6: =SUM(E11:E45) -> 500 | F6: =SUM(F11:F45) -> 0 | G6: =SUM(G11:G45) -> 0 | H6: =SUM(H11:H45) -> 0 | I6: =SUM(I11:I45) -> 0 | J6: =SUM(J11:J45) -> 0 | K6: =SUM(K11:K45) -> 0 | L6: =SUM(L11:L45) -> 0 | ... Q6: =SUM(Q11:Q45) -> 500
B7: งบบุคลากร | D7: เหลือ | E7: =E5-E6 -> 500 | F7: =F5-F6 -> 0 | G7: =G5-G6 -> 0 | H7: =H5-H6 -> 0 | I7: =I5-I6 -> 0 | J7: =J5-J6 -> 0 | K7: =K5-K6 -> 0 | L7: =L5-L6 -> 0 | ... Q7: =Q5-Q6 -> 500
B8: รหัสรายการจ่าย | C8: ='จัดสรร งปม.'!$B$10 -> 101
B9: รายการจ่าย | C9: ='จัดสรร งปม.'!$C$10 -> เงินเดือนพนักงานราชการ
A10: รหัส | B10: วันที่ | C10: ชื่อผู้ขอใช้ | D10: แผนก/งาน | E10: ปวช. | F10: ปวส. | G10: ระยะสั้น | H10: อุดหนุน | I10: หนังสือ | J10: เครื่องแบบ | K10: กิจกรรม | L10: อุปกรณ์ | M10: เครื่องมือ | N10: โครงการ | O10: เงินรายได้ | P10: เงินรับฝาก | Q10: รวม
A11: 001 | B11: 1 ตุลาคม 2565 | E11: 500 | Q11: =SUM(E11:P11) -> 500
A12: 002 | Q12: =SUM(E12:P12) -> 0
A13: 003 | Q13: =SUM(E13:P13) -> 0
A14: 004 | Q14: =SUM(E14:P14) -> 0
A15: 005 | Q15: =SUM(E15:P15) -> 0
A16: 006 | Q16: =SUM(E16:P16) -> 0
A17: 007 | Q17: =SUM(E17:P17) -> 0
A18: 008 | Q18: =SUM(E18:P18) -> 0
A19: 009 | Q19: =SUM(E19:P19) -> 0
A20: 010 | Q20: =SUM(E20:P20) -> 0
A21: 011 | Q21: =SUM(E21:P21) -> 0
A22: 012 | Q22: =SUM(E22:P22) -> 0
A23: 013 | Q23: =SUM(E23:P23) -> 0
... A45: 035 | Q45: =SUM(E45:P45) -> 0

Sheet 102
A1: กลับไปที่หน้าจัดสรร งปม.
E2: =Note!$B$1 -> วิทยาลัยการอาชีพแม่สะเรียง
E3: เงินงบประมาณ | H3: เงินอุดหนุน | N3: งบรายจ่ายอื่น | O3: เงิน บกศ. | Q3: รวม
E4: ปวช. | F4: ปวส. | G4: ระยะสั้น | H4: อุดหนุน | I4: หนังสือ | J4: เครื่องแบบ | K4: กิจกรรม | L4: อุปกรณ์ | M4: เครื่องมือ | N4: โครงการ | O4: เงินรายได้ | P4: เงินรับฝาก
D5: ได้รับมา | E5: ='จัดสรร งปม.'!D11 -> 1000 | F5: ='จัดสรร งปม.'!E11 -> 0 | G5: ='จัดสรร งปม.'!F11 -> 0 | H5: ='จัดสรร งปม.'!G11 -> 0 | I5: ='จัดสรร งปม.'!H11 -> 0 | J5: ='จัดสรร งปม.'!I11 -> 0 | K5: ='จัดสรร งปม.'!J11 -> 0 | L5: ='จัดสรร งปม.'!K11 -> 0 | ... Q5: ='จัดสรร งปม.'!P11 -> 1000
D6: ใช้ไปแล้ว | E6: =SUM(E11:E45) -> 250 | F6: =SUM(F11:F45) -> 0 | G6: =SUM(G11:G45) -> 0 | H6: =SUM(H11:H45) -> 0 | I6: =SUM(I11:I45) -> 0 | J6: =SUM(J11:J45) -> 0 | K6: =SUM(K11:K45) -> 0 | L6: =SUM(L11:L45) -> 0 | ... Q6: =SUM(Q11:Q45) -> 250
B7: งบบุคลากร | D7: เหลือ | E7: =E5-E6 -> 750 | F7: =F5-F6 -> 0 | G7: =G5-G6 -> 0 | H7: =H5-H6 -> 0 | I7: =I5-I6 -> 0 | J7: =J5-J6 -> 0 | K7: =K5-K6 -> 0 | L7: =L5-L6 -> 0 | ... Q7: =Q5-Q6 -> 750
B8: รหัสรายการจ่าย | C8: ='จัดสรร งปม.'!$B$11 -> 102
B9: รายการจ่าย | C9: ='จัดสรร งปม.'!$C$11 -> สำรอง 1
A10: รหัส | B10: วันที่ | C10: ชื่อผู้ขอใช้ | D10: แผนก/งาน | E10: ปวช. | F10: ปวส. | G10: ระยะสั้น | H10: อุดหนุน | I10: หนังสือ | J10: เครื่องแบบ | K10: กิจกรรม | L10: อุปกรณ์ | M10: เครื่องมือ | N10: โครงการ | O10: เงินรายได้ | P10: เงินรับฝาก | Q10: รวม
A11: 001 | E11: 250 | Q11: =SUM(E11:P11) -> 250
A12: 002 | Q12: =SUM(E12:P12) -> 0
A13: 003 | Q13: =SUM(E13:P13) -> 0
A14: 004 | Q14: =SUM(E14:P14) -> 0
A15: 005 | Q15: =SUM(E15:P15) -> 0
A16: 006 | Q16: =SUM(E16:P16) -> 0
A17: 007 | Q17: =SUM(E17:P17) -> 0
A18: 008 | Q18: =SUM(E18:P18) -> 0
A19: 009 | Q19: =SUM(E19:P19) -> 0
A20: 010 | Q20: =SUM(E20:P20) -> 0
A21: 011 | Q21: =SUM(E21:P21) -> 0
A22: 012 | Q22: =SUM(E22:P22) -> 0
A23: 013 | Q23: =SUM(E23:P23) -> 0
... A45: 035 | Q45: =SUM(E45:P45) -> 0

Sheet 103
A1: กลับไปที่หน้าจัดสรร งปม.
E2: =Note!$B$1 -> วิทยาลัยการอาชีพแม่สะเรียง
E3: เงินงบประมาณ | H3: เงินอุดหนุน | N3: งบรายจ่ายอื่น | O3: เงิน บกศ. | Q3: รวม
E4: ปวช. | F4: ปวส. | G4: ระยะสั้น | H4: อุดหนุน | I4: หนังสือ | J4: เครื่องแบบ | K4: กิจกรรม | L4: อุปกรณ์ | M4: เครื่องมือ | N4: โครงการ | O4: เงินรายได้ | P4: เงินรับฝาก
D5: ได้รับมา | E5: ='จัดสรร งปม.'!D12 -> 1010 | F5: ='จัดสรร งปม.'!E12 -> 0 | G5: ='จัดสรร งปม.'!F12 -> 0 | H5: ='จัดสรร งปม.'!G12 -> 0 | I5: ='จัดสรร งปม.'!H12 -> 0 | J5: ='จัดสรร งปม.'!I12 -> 0 | K5: ='จัดสรร งปม.'!J12 -> 0 | L5: ='จัดสรร งปม.'!K12 -> 0 | ... Q5: ='จัดสรร งปม.'!P12 -> 1010
D6: ใช้ไปแล้ว | E6: =SUM(E11:E45) -> 50 | F6: =SUM(F11:F45) -> 0 | G6: =SUM(G11:G45) -> 0 | H6: =SUM(H11:H45) -> 0 | I6: =SUM(I11:I45) -> 0 | J6: =SUM(J11:J45) -> 0 | K6: =SUM(K11:K45) -> 0 | L6: =SUM(L11:L45) -> 0 | ... Q6: =SUM(Q11:Q45) -> 50
B7: งบบุคลากร | D7: เหลือ | E7: =E5-E6 -> 960 | F7: =F5-F6 -> 0 | G7: =G5-G6 -> 0 | H7: =H5-H6 -> 0 | I7: =I5-I6 -> 0 | J7: =J5-J6 -> 0 | K7: =K5-K6 -> 0 | L7: =L5-L6 -> 0 | ... Q7: =Q5-Q6 -> 960
B8: รหัสรายการจ่าย | C8: ='จัดสรร งปม.'!$B$12 -> 103
B9: รายการจ่าย | C9: ='จัดสรร งปม.'!$C$12 -> สำรอง 2
A10: รหัส | B10: วันที่ | C10: ชื่อผู้ขอใช้ | D10: แผนก/งาน | E10: ปวช. | F10: ปวส. | G10: ระยะสั้น | H10: อุดหนุน | I10: หนังสือ | J10: เครื่องแบบ | K10: กิจกรรม | L10: อุปกรณ์ | M10: เครื่องมือ | N10: โครงการ | O10: เงินรายได้ | P10: เงินรับฝาก | Q10: รวม
A11: 001 | E11: 50 | Q11: =SUM(E11:P11) -> 50
A12: 002 | Q12: =SUM(E12:P12) -> 0
A13: 003 | Q13: =SUM(E13:P13) -> 0
A14: 004 | Q14: =SUM(E14:P14) -> 0
A15: 005 | Q15: =SUM(E15:P15) -> 0
A16: 006 | Q16: =SUM(E16:P16) -> 0
A17: 007 | Q17: =SUM(E17:P17) -> 0
A18: 008 | Q18: =SUM(E18:P18) -> 0
A19: 009 | Q19: =SUM(E19:P19) -> 0
A20: 010 | Q20: =SUM(E20:P20) -> 0
A21: 011 | Q21: =SUM(E21:P21) -> 0
A22: 012 | Q22: =SUM(E22:P22) -> 0
A23: 013 | Q23: =SUM(E23:P23) -> 0
... A45: 035 | Q45: =SUM(E45:P45) -> 0

Sheet 104
A1: กลับไปที่หน้าจัดสรร งปม.
E2: =Note!$B$1 -> วิทยาลัยการอาชีพแม่สะเรียง
E3: เงินงบประมาณ | H3: เงินอุดหนุน | N3: งบรายจ่ายอื่น | O3: เงิน บกศ. | Q3: รวม
E4: ปวช. | F4: ปวส. | G4: ระยะสั้น | H4: อุดหนุน | I4: หนังสือ | J4: เครื่องแบบ | K4: กิจกรรม | L4: อุปกรณ์ | M4: เครื่องมือ | N4: โครงการ | O4: เงินรายได้ | P4: เงินรับฝาก
D5: ได้รับมา | E5: ='จัดสรร งปม.'!D13 -> 1000 | F5: ='จัดสรร งปม.'!E13 -> 0 | G5: ='จัดสรร งปม.'!F13 -> 0 | H5: ='จัดสรร งปม.'!G13 -> 0 | I5: ='จัดสรร งปม.'!H13 -> 0 | J5: ='จัดสรร งปม.'!I13 -> 0 | K5: ='จัดสรร งปม.'!J13 -> 0 | L5: ='จัดสรร งปม.'!K13 -> 0 | ... Q5: ='จัดสรร งปม.'!P13 -> 1000
D6: ใช้ไปแล้ว | E6: =SUM(E11:E45) -> 150 | F6: =SUM(F11:F45) -> 0 | G6: =SUM(G11:G45) -> 0 | H6: =SUM(H11:H45) -> 0 | I6: =SUM(I11:I45) -> 0 | J6: =SUM(J11:J45) -> 0 | K6: =SUM(K11:K45) -> 0 | L6: =SUM(L11:L45) -> 0 | ... Q6: =SUM(Q11:Q45) -> 150
B7: งบบุคลากร | D7: เหลือ | E7: =E5-E6 -> 850 | F7: =F5-F6 -> 0 | G7: =G5-G6 -> 0 | H7: =H5-H6 -> 0 | I7: =I5-I6 -> 0 | J7: =J5-J6 -> 0 | K7: =K5-K6 -> 0 | L7: =L5-L6 -> 0 | ... Q7: =Q5-Q6 -> 850
B8: รหัสรายการจ่าย | C8: ='จัดสรร งปม.'!$B$13 -> 104
B9: รายการจ่าย | C9: ='จัดสรร งปม.'!$C$13 -> สำรอง 3
A10: รหัส | B10: วันที่ | C10: ชื่อผู้ขอใช้ | D10: แผนก/งาน | E10: ปวช. | F10: ปวส. | G10: ระยะสั้น | H10: อุดหนุน | I10: หนังสือ | J10: เครื่องแบบ | K10: กิจกรรม | L10: อุปกรณ์ | M10: เครื่องมือ | N10: โครงการ | O10: เงินรายได้ | P10: เงินรับฝาก | Q10: รวม
A11: 001 | E11: 150 | Q11: =SUM(E11:P11) -> 150
A12: 002 | Q12: =SUM(E12:P12) -> 0
A13: 003 | Q13: =SUM(E13:P13) -> 0
A14: 004 | Q14: =SUM(E14:P14) -> 0
A15: 005 | Q15: =SUM(E15:P15) -> 0
A16: 006 | Q16: =SUM(E16:P16) -> 0
A17: 007 | Q17: =SUM(E17:P17) -> 0
A18: 008 | Q18: =SUM(E18:P18) -> 0
A19: 009 | Q19: =SUM(E19:P19) -> 0
A20: 010 | Q20: =SUM(E20:P20) -> 0
A21: 011 | Q21: =SUM(E21:P21) -> 0
A22: 012 | Q22: =SUM(E22:P22) -> 0
A23: 013 | Q23: =SUM(E23:P23) -> 0
... A45: 035 | Q45: =SUM(E45:P45) -> 0

Sheet 105
A1: กลับไปที่หน้าจัดสรร งปม.
E2: =Note!$B$1 -> วิทยาลัยการอาชีพแม่สะเรียง
E3: เงินงบประมาณ | H3: เงินอุดหนุน | N3: งบรายจ่ายอื่น | O3: เงิน บกศ. | Q3: รวม
E4: ปวช. | F4: ปวส. | G4: ระยะสั้น | H4: อุดหนุน | I4: หนังสือ | J4: เครื่องแบบ | K4: กิจกรรม | L4: อุปกรณ์ | M4: เครื่องมือ | N4: โครงการ | O4: เงินรายได้ | P4: เงินรับฝาก
D5: ได้รับมา | E5: ='จัดสรร งปม.'!D14 -> 1000 | F5: ='จัดสรร งปม.'!E14 -> 0 | G5: ='จัดสรร งปม.'!F14 -> 0 | H5: ='จัดสรร งปม.'!G14 -> 0 | I5: ='จัดสรร งปม.'!H14 -> 0 | J5: ='จัดสรร งปม.'!I14 -> 0 | K5: ='จัดสรร งปม.'!J14 -> 0 | L5: ='จัดสรร งปม.'!K14 -> 0 | ... Q5: ='จัดสรร งปม.'!P14 -> 1000
D6: ใช้ไปแล้ว | E6: =SUM(E11:E45) -> 120 | F6: =SUM(F11:F45) -> 0 | G6: =SUM(G11:G45) -> 0 | H6: =SUM(H11:H45) -> 0 | I6: =SUM(I11:I45) -> 0 | J6: =SUM(J11:J45) -> 0 | K6: =SUM(K11:K45) -> 0 | L6: =SUM(L11:L45) -> 0 | ... Q6: =SUM(Q11:Q45) -> 120
B7: งบบุคลากร | D7: เหลือ | E7: =E5-E6 -> 880 | F7: =F5-F6 -> 0 | G7: =G5-G6 -> 0 | H7: =H5-H6 -> 0 | I7: =I5-I6 -> 0 | J7: =J5-J6 -> 0 | K7: =K5-K6 -> 0 | L7: =L5-L6 -> 0 | ... Q7: =Q5-Q6 -> 880
B8: รหัสรายการจ่าย | C8: ='จัดสรร งปม.'!$B$14 -> 105
B9: รายการจ่าย | C9: ='จัดสรร งปม.'!$C$14 -> สำรอง 4
A10: รหัส | B10: วันที่ | C10: ชื่อผู้ขอใช้ | D10: แผนก/งาน | E10: ปวช. | F10: ปวส. | G10: ระยะสั้น | H10: อุดหนุน | I10: หนังสือ | J10: เครื่องแบบ | K10: กิจกรรม | L10: อุปกรณ์ | M10: เครื่องมือ | N10: โครงการ | O10: เงินรายได้ | P10: เงินรับฝาก | Q10: รวม
A11: 001 | E11: 120 | Q11: =SUM(E11:P11) -> 120
A12: 002 | Q12: =SUM(E12:P12) -> 0
A13: 003 | Q13: =SUM(E13:P13) -> 0
A14: 004 | Q14: =SUM(E14:P14) -> 0
A15: 005 | Q15: =SUM(E15:P15) -> 0
A16: 006 | Q16: =SUM(E16:P16) -> 0
A17: 007 | Q17: =SUM(E17:P17) -> 0
A18: 008 | Q18: =SUM(E18:P18) -> 0
A19: 009 | Q19: =SUM(E19:P19) -> 0
A20: 010 | Q20: =SUM(E20:P20) -> 0
A21: 011 | Q21: =SUM(E21:P21) -> 0
A22: 012 | Q22: =SUM(E22:P22) -> 0
A23: 013 | Q23: =SUM(E23:P23) -> 0
... A45: 035 | Q45: =SUM(E45:P45) -> 0

Sheet 201
A1: กลับไปที่หน้าจัดสรร งปม.
E2: =Note!$B$1 -> วิทยาลัยการอาชีพแม่สะเรียง
E3: เงินงบประมาณ | H3: เงินอุดหนุน | N3: งบรายจ่ายอื่น | O3: เงิน บกศ. | Q3: รวม
E4: ปวช. | F4: ปวส. | G4: ระยะสั้น | H4: อุดหนุน | I4: หนังสือ | J4: เครื่องแบบ | K4: กิจกรรม | L4: อุปกรณ์ | M4: เครื่องมือ | N4: โครงการ | O4: เงินรายได้ | P4: เงินรับฝาก
D5: ได้รับมา | E5: ='จัดสรร งปม.'!D16 -> 110 | F5: ='จัดสรร งปม.'!E16 -> 0 | G5: ='จัดสรร งปม.'!F16 -> 0 | H5: ='จัดสรร งปม.'!G16 -> 0 | I5: ='จัดสรร งปม.'!H16 -> 0 | J5: ='จัดสรร งปม.'!I16 -> 0 | K5: ='จัดสรร งปม.'!J16 -> 0 | L5: ='จัดสรร งปม.'!K16 -> 0 | ... Q5: ='จัดสรร งปม.'!P16 -> 110
D6: ใช้ไปแล้ว | E6: =SUM(E11:E45) -> 35 | F6: =SUM(F11:F45) -> 0 | G6: =SUM(G11:G45) -> 0 | H6: =SUM(H11:H45) -> 0 | I6: =SUM(I11:I45) -> 0 | J6: =SUM(J11:J45) -> 0 | K6: =SUM(K11:K45) -> 0 | L6: =SUM(L11:L45) -> 0 | ... Q6: =SUM(Q11:Q45) -> 35
B7: งบดำเนินงาน (ค่าตอบแทน) | D7: เหลือ | E7: =E5-E6 -> 75 | F7: =F5-F6 -> 0 | G7: =G5-G6 -> 0 | H7: =H5-H6 -> 0 | I7: =I5-I6 -> 0 | J7: =J5-J6 -> 0 | K7: =K5-K6 -> 0 | L7: =L5-L6 -> 0 | ... Q7: =Q5-Q6 -> 75
B8: รหัสรายการจ่าย | C8: ='จัดสรร งปม.'!$B$16 -> 201
B9: รายการจ่าย | C9: ='จัดสรร งปม.'!$C$16 -> ค่าตอบแทนพิเศษพนักงานราชการ
A10: รหัส | B10: วันที่ | C10: ชื่อผู้ขอใช้ | D10: แผนก/งาน | E10: ปวช. | F10: ปวส. | G10: ระยะสั้น | H10: อุดหนุน | I10: หนังสือ | J10: เครื่องแบบ | K10: กิจกรรม | L10: อุปกรณ์ | M10: เครื่องมือ | N10: โครงการ | O10: เงินรายได้ | P10: เงินรับฝาก | Q10: รวม
A11: 001 | E11: 35 | Q11: =SUM(E11:P11) -> 35
A12: 002 | Q12: =SUM(E12:P12) -> 0
A13: 003 | Q13: =SUM(E13:P13) -> 0
A14: 004 | Q14: =SUM(E14:P14) -> 0
A15: 005 | Q15: =SUM(E15:P15) -> 0
A16: 006 | Q16: =SUM(E16:P16) -> 0
A17: 007 | Q17: =SUM(E17:P17) -> 0
A18: 008 | Q18: =SUM(E18:P18) -> 0
A19: 009 | Q19: =SUM(E19:P19) -> 0
A20: 010 | Q20: =SUM(E20:P20) -> 0
A21: 011 | Q21: =SUM(E21:P21) -> 0
A22: 012 | Q22: =SUM(E22:P22) -> 0
A23: 013 | Q23: =SUM(E23:P23) -> 0
... A45: 035 | Q45: =SUM(E45:P45) -> 0

Sheet 202
A1: กลับไปที่หน้าจัดสรร งปม.
E2: =Note!$B$1 -> วิทยาลัยการอาชีพแม่สะเรียง
E3: เงินงบประมาณ | H3: เงินอุดหนุน | N3: งบรายจ่ายอื่น | O3: เงิน บกศ. | Q3: รวม
E4: ปวช. | F4: ปวส. | G4: ระยะสั้น | H4: อุดหนุน | I4: หนังสือ | J4: เครื่องแบบ | K4: กิจกรรม | L4: อุปกรณ์ | M4: เครื่องมือ | N4: โครงการ | O4: เงินรายได้ | P4: เงินรับฝาก
D5: ได้รับมา | E5: ='จัดสรร งปม.'!D17 -> 120 | F5: ='จัดสรร งปม.'!E17 -> 0 | G5: ='จัดสรร งปม.'!F17 -> 0 | H5: ='จัดสรร งปม.'!G17 -> 0 | I5: ='จัดสรร งปม.'!H17 -> 0 | J5: ='จัดสรร งปม.'!I17 -> 0 | K5: ='จัดสรร งปม.'!J17 -> 0 | L5: ='จัดสรร งปม.'!K17 -> 0 | ... Q5: ='จัดสรร งปม.'!P17 -> 120
D6: ใช้ไปแล้ว | E6: =SUM(E11:E45) -> 40 | F6: =SUM(F11:F45) -> 0 | G6: =SUM(G11:G45) -> 0 | H6: =SUM(H11:H45) -> 0 | I6: =SUM(I11:I45) -> 0 | J6: =SUM(J11:J45) -> 0 | K6: =SUM(K11:K45) -> 0 | L6: =SUM(L11:L45) -> 0 | ... Q6: =SUM(Q11:Q45) -> 40
B7: งบดำเนินงาน (ค่าตอบแทน) | D7: เหลือ | E7: =E5-E6 -> 80 | F7: =F5-F6 -> 0 | G7: =G5-G6 -> 0 | H7: =H5-H6 -> 0 | I7: =I5-I6 -> 0 | J7: =J5-J6 -> 0 | K7: =K5-K6 -> 0 | L7: =L5-L6 -> 0 | ... Q7: =Q5-Q6 -> 80
B8: รหัสรายการจ่าย | C8: ='จัดสรร งปม.'!$B$17 -> 202
B9: รายการจ่าย | C9: ='จัดสรร งปม.'!$C$17 -> ค่าสอนเกินภาระงาน
A10: รหัส | B10: วันที่ | C10: ชื่อผู้ขอใช้ | D10: แผนก/งาน | E10: ปวช. | F10: ปวส. | G10: ระยะสั้น | H10: อุดหนุน | I10: หนังสือ | J10: เครื่องแบบ | K10: กิจกรรม | L10: อุปกรณ์ | M10: เครื่องมือ | N10: โครงการ | O10: เงินรายได้ | P10: เงินรับฝาก | Q10: รวม
A11: 001 | E11: 40 | Q11: =SUM(E11:P11) -> 40
A12: 002 | Q12: =SUM(E12:P12) -> 0
A13: 003 | Q13: =SUM(E13:P13) -> 0
A14: 004 | Q14: =SUM(E14:P14) -> 0
A15: 005 | Q15: =SUM(E15:P15) -> 0
A16: 006 | Q16: =SUM(E16:P16) -> 0
A17: 007 | Q17: =SUM(E17:P17) -> 0
A18: 008 | Q18: =SUM(E18:P18) -> 0
A19: 009 | Q19: =SUM(E19:P19) -> 0
A20: 010 | Q20: =SUM(E20:P20) -> 0
A21: 011 | Q21: =SUM(E21:P21) -> 0
A22: 012 | Q22: =SUM(E22:P22) -> 0
A23: 013 | Q23: =SUM(E23:P23) -> 0
... A45: 035 | Q45: =SUM(E45:P45) -> 0

Sheet 203
A1: กลับไปที่หน้าจัดสรร งปม.
E2: =Note!$B$1 -> วิทยาลัยการอาชีพแม่สะเรียง
E3: เงินงบประมาณ | H3: เงินอุดหนุน | N3: งบรายจ่ายอื่น | O3: เงิน บกศ. | Q3: รวม
E4: ปวช. | F4: ปวส. | G4: ระยะสั้น | H4: อุดหนุน | I4: หนังสือ | J4: เครื่องแบบ | K4: กิจกรรม | L4: อุปกรณ์ | M4: เครื่องมือ | N4: โครงการ | O4: เงินรายได้ | P4: เงินรับฝาก
D5: ได้รับมา | E5: ='จัดสรร งปม.'!D18 -> 130 | F5: ='จัดสรร งปม.'!E18 -> 0 | G5: ='จัดสรร งปม.'!F18 -> 0 | H5: ='จัดสรร งปม.'!G18 -> 0 | I5: ='จัดสรร งปม.'!H18 -> 0 | J5: ='จัดสรร งปม.'!I18 -> 0 | K5: ='จัดสรร งปม.'!J18 -> 0 | L5: ='จัดสรร งปม.'!K18 -> 0 | ... Q5: ='จัดสรร งปม.'!P18 -> 130
D6: ใช้ไปแล้ว | E6: =SUM(E11:E45) -> 32 | F6: =SUM(F11:F45) -> 0 | G6: =SUM(G11:G45) -> 0 | H6: =SUM(H11:H45) -> 0 | I6: =SUM(I11:I45) -> 0 | J6: =SUM(J11:J45) -> 0 | K6: =SUM(K11:K45) -> 0 | L6: =SUM(L11:L45) -> 0 | ... Q6: =SUM(Q11:Q45) -> 32
B7: งบดำเนินงาน (ค่าตอบแทน) | D7: เหลือ | E7: =E5-E6 -> 98 | F7: =F5-F6 -> 0 | G7: =G5-G6 -> 0 | H7: =H5-H6 -> 0 | I7: =I5-I6 -> 0 | J7: =J5-J6 -> 0 | K7: =K5-K6 -> 0 | L7: =L5-L6 -> 0 | ... Q7: =Q5-Q6 -> 98
B8: รหัสรายการจ่าย | C8: ='จัดสรร งปม.'!$B$18 -> 203
B9: รายการจ่าย | C9: ='จัดสรร งปม.'!$C$18 -> ค่าธุรการนอกเวลา
A10: รหัส | B10: วันที่ | C10: ชื่อผู้ขอใช้ | D10: แผนก/งาน | E10: ปวช. | F10: ปวส. | G10: ระยะสั้น | H10: อุดหนุน | I10: หนังสือ | J10: เครื่องแบบ | K10: กิจกรรม | L10: อุปกรณ์ | M10: เครื่องมือ | N10: โครงการ | O10: เงินรายได้ | P10: เงินรับฝาก | Q10: รวม
A11: 001 | E11: 32 | Q11: =SUM(E11:P11) -> 32
A12: 002 | Q12: =SUM(E12:P12) -> 0
A13: 003 | Q13: =SUM(E13:P13) -> 0
A14: 004 | Q14: =SUM(E14:P14) -> 0
A15: 005 | Q15: =SUM(E15:P15) -> 0
A16: 006 | Q16: =SUM(E16:P16) -> 0
A17: 007 | Q17: =SUM(E17:P17) -> 0
A18: 008 | Q18: =SUM(E18:P18) -> 0
A19: 009 | Q19: =SUM(E19:P19) -> 0
A20: 010 | Q20: =SUM(E20:P20) -> 0
A21: 011 | Q21: =SUM(E21:P21) -> 0
A22: 012 | Q22: =SUM(E22:P22) -> 0
A23: 013 | Q23: =SUM(E23:P23) -> 0
... A45: 035 | Q45: =SUM(E45:P45) -> 0

Sheet 204
A1: กลับไปที่หน้าจัดสรร งปม.
E2: =Note!$B$1 -> วิทยาลัยการอาชีพแม่สะเรียง
E3: เงินงบประมาณ | H3: เงินอุดหนุน | N3: งบรายจ่ายอื่น | O3: เงิน บกศ. | Q3: รวม
E4: ปวช. | F4: ปวส. | G4: ระยะสั้น | H4: อุดหนุน | I4: หนังสือ | J4: เครื่องแบบ | K4: กิจกรรม | L4: อุปกรณ์ | M4: เครื่องมือ | N4: โครงการ | O4: เงินรายได้ | P4: เงินรับฝาก
D5: ได้รับมา | E5: ='จัดสรร งปม.'!D19 -> 140 | F5: ='จัดสรร งปม.'!E19 -> 0 | G5: ='จัดสรร งปม.'!F19 -> 0 | H5: ='จัดสรร งปม.'!G19 -> 0 | I5: ='จัดสรร งปม.'!H19 -> 0 | J5: ='จัดสรร งปม.'!I19 -> 0 | K5: ='จัดสรร งปม.'!J19 -> 0 | L5: ='จัดสรร งปม.'!K19 -> 0 | ... Q5: ='จัดสรร งปม.'!P19 -> 140
D6: ใช้ไปแล้ว | E6: =SUM(E11:E45) -> 33 | F6: =SUM(F11:F45) -> 0 | G6: =SUM(G11:G45) -> 0 | H6: =SUM(H11:H45) -> 0 | I6: =SUM(I11:I45) -> 0 | J6: =SUM(J11:J45) -> 0 | K6: =SUM(K11:K45) -> 0 | L6: =SUM(L11:L45) -> 0 | ... Q6: =SUM(Q11:Q45) -> 33
B7: งบดำเนินงาน (ค่าตอบแทน) | D7: เหลือ | E7: =E5-E6 -> 107 | F7: =F5-F6 -> 0 | G7: =G5-G6 -> 0 | H7: =H5-H6 -> 0 | I7: =I5-I6 -> 0 | J7: =J5-J6 -> 0 | K7: =K5-K6 -> 0 | L7: =L5-L6 -> 0 | ... Q7: =Q5-Q6 -> 107
B8: รหัสรายการจ่าย | C8: ='จัดสรร งปม.'!$B$19 -> 204
B9: รายการจ่าย | C9: ='จัดสรร งปม.'!$C$19 -> ค่าสอนภาคฤดูร้อน
A10: รหัส | B10: วันที่ | C10: ชื่อผู้ขอใช้ | D10: แผนก/งาน | E10: ปวช. | F10: ปวส. | G10: ระยะสั้น | H10: อุดหนุน | I10: หนังสือ | J10: เครื่องแบบ | K10: กิจกรรม | L10: อุปกรณ์ | M10: เครื่องมือ | N10: โครงการ | O10: เงินรายได้ | P10: เงินรับฝาก | Q10: รวม
A11: 001 | E11: 33 | Q11: =SUM(E11:P11) -> 33
A12: 002 | Q12: =SUM(E12:P12) -> 0
A13: 003 | Q13: =SUM(E13:P13) -> 0
A14: 004 | Q14: =SUM(E14:P14) -> 0
A15: 005 | Q15: =SUM(E15:P15) -> 0
A16: 006 | Q16: =SUM(E16:P16) -> 0
A17: 007 | Q17: =SUM(E17:P17) -> 0
A18: 008 | Q18: =SUM(E18:P18) -> 0
A19: 009 | Q19: =SUM(E19:P19) -> 0
A20: 010 | Q20: =SUM(E20:P20) -> 0
A21: 011 | Q21: =SUM(E21:P21) -> 0
A22: 012 | Q22: =SUM(E22:P22) -> 0
A23: 013 | Q23: =SUM(E23:P23) -> 0
... A45: 035 | Q45: =SUM(E45:P45) -> 0

Sheet 205
A1: กลับไปที่หน้าจัดสรร งปม.
E2: =Note!$B$1 -> วิทยาลัยการอาชีพแม่สะเรียง
E3: เงินงบประมาณ | H3: เงินอุดหนุน | N3: งบรายจ่ายอื่น | O3: เงิน บกศ. | Q3: รวม
E4: ปวช. | F4: ปวส. | G4: ระยะสั้น | H4: อุดหนุน | I4: หนังสือ | J4: เครื่องแบบ | K4: กิจกรรม | L4: อุปกรณ์ | M4: เครื่องมือ | N4: โครงการ | O4: เงินรายได้ | P4: เงินรับฝาก
D5: ได้รับมา | E5: ='จัดสรร งปม.'!D20 -> 150 | F5: ='จัดสรร งปม.'!E20 -> 0 | G5: ='จัดสรร งปม.'!F20 -> 0 | H5: ='จัดสรร งปม.'!G20 -> 0 | I5: ='จัดสรร งปม.'!H20 -> 0 | J5: ='จัดสรร งปม.'!I20 -> 0 | K5: ='จัดสรร งปม.'!J20 -> 0 | L5: ='จัดสรร งปม.'!K20 -> 0 | ... Q5: ='จัดสรร งปม.'!P20 -> 150
D6: ใช้ไปแล้ว | E6: =SUM(E11:E45) -> 32 | F6: =SUM(F11:F45) -> 0 | G6: =SUM(G11:G45) -> 0 | H6: =SUM(H11:H45) -> 0 | I6: =SUM(I11:I45) -> 0 | J6: =SUM(J11:J45) -> 0 | K6: =SUM(K11:K45) -> 0 | L6: =SUM(L11:L45) -> 0 | ... Q6: =SUM(Q11:Q45) -> 32
B7: งบดำเนินงาน (ค่าตอบแทน) | D7: เหลือ | E7: =E5-E6 -> 118 | F7: =F5-F6 -> 0 | G7: =G5-G6 -> 0 | H7: =H5-H6 -> 0 | I7: =I5-I6 -> 0 | J7: =J5-J6 -> 0 | K7: =K5-K6 -> 0 | L7: =L5-L6 -> 0 | ... Q7: =Q5-Q6 -> 118
B8: รหัสรายการจ่าย | C8: ='จัดสรร งปม.'!$B$20 -> 205
B9: รายการจ่าย | C9: ='จัดสรร งปม.'!$C$20 -> ค่าสอนเทียบโอน
A10: รหัส | B10: วันที่ | C10: ชื่อผู้ขอใช้ | D10: แผนก/งาน | E10: ปวช. | F10: ปวส. | G10: ระยะสั้น | H10: อุดหนุน | I10: หนังสือ | J10: เครื่องแบบ | K10: กิจกรรม | L10: อุปกรณ์ | M10: เครื่องมือ | N10: โครงการ | O10: เงินรายได้ | P10: เงินรับฝาก | Q10: รวม
A11: 001 | E11: 32 | Q11: =SUM(E11:P11) -> 32
A12: 002 | Q12: =SUM(E12:P12) -> 0
A13: 003 | Q13: =SUM(E13:P13) -> 0
A14: 004 | Q14: =SUM(E14:P14) -> 0
A15: 005 | Q15: =SUM(E15:P15) -> 0
A16: 006 | Q16: =SUM(E16:P16) -> 0
A17: 007 | Q17: =SUM(E17:P17) -> 0
A18: 008 | Q18: =SUM(E18:P18) -> 0
A19: 009 | Q19: =SUM(E19:P19) -> 0
A20: 010 | Q20: =SUM(E20:P20) -> 0
A21: 011 | Q21: =SUM(E21:P21) -> 0
A22: 012 | Q22: =SUM(E22:P22) -> 0
A23: 013 | Q23: =SUM(E23:P23) -> 0
... A45: 035 | Q45: =SUM(E45:P45) -> 0

Sheet 206
A1: กลับไปที่หน้าจัดสรร งปม.
E2: =Note!$B$1 -> วิทยาลัยการอาชีพแม่สะเรียง
E3: เงินงบประมาณ | H3: เงินอุดหนุน | N3: งบรายจ่ายอื่น | O3: เงิน บกศ. | Q3: รวม
E4: ปวช. | F4: ปวส. | G4: ระยะสั้น | H4: อุดหนุน | I4: หนังสือ | J4: เครื่องแบบ | K4: กิจกรรม | L4: อุปกรณ์ | M4: เครื่องมือ | N4: โครงการ | O4: เงินรายได้ | P4: เงินรับฝาก
D5: ได้รับมา | E5: ='จัดสรร งปม.'!D21 -> 160 | F5: ='จัดสรร งปม.'!E21 -> 0 | G5: ='จัดสรร งปม.'!F21 -> 0 | H5: ='จัดสรร งปม.'!G21 -> 0 | I5: ='จัดสรร งปม.'!H21 -> 0 | J5: ='จัดสรร งปม.'!I21 -> 0 | K5: ='จัดสรร งปม.'!J21 -> 0 | L5: ='จัดสรร งปม.'!K21 -> 0 | ... Q5: ='จัดสรร งปม.'!P21 -> 160
D6: ใช้ไปแล้ว | E6: =SUM(E11:E45) -> 30 | F6: =SUM(F11:F45) -> 0 | G6: =SUM(G11:G45) -> 0 | H6: =SUM(H11:H45) -> 0 | I6: =SUM(I11:I45) -> 0 | J6: =SUM(J11:J45) -> 0 | K6: =SUM(K11:K45) -> 0 | L6: =SUM(L11:L45) -> 0 | ... Q6: =SUM(Q11:Q45) -> 30
B7: งบดำเนินงาน (ค่าตอบแทน) | D7: เหลือ | E7: =E5-E6 -> 130 | F7: =F5-F6 -> 0 | G7: =G5-G6 -> 0 | H7: =H5-H6 -> 0 | I7: =I5-I6 -> 0 | J7: =J5-J6 -> 0 | K7: =K5-K6 -> 0 | L7: =L5-L6 -> 0 | ... Q7: =Q5-Q6 -> 130
B8: รหัสรายการจ่าย | C8: ='จัดสรร งปม.'!$B$21 -> 206
B9: รายการจ่าย | C9: ='จัดสรร งปม.'!$C$21 -> ค่าจ้างครูรายเดือน
A10: รหัส | B10: วันที่ | C10: ชื่อผู้ขอใช้ | D10: แผนก/งาน | E10: ปวช. | F10: ปวส. | G10: ระยะสั้น | H10: อุดหนุน | I10: หนังสือ | J10: เครื่องแบบ | K10: กิจกรรม | L10: อุปกรณ์ | M10: เครื่องมือ | N10: โครงการ | O10: เงินรายได้ | P10: เงินรับฝาก | Q10: รวม
A11: 001 | E11: 30 | Q11: =SUM(E11:P11) -> 30
A12: 002 | Q12: =SUM(E12:P12) -> 0
A13: 003 | Q13: =SUM(E13:P13) -> 0
A14: 004 | Q14: =SUM(E14:P14) -> 0
A15: 005 | Q15: =SUM(E15:P15) -> 0
A16: 006 | Q16: =SUM(E16:P16) -> 0
A17: 007 | Q17: =SUM(E17:P17) -> 0
A18: 008 | Q18: =SUM(E18:P18) -> 0
A19: 009 | Q19: =SUM(E19:P19) -> 0
A20: 010 | Q20: =SUM(E20:P20) -> 0
A21: 011 | Q21: =SUM(E21:P21) -> 0
A22: 012 | Q22: =SUM(E22:P22) -> 0
A23: 013 | Q23: =SUM(E23:P23) -> 0
... A45: 035 | Q45: =SUM(E45:P45) -> 0

Sheet 207
A1: กลับไปที่หน้าจัดสรร งปม.
E2: =Note!$B$1 -> วิทยาลัยการอาชีพแม่สะเรียง
E3: เงินงบประมาณ | H3: เงินอุดหนุน | N3: งบรายจ่ายอื่น | O3: เงิน บกศ. | Q3: รวม
E4: ปวช. | F4: ปวส. | G4: ระยะสั้น | H4: อุดหนุน | I4: หนังสือ | J4: เครื่องแบบ | K4: กิจกรรม | L4: อุปกรณ์ | M4: เครื่องมือ | N4: โครงการ | O4: เงินรายได้ | P4: เงินรับฝาก
D5: ได้รับมา | E5: ='จัดสรร งปม.'!D22 -> 170 | F5: ='จัดสรร งปม.'!E22 -> 0 | G5: ='จัดสรร งปม.'!F22 -> 0 | H5: ='จัดสรร งปม.'!G22 -> 0 | I5: ='จัดสรร งปม.'!H22 -> 0 | J5: ='จัดสรร งปม.'!I22 -> 0 | K5: ='จัดสรร งปม.'!J22 -> 0 | L5: ='จัดสรร งปม.'!K22 -> 0 | ... Q5: ='จัดสรร งปม.'!P22 -> 170
D6: ใช้ไปแล้ว | E6: =SUM(E11:E45) -> 70 | F6: =SUM(F11:F45) -> 0 | G6: =SUM(G11:G45) -> 0 | H6: =SUM(H11:H45) -> 0 | I6: =SUM(I11:I45) -> 0 | J6: =SUM(J11:J45) -> 0 | K6: =SUM(K11:K45) -> 0 | L6: =SUM(L11:L45) -> 0 | ... Q6: =SUM(Q11:Q45) -> 70
B7: งบดำเนินงาน (ค่าตอบแทน) | D7: เหลือ | E7: =E5-E6 -> 100 | F7: =F5-F6 -> 0 | G7: =G5-G6 -> 0 | H7: =H5-H6 -> 0 | I7: =I5-I6 -> 0 | J7: =J5-J6 -> 0 | K7: =K5-K6 -> 0 | L7: =L5-L6 -> 0 | ... Q7: =Q5-Q6 -> 100
B8: รหัสรายการจ่าย | C8: ='จัดสรร งปม.'!$B$22 -> 207
B9: รายการจ่าย | C9: ='จัดสรร งปม.'!$C$22 -> ค่าจ้างเจ้าหน้าที่รายเดือน
A10: รหัส | B10: วันที่ | C10: ชื่อผู้ขอใช้ | D10: แผนก/งาน | E10: ปวช. | F10: ปวส. | G10: ระยะสั้น | H10: อุดหนุน | I10: หนังสือ | J10: เครื่องแบบ | K10: กิจกรรม | L10: อุปกรณ์ | M10: เครื่องมือ | N10: โครงการ | O10: เงินรายได้ | P10: เงินรับฝาก | Q10: รวม
A11: 001 | E11: 70 | Q11: =SUM(E11:P11) -> 70
A12: 002 | Q12: =SUM(E12:P12) -> 0
A13: 003 | Q13: =SUM(E13:P13) -> 0
A14: 004 | Q14: =SUM(E14:P14) -> 0
A15: 005 | Q15: =SUM(E15:P15) -> 0
A16: 006 | Q16: =SUM(E16:P16) -> 0
A17: 007 | Q17: =SUM(E17:P17) -> 0
A18: 008 | Q18: =SUM(E18:P18) -> 0
A19: 009 | Q19: =SUM(E19:P19) -> 0
A20: 010 | Q20: =SUM(E20:P20) -> 0
A21: 011 | Q21: =SUM(E21:P21) -> 0
A22: 012 | Q22: =SUM(E22:P22) -> 0
A23: 013 | Q23: =SUM(E23:P23) -> 0
... A45: 035 | Q45: =SUM(E45:P45) -> 0

Sheet 208
A1: กลับไปที่หน้าจัดสรร งปม.
E2: =Note!$B$1 -> วิทยาลัยการอาชีพแม่สะเรียง
E3: เงินงบประมาณ | H3: เงินอุดหนุน | N3: งบรายจ่ายอื่น | O3: เงิน บกศ. | Q3: รวม
E4: ปวช. | F4: ปวส. | G4: ระยะสั้น | H4: อุดหนุน | I4: หนังสือ | J4: เครื่องแบบ | K4: กิจกรรม | L4: อุปกรณ์ | M4: เครื่องมือ | N4: โครงการ | O4: เงินรายได้ | P4: เงินรับฝาก
D5: ได้รับมา | E5: ='จัดสรร งปม.'!D23 -> 180 | F5: ='จัดสรร งปม.'!E23 -> 0 | G5: ='จัดสรร งปม.'!F23 -> 0 | H5: ='จัดสรร งปม.'!G23 -> 0 | I5: ='จัดสรร งปม.'!H23 -> 0 | J5: ='จัดสรร งปม.'!I23 -> 0 | K5: ='จัดสรร งปม.'!J23 -> 0 | L5: ='จัดสรร งปม.'!K23 -> 0 | ... Q5: ='จัดสรร งปม.'!P23 -> 180
D6: ใช้ไปแล้ว | E6: =SUM(E11:E45) -> 80 | F6: =SUM(F11:F45) -> 0 | G6: =SUM(G11:G45) -> 0 | H6: =SUM(H11:H45) -> 0 | I6: =SUM(I11:I45) -> 0 | J6: =SUM(J11:J45) -> 0 | K6: =SUM(K11:K45) -> 0 | L6: =SUM(L11:L45) -> 0 | ... Q6: =SUM(Q11:Q45) -> 80
B7: งบดำเนินงาน (ค่าตอบแทน) | D7: เหลือ | E7: =E5-E6 -> 100 | F7: =F5-F6 -> 0 | G7: =G5-G6 -> 0 | H7: =H5-H6 -> 0 | I7: =I5-I6 -> 0 | J7: =J5-J6 -> 0 | K7: =K5-K6 -> 0 | L7: =L5-L6 -> 0 | ... Q7: =Q5-Q6 -> 100
B8: รหัสรายการจ่าย | C8: ='จัดสรร งปม.'!$B$23 -> 208
B9: รายการจ่าย | C9: ='จัดสรร งปม.'!$C$23 -> ค่าครองชีพครูรายเดือน
A10: รหัส | B10: วันที่ | C10: ชื่อผู้ขอใช้ | D10: แผนก/งาน | E10: ปวช. | F10: ปวส. | G10: ระยะสั้น | H10: อุดหนุน | I10: หนังสือ | J10: เครื่องแบบ | K10: กิจกรรม | L10: อุปกรณ์ | M10: เครื่องมือ | N10: โครงการ | O10: เงินรายได้ | P10: เงินรับฝาก | Q10: รวม
A11: 001 | E11: 80 | Q11: =SUM(E11:P11) -> 80
A12: 002 | Q12: =SUM(E12:P12) -> 0
A13: 003 | Q13: =SUM(E13:P13) -> 0
A14: 004 | Q14: =SUM(E14:P14) -> 0
A15: 005 | Q15: =SUM(E15:P15) -> 0
A16: 006 | Q16: =SUM(E16:P16) -> 0
A17: 007 | Q17: =SUM(E17:P17) -> 0
A18: 008 | Q18: =SUM(E18:P18) -> 0
A19: 009 | Q19: =SUM(E19:P19) -> 0
A20: 010 | Q20: =SUM(E20:P20) -> 0
A21: 011 | Q21: =SUM(E21:P21) -> 0
A22: 012 | Q22: =SUM(E22:P22) -> 0
A23: 013 | Q23: =SUM(E23:P23) -> 0
... A45: 035 | Q45: =SUM(E45:P45) -> 0

Sheet 209
A1: กลับไปที่หน้าจัดสรร งปม.
E2: =Note!$B$1 -> วิทยาลัยการอาชีพแม่สะเรียง
E3: เงินงบประมาณ | H3: เงินอุดหนุน | N3: งบรายจ่ายอื่น | O3: เงิน บกศ. | Q3: รวม
E4: ปวช. | F4: ปวส. | G4: ระยะสั้น | H4: อุดหนุน | I4: หนังสือ | J4: เครื่องแบบ | K4: กิจกรรม | L4: อุปกรณ์ | M4: เครื่องมือ | N4: โครงการ | O4: เงินรายได้ | P4: เงินรับฝาก
D5: ได้รับมา | E5: ='จัดสรร งปม.'!D24 -> 190 | F5: ='จัดสรร งปม.'!E24 -> 0 | G5: ='จัดสรร งปม.'!F24 -> 0 | H5: ='จัดสรร งปม.'!G24 -> 0 | I5: ='จัดสรร งปม.'!H24 -> 0 | J5: ='จัดสรร งปม.'!I24 -> 0 | K5: ='จัดสรร งปม.'!J24 -> 0 | L5: ='จัดสรร งปม.'!K24 -> 0 | ... Q5: ='จัดสรร งปม.'!P24 -> 190
D6: ใช้ไปแล้ว | E6: =SUM(E11:E45) -> 90 | F6: =SUM(F11:F45) -> 0 | G6: =SUM(G11:G45) -> 0 | H6: =SUM(H11:H45) -> 0 | I6: =SUM(I11:I45) -> 0 | J6: =SUM(J11:J45) -> 0 | K6: =SUM(K11:K45) -> 0 | L6: =SUM(L11:L45) -> 0 | ... Q6: =SUM(Q11:Q45) -> 90
B7: งบดำเนินงาน (ค่าตอบแทน) | D7: เหลือ | E7: =E5-E6 -> 100 | F7: =F5-F6 -> 0 | G7: =G5-G6 -> 0 | H7: =H5-H6 -> 0 | I7: =I5-I6 -> 0 | J7: =J5-J6 -> 0 | K7: =K5-K6 -> 0 | L7: =L5-L6 -> 0 | ... Q7: =Q5-Q6 -> 100
B8: รหัสรายการจ่าย | C8: ='จัดสรร งปม.'!$B$24 -> 209
B9: รายการจ่าย | C9: ='จัดสรร งปม.'!$C$24 -> ค่าครองชีพเจ้าหน้าที่รายเดือน
A10: รหัส | B10: วันที่ | C10: ชื่อผู้ขอใช้ | D10: แผนก/งาน | E10: ปวช. | F10: ปวส. | G10: ระยะสั้น | H10: อุดหนุน | I10: หนังสือ | J10: เครื่องแบบ | K10: กิจกรรม | L10: อุปกรณ์ | M10: เครื่องมือ | N10: โครงการ | O10: เงินรายได้ | P10: เงินรับฝาก | Q10: รวม
A11: 001 | E11: 90 | Q11: =SUM(E11:P11) -> 90
A12: 002 | Q12: =SUM(E12:P12) -> 0
A13: 003 | Q13: =SUM(E13:P13) -> 0
A14: 004 | Q14: =SUM(E14:P14) -> 0
A15: 005 | Q15: =SUM(E15:P15) -> 0
A16: 006 | Q16: =SUM(E16:P16) -> 0
A17: 007 | Q17: =SUM(E17:P17) -> 0
A18: 008 | Q18: =SUM(E18:P18) -> 0
A19: 009 | Q19: =SUM(E19:P19) -> 0
A20: 010 | Q20: =SUM(E20:P20) -> 0
A21: 011 | Q21: =SUM(E21:P21) -> 0
A22: 012 | Q22: =SUM(E22:P22) -> 0
A23: 013 | Q23: =SUM(E23:P23) -> 0
... A45: 035 | Q45: =SUM(E45:P45) -> 0

Sheet 210
A1: กลับไปที่หน้าจัดสรร งปม.
E2: =Note!$B$1 -> วิทยาลัยการอาชีพแม่สะเรียง
E3: เงินงบประมาณ | H3: เงินอุดหนุน | N3: งบรายจ่ายอื่น | O3: เงิน บกศ. | Q3: รวม
E4: ปวช. | F4: ปวส. | G4: ระยะสั้น | H4: อุดหนุน | I4: หนังสือ | J4: เครื่องแบบ | K4: กิจกรรม | L4: อุปกรณ์ | M4: เครื่องมือ | N4: โครงการ | O4: เงินรายได้ | P4: เงินรับฝาก
D5: ได้รับมา | E5: ='จัดสรร งปม.'!D25 -> 200 | F5: ='จัดสรร งปม.'!E25 -> 0 | G5: ='จัดสรร งปม.'!F25 -> 0 | H5: ='จัดสรร งปม.'!G25 -> 0 | I5: ='จัดสรร งปม.'!H25 -> 0 | J5: ='จัดสรร งปม.'!I25 -> 0 | K5: ='จัดสรร งปม.'!J25 -> 0 | L5: ='จัดสรร งปม.'!K25 -> 0 | ... Q5: ='จัดสรร งปม.'!P25 -> 200
D6: ใช้ไปแล้ว | E6: =SUM(E11:E45) -> 50 | F6: =SUM(F11:F45) -> 0 | G6: =SUM(G11:G45) -> 0 | H6: =SUM(H11:H45) -> 0 | I6: =SUM(I11:I45) -> 0 | J6: =SUM(J11:J45) -> 0 | K6: =SUM(K11:K45) -> 0 | L6: =SUM(L11:L45) -> 0 | ... Q6: =SUM(Q11:Q45) -> 50
B7: งบดำเนินงาน (ค่าตอบแทน) | D7: เหลือ | E7: =E5-E6 -> 150 | F7: =F5-F6 -> 0 | G7: =G5-G6 -> 0 | H7: =H5-H6 -> 0 | I7: =I5-I6 -> 0 | J7: =J5-J6 -> 0 | K7: =K5-K6 -> 0 | L7: =L5-L6 -> 0 | ... Q7: =Q5-Q6 -> 150
B8: รหัสรายการจ่าย | C8: ='จัดสรร งปม.'!$B$25 -> 210
B9: รายการจ่าย | C9: ='จัดสรร งปม.'!$C$25 -> สำรอง 1
A10: รหัส | B10: วันที่ | C10: ชื่อผู้ขอใช้ | D10: แผนก/งาน | E10: ปวช. | F10: ปวส. | G10: ระยะสั้น | H10: อุดหนุน | I10: หนังสือ | J10: เครื่องแบบ | K10: กิจกรรม | L10: อุปกรณ์ | M10: เครื่องมือ | N10: โครงการ | O10: เงินรายได้ | P10: เงินรับฝาก | Q10: รวม
A11: 001 | E11: 50 | Q11: =SUM(E11:P11) -> 50
A12: 002 | Q12: =SUM(E12:P12) -> 0
A13: 003 | Q13: =SUM(E13:P13) -> 0
A14: 004 | Q14: =SUM(E14:P14) -> 0
A15: 005 | Q15: =SUM(E15:P15) -> 0
A16: 006 | Q16: =SUM(E16:P16) -> 0
A17: 007 | Q17: =SUM(E17:P17) -> 0
A18: 008 | Q18: =SUM(E18:P18) -> 0
A19: 009 | Q19: =SUM(E19:P19) -> 0
A20: 010 | Q20: =SUM(E20:P20) -> 0
A21: 011 | Q21: =SUM(E21:P21) -> 0
A22: 012 | Q22: =SUM(E22:P22) -> 0
A23: 013 | Q23: =SUM(E23:P23) -> 0
... A45: 035 | Q45: =SUM(E45:P45) -> 0

Sheet 211
A1: กลับไปที่หน้าจัดสรร งปม.
E2: =Note!$B$1 -> วิทยาลัยการอาชีพแม่สะเรียง
E3: เงินงบประมาณ | H3: เงินอุดหนุน | N3: งบรายจ่ายอื่น | O3: เงิน บกศ. | Q3: รวม
E4: ปวช. | F4: ปวส. | G4: ระยะสั้น | H4: อุดหนุน | I4: หนังสือ | J4: เครื่องแบบ | K4: กิจกรรม | L4: อุปกรณ์ | M4: เครื่องมือ | N4: โครงการ | O4: เงินรายได้ | P4: เงินรับฝาก
D5: ได้รับมา | E5: ='จัดสรร งปม.'!D26 -> 210 | F5: ='จัดสรร งปม.'!E26 -> 0 | G5: ='จัดสรร งปม.'!F26 -> 0 | H5: ='จัดสรร งปม.'!G26 -> 0 | I5: ='จัดสรร งปม.'!H26 -> 0 | J5: ='จัดสรร งปม.'!I26 -> 0 | K5: ='จัดสรร งปม.'!J26 -> 0 | L5: ='จัดสรร งปม.'!K26 -> 0 | ... Q5: ='จัดสรร งปม.'!P26 -> 210
D6: ใช้ไปแล้ว | E6: =SUM(E11:E45) -> 10 | F6: =SUM(F11:F45) -> 0 | G6: =SUM(G11:G45) -> 0 | H6: =SUM(H11:H45) -> 0 | I6: =SUM(I11:I45) -> 0 | J6: =SUM(J11:J45) -> 0 | K6: =SUM(K11:K45) -> 0 | L6: =SUM(L11:L45) -> 0 | ... Q6: =SUM(Q11:Q45) -> 10
B7: งบดำเนินงาน (ค่าตอบแทน) | D7: เหลือ | E7: =E5-E6 -> 200 | F7: =F5-F6 -> 0 | G7: =G5-G6 -> 0 | H7: =H5-H6 -> 0 | I7: =I5-I6 -> 0 | J7: =J5-J6 -> 0 | K7: =K5-K6 -> 0 | L7: =L5-L6 -> 0 | ... Q7: =Q5-Q6 -> 200
B8: รหัสรายการจ่าย | C8: ='จัดสรร งปม.'!$B$26 -> 211
B9: รายการจ่าย | C9: ='จัดสรร งปม.'!$C$26 -> สำรอง 2
A10: รหัส | B10: วันที่ | C10: ชื่อผู้ขอใช้ | D10: แผนก/งาน | E10: ปวช. | F10: ปวส. | G10: ระยะสั้น | H10: อุดหนุน | I10: หนังสือ | J10: เครื่องแบบ | K10: กิจกรรม | L10: อุปกรณ์ | M10: เครื่องมือ | N10: โครงการ | O10: เงินรายได้ | P10: เงินรับฝาก | Q10: รวม
A11: 001 | E11: 10 | Q11: =SUM(E11:P11) -> 10
A12: 002 | Q12: =SUM(E12:P12) -> 0
A13: 003 | Q13: =SUM(E13:P13) -> 0
A14: 004 | Q14: =SUM(E14:P14) -> 0
A15: 005 | Q15: =SUM(E15:P15) -> 0
A16: 006 | Q16: =SUM(E16:P16) -> 0
A17: 007 | Q17: =SUM(E17:P17) -> 0
A18: 008 | Q18: =SUM(E18:P18) -> 0
A19: 009 | Q19: =SUM(E19:P19) -> 0
A20: 010 | Q20: =SUM(E20:P20) -> 0
A21: 011 | Q21: =SUM(E21:P21) -> 0
A22: 012 | Q22: =SUM(E22:P22) -> 0
A23: 013 | Q23: =SUM(E23:P23) -> 0
... A45: 035 | Q45: =SUM(E45:P45) -> 0

Sheet 212
A1: กลับไปที่หน้าจัดสรร งปม.
E2: =Note!$B$1 -> วิทยาลัยการอาชีพแม่สะเรียง
E3: เงินงบประมาณ | H3: เงินอุดหนุน | N3: งบรายจ่ายอื่น | O3: เงิน บกศ. | Q3: รวม
E4: ปวช. | F4: ปวส. | G4: ระยะสั้น | H4: อุดหนุน | I4: หนังสือ | J4: เครื่องแบบ | K4: กิจกรรม | L4: อุปกรณ์ | M4: เครื่องมือ | N4: โครงการ | O4: เงินรายได้ | P4: เงินรับฝาก
D5: ได้รับมา | E5: ='จัดสรร งปม.'!D27 -> 220 | F5: ='จัดสรร งปม.'!E27 -> 0 | G5: ='จัดสรร งปม.'!F27 -> 0 | H5: ='จัดสรร งปม.'!G27 -> 0 | I5: ='จัดสรร งปม.'!H27 -> 0 | J5: ='จัดสรร งปม.'!I27 -> 0 | K5: ='จัดสรร งปม.'!J27 -> 0 | L5: ='จัดสรร งปม.'!K27 -> 0 | ... Q5: ='จัดสรร งปม.'!P27 -> 220
D6: ใช้ไปแล้ว | E6: =SUM(E11:E45) -> 20 | F6: =SUM(F11:F45) -> 0 | G6: =SUM(G11:G45) -> 0 | H6: =SUM(H11:H45) -> 0 | I6: =SUM(I11:I45) -> 0 | J6: =SUM(J11:J45) -> 0 | K6: =SUM(K11:K45) -> 0 | L6: =SUM(L11:L45) -> 0 | ... Q6: =SUM(Q11:Q45) -> 20
B7: งบดำเนินงาน (ค่าตอบแทน) | D7: เหลือ | E7: =E5-E6 -> 200 | F7: =F5-F6 -> 0 | G7: =G5-G6 -> 0 | H7: =H5-H6 -> 0 | I7: =I5-I6 -> 0 | J7: =J5-J6 -> 0 | K7: =K5-K6 -> 0 | L7: =L5-L6 -> 0 | ... Q7: =Q5-Q6 -> 200
B8: รหัสรายการจ่าย | C8: ='จัดสรร งปม.'!$B$27 -> 212
B9: รายการจ่าย | C9: ='จัดสรร งปม.'!$C$27 -> สำรอง 3
A10: รหัส | B10: วันที่ | C10: ชื่อผู้ขอใช้ | D10: แผนก/งาน | E10: ปวช. | F10: ปวส. | G10: ระยะสั้น | H10: อุดหนุน | I10: หนังสือ | J10: เครื่องแบบ | K10: กิจกรรม | L10: อุปกรณ์ | M10: เครื่องมือ | N10: โครงการ | O10: เงินรายได้ | P10: เงินรับฝาก | Q10: รวม
A11: 001 | E11: 20 | Q11: =SUM(E11:P11) -> 20
A12: 002 | Q12: =SUM(E12:P12) -> 0
A13: 003 | Q13: =SUM(E13:P13) -> 0
A14: 004 | Q14: =SUM(E14:P14) -> 0
A15: 005 | Q15: =SUM(E15:P15) -> 0
A16: 006 | Q16: =SUM(E16:P16) -> 0
A17: 007 | Q17: =SUM(E17:P17) -> 0
A18: 008 | Q18: =SUM(E18:P18) -> 0
A19: 009 | Q19: =SUM(E19:P19) -> 0
A20: 010 | Q20: =SUM(E20:P20) -> 0
A21: 011 | Q21: =SUM(E21:P21) -> 0
A22: 012 | Q22: =SUM(E22:P22) -> 0
A23: 013 | Q23: =SUM(E23:P23) -> 0
... A45: 035 | Q45: =SUM(E45:P45) -> 0

Sheet 213
A1: กลับไปที่หน้าจัดสรร งปม.
E2: =Note!$B$1 -> วิทยาลัยการอาชีพแม่สะเรียง
E3: เงินงบประมาณ | H3: เงินอุดหนุน | N3: งบรายจ่ายอื่น | O3: เงิน บกศ. | Q3: รวม
E4: ปวช. | F4: ปวส. | G4: ระยะสั้น | H4: อุดหนุน | I4: หนังสือ | J4: เครื่องแบบ | K4: กิจกรรม | L4: อุปกรณ์ | M4: เครื่องมือ | N4: โครงการ | O4: เงินรายได้ | P4: เงินรับฝาก
D5: ได้รับมา | E5: ='จัดสรร งปม.'!D28 -> 230 | F5: ='จัดสรร งปม.'!E28 -> 0 | G5: ='จัดสรร งปม.'!F28 -> 0 | H5: ='จัดสรร งปม.'!G28 -> 0 | I5: ='จัดสรร งปม.'!H28 -> 0 | J5: ='จัดสรร งปม.'!I28 -> 0 | K5: ='จัดสรร งปม.'!J28 -> 0 | L5: ='จัดสรร งปม.'!K28 -> 0 | ... Q5: ='จัดสรร งปม.'!P28 -> 230
D6: ใช้ไปแล้ว | E6: =SUM(E11:E45) -> 30 | F6: =SUM(F11:F45) -> 0 | G6: =SUM(G11:G45) -> 0 | H6: =SUM(H11:H45) -> 0 | I6: =SUM(I11:I45) -> 0 | J6: =SUM(J11:J45) -> 0 | K6: =SUM(K11:K45) -> 0 | L6: =SUM(L11:L45) -> 0 | ... Q6: =SUM(Q11:Q45) -> 30
B7: งบดำเนินงาน (ค่าตอบแทน) | D7: เหลือ | E7: =E5-E6 -> 200 | F7: =F5-F6 -> 0 | G7: =G5-G6 -> 0 | H7: =H5-H6 -> 0 | I7: =I5-I6 -> 0 | J7: =J5-J6 -> 0 | K7: =K5-K6 -> 0 | L7: =L5-L6 -> 0 | ... Q7: =Q5-Q6 -> 200
B8: รหัสรายการจ่าย | C8: ='จัดสรร งปม.'!$B$28 -> 213
B9: รายการจ่าย | C9: ='จัดสรร งปม.'!$C$28 -> สำรอง 4
A10: รหัส | B10: วันที่ | C10: ชื่อผู้ขอใช้ | D10: แผนก/งาน | E10: ปวช. | F10: ปวส. | G10: ระยะสั้น | H10: อุดหนุน | I10: หนังสือ | J10: เครื่องแบบ | K10: กิจกรรม | L10: อุปกรณ์ | M10: เครื่องมือ | N10: โครงการ | O10: เงินรายได้ | P10: เงินรับฝาก | Q10: รวม
A11: 001 | E11: 30 | Q11: =SUM(E11:P11) -> 30
A12: 002 | Q12: =SUM(E12:P12) -> 0
A13: 003 | Q13: =SUM(E13:P13) -> 0
A14: 004 | Q14: =SUM(E14:P14) -> 0
A15: 005 | Q15: =SUM(E15:P15) -> 0
A16: 006 | Q16: =SUM(E16:P16) -> 0
A17: 007 | Q17: =SUM(E17:P17) -> 0
A18: 008 | Q18: =SUM(E18:P18) -> 0
A19: 009 | Q19: =SUM(E19:P19) -> 0
A20: 010 | Q20: =SUM(E20:P20) -> 0
A21: 011 | Q21: =SUM(E21:P21) -> 0
A22: 012 | Q22: =SUM(E22:P22) -> 0
A23: 013 | Q23: =SUM(E23:P23) -> 0
... A45: 035 | Q45: =SUM(E45:P45) -> 0

Sheet 214
A1: กลับไปที่หน้าจัดสรร งปม.
E2: =Note!$B$1 -> วิทยาลัยการอาชีพแม่สะเรียง
E3: เงินงบประมาณ | H3: เงินอุดหนุน | N3: งบรายจ่ายอื่น | O3: เงิน บกศ. | Q3: รวม
E4: ปวช. | F4: ปวส. | G4: ระยะสั้น | H4: อุดหนุน | I4: หนังสือ | J4: เครื่องแบบ | K4: กิจกรรม | L4: อุปกรณ์ | M4: เครื่องมือ | N4: โครงการ | O4: เงินรายได้ | P4: เงินรับฝาก
D5: ได้รับมา | E5: ='จัดสรร งปม.'!D29 -> 240 | F5: ='จัดสรร งปม.'!E29 -> 0 | G5: ='จัดสรร งปม.'!F29 -> 0 | H5: ='จัดสรร งปม.'!G29 -> 0 | I5: ='จัดสรร งปม.'!H29 -> 0 | J5: ='จัดสรร งปม.'!I29 -> 0 | K5: ='จัดสรร งปม.'!J29 -> 0 | L5: ='จัดสรร งปม.'!K29 -> 0 | ... Q5: ='จัดสรร งปม.'!P29 -> 240
D6: ใช้ไปแล้ว | E6: =SUM(E11:E45) -> 40 | F6: =SUM(F11:F45) -> 0 | G6: =SUM(G11:G45) -> 0 | H6: =SUM(H11:H45) -> 0 | I6: =SUM(I11:I45) -> 0 | J6: =SUM(J11:J45) -> 0 | K6: =SUM(K11:K45) -> 0 | L6: =SUM(L11:L45) -> 0 | ... Q6: =SUM(Q11:Q45) -> 40
B7: งบดำเนินงาน (ค่าตอบแทน) | D7: เหลือ | E7: =E5-E6 -> 200 | F7: =F5-F6 -> 0 | G7: =G5-G6 -> 0 | H7: =H5-H6 -> 0 | I7: =I5-I6 -> 0 | J7: =J5-J6 -> 0 | K7: =K5-K6 -> 0 | L7: =L5-L6 -> 0 | ... Q7: =Q5-Q6 -> 200
B8: รหัสรายการจ่าย | C8: ='จัดสรร งปม.'!$B$29 -> 214
B9: รายการจ่าย | C9: ='จัดสรร งปม.'!$C$29 -> สำรอง 5
A10: รหัส | B10: วันที่ | C10: ชื่อผู้ขอใช้ | D10: แผนก/งาน | E10: ปวช. | F10: ปวส. | G10: ระยะสั้น | H10: อุดหนุน | I10: หนังสือ | J10: เครื่องแบบ | K10: กิจกรรม | L10: อุปกรณ์ | M10: เครื่องมือ | N10: โครงการ | O10: เงินรายได้ | P10: เงินรับฝาก | Q10: รวม
A11: 001 | E11: 40 | Q11: =SUM(E11:P11) -> 40
A12: 002 | Q12: =SUM(E12:P12) -> 0
A13: 003 | Q13: =SUM(E13:P13) -> 0
A14: 004 | Q14: =SUM(E14:P14) -> 0
A15: 005 | Q15: =SUM(E15:P15) -> 0
A16: 006 | Q16: =SUM(E16:P16) -> 0
A17: 007 | Q17: =SUM(E17:P17) -> 0
A18: 008 | Q18: =SUM(E18:P18) -> 0
A19: 009 | Q19: =SUM(E19:P19) -> 0
A20: 010 | Q20: =SUM(E20:P20) -> 0
A21: 011 | Q21: =SUM(E21:P21) -> 0
A22: 012 | Q22: =SUM(E22:P22) -> 0
A23: 013 | Q23: =SUM(E23:P23) -> 0
... A45: 035 | Q45: =SUM(E45:P45) -> 0

Sheet 301
A1: กลับไปที่หน้าจัดสรร งปม.
E2: =Note!$B$1 -> วิทยาลัยการอาชีพแม่สะเรียง
E3: เงินงบประมาณ | H3: เงินอุดหนุน | N3: งบรายจ่ายอื่น | O3: เงิน บกศ. | Q3: รวม
E4: ปวช. | F4: ปวส. | G4: ระยะสั้น | H4: อุดหนุน | I4: หนังสือ | J4: เครื่องแบบ | K4: กิจกรรม | L4: อุปกรณ์ | M4: เครื่องมือ | N4: โครงการ | O4: เงินรายได้ | P4: เงินรับฝาก
D5: ได้รับมา | E5: ='จัดสรร งปม.'!D31 -> 110 | F5: ='จัดสรร งปม.'!E31 -> 0 | G5: ='จัดสรร งปม.'!F31 -> 0 | H5: ='จัดสรร งปม.'!G31 -> 0 | I5: ='จัดสรร งปม.'!H31 -> 0 | J5: ='จัดสรร งปม.'!I31 -> 0 | K5: ='จัดสรร งปม.'!J31 -> 0 | L5: ='จัดสรร งปม.'!K31 -> 0 | ... Q5: ='จัดสรร งปม.'!P31 -> 110
D6: ใช้ไปแล้ว | E6: =SUM(E11:E45) -> 10 | F6: =SUM(F11:F45) -> 0 | G6: =SUM(G11:G45) -> 0 | H6: =SUM(H11:H45) -> 0 | I6: =SUM(I11:I45) -> 0 | J6: =SUM(J11:J45) -> 0 | K6: =SUM(K11:K45) -> 0 | L6: =SUM(L11:L45) -> 0 | ... Q6: =SUM(Q11:Q45) -> 10
B7: งบดำเนินงาน (ค่าใช้สอย) | D7: เหลือ | E7: =E5-E6 -> 100 | F7: =F5-F6 -> 0 | G7: =G5-G6 -> 0 | H7: =H5-H6 -> 0 | I7: =I5-I6 -> 0 | J7: =J5-J6 -> 0 | K7: =K5-K6 -> 0 | L7: =L5-L6 -> 0 | ... Q7: =Q5-Q6 -> 100
B8: รหัสรายการจ่าย | C8: ='จัดสรร งปม.'!$B$31 -> 301
B9: รายการจ่าย | C9: ='จัดสรร งปม.'!$C$31 -> ค่าจ้างซ่อมครุภัณฑ์การศึกษาและสำนักงาน
A10: รหัส | B10: วันที่ | C10: ชื่อผู้ขอใช้ | D10: แผนก/งาน | E10: ปวช. | F10: ปวส. | G10: ระยะสั้น | H10: อุดหนุน | I10: หนังสือ | J10: เครื่องแบบ | K10: กิจกรรม | L10: อุปกรณ์ | M10: เครื่องมือ | N10: โครงการ | O10: เงินรายได้ | P10: เงินรับฝาก | Q10: รวม
A11: 001 | E11: 10 | Q11: =SUM(E11:P11) -> 10
A12: 002 | Q12: =SUM(E12:P12) -> 0
A13: 003 | Q13: =SUM(E13:P13) -> 0
A14: 004 | Q14: =SUM(E14:P14) -> 0
A15: 005 | Q15: =SUM(E15:P15) -> 0
A16: 006 | Q16: =SUM(E16:P16) -> 0
A17: 007 | Q17: =SUM(E17:P17) -> 0
A18: 008 | Q18: =SUM(E18:P18) -> 0
A19: 009 | Q19: =SUM(E19:P19) -> 0
A20: 010 | Q20: =SUM(E20:P20) -> 0
A21: 011 | Q21: =SUM(E21:P21) -> 0
A22: 012 | Q22: =SUM(E22:P22) -> 0
A23: 013 | Q23: =SUM(E23:P23) -> 0
... A45: 035 | Q45: =SUM(E45:P45) -> 0

Sheet 302
A1: กลับไปที่หน้าจัดสรร งปม.
E2: =Note!$B$1 -> วิทยาลัยการอาชีพแม่สะเรียง
E3: เงินงบประมาณ | H3: เงินอุดหนุน | N3: งบรายจ่ายอื่น | O3: เงิน บกศ. | Q3: รวม
E4: ปวช. | F4: ปวส. | G4: ระยะสั้น | H4: อุดหนุน | I4: หนังสือ | J4: เครื่องแบบ | K4: กิจกรรม | L4: อุปกรณ์ | M4: เครื่องมือ | N4: โครงการ | O4: เงินรายได้ | P4: เงินรับฝาก
D5: ได้รับมา | E5: ='จัดสรร งปม.'!D32 -> 120 | F5: ='จัดสรร งปม.'!E32 -> 0 | G5: ='จัดสรร งปม.'!F32 -> 0 | H5: ='จัดสรร งปม.'!G32 -> 0 | I5: ='จัดสรร งปม.'!H32 -> 0 | J5: ='จัดสรร งปม.'!I32 -> 0 | K5: ='จัดสรร งปม.'!J32 -> 0 | L5: ='จัดสรร งปม.'!K32 -> 0 | ... Q5: ='จัดสรร งปม.'!P32 -> 120
D6: ใช้ไปแล้ว | E6: =SUM(E11:E45) -> 20 | F6: =SUM(F11:F45) -> 0 | G6: =SUM(G11:G45) -> 0 | H6: =SUM(H11:H45) -> 0 | I6: =SUM(I11:I45) -> 0 | J6: =SUM(J11:J45) -> 0 | K6: =SUM(K11:K45) -> 0 | L6: =SUM(L11:L45) -> 0 | ... Q6: =SUM(Q11:Q45) -> 20
B7: งบดำเนินงาน (ค่าใช้สอย) | D7: เหลือ | E7: =E5-E6 -> 100 | F7: =F5-F6 -> 0 | G7: =G5-G6 -> 0 | H7: =H5-H6 -> 0 | I7: =I5-I6 -> 0 | J7: =J5-J6 -> 0 | K7: =K5-K6 -> 0 | L7: =L5-L6 -> 0 | ... Q7: =Q5-Q6 -> 100
B8: รหัสรายการจ่าย | C8: ='จัดสรร งปม.'!$B$32 -> 302
B9: รายการจ่าย | C9: ='จัดสรร งปม.'!$C$32 -> ค่าซ่อมยานพาหนะ
A10: รหัส | B10: วันที่ | C10: ชื่อผู้ขอใช้ | D10: แผนก/งาน | E10: ปวช. | F10: ปวส. | G10: ระยะสั้น | H10: อุดหนุน | I10: หนังสือ | J10: เครื่องแบบ | K10: กิจกรรม | L10: อุปกรณ์ | M10: เครื่องมือ | N10: โครงการ | O10: เงินรายได้ | P10: เงินรับฝาก | Q10: รวม
A11: 001 | E11: 20 | Q11: =SUM(E11:P11) -> 20
A12: 002 | Q12: =SUM(E12:P12) -> 0
A13: 003 | Q13: =SUM(E13:P13) -> 0
A14: 004 | Q14: =SUM(E14:P14) -> 0
A15: 005 | Q15: =SUM(E15:P15) -> 0
A16: 006 | Q16: =SUM(E16:P16) -> 0
A17: 007 | Q17: =SUM(E17:P17) -> 0
A18: 008 | Q18: =SUM(E18:P18) -> 0
A19: 009 | Q19: =SUM(E19:P19) -> 0
A20: 010 | Q20: =SUM(E20:P20) -> 0
A21: 011 | Q21: =SUM(E21:P21) -> 0
A22: 012 | Q22: =SUM(E22:P22) -> 0
A23: 013 | Q23: =SUM(E23:P23) -> 0
... A45: 035 | Q45: =SUM(E45:P45) -> 0

Sheet 303
A1: กลับไปที่หน้าจัดสรร งปม.
E2: =Note!$B$1 -> วิทยาลัยการอาชีพแม่สะเรียง
E3: เงินงบประมาณ | H3: เงินอุดหนุน | N3: งบรายจ่ายอื่น | O3: เงิน บกศ. | Q3: รวม
E4: ปวช. | F4: ปวส. | G4: ระยะสั้น | H4: อุดหนุน | I4: หนังสือ | J4: เครื่องแบบ | K4: กิจกรรม | L4: อุปกรณ์ | M4: เครื่องมือ | N4: โครงการ | O4: เงินรายได้ | P4: เงินรับฝาก
D5: ได้รับมา | E5: ='จัดสรร งปม.'!D33 -> 130 | F5: ='จัดสรร งปม.'!E33 -> 0 | G5: ='จัดสรร งปม.'!F33 -> 0 | H5: ='จัดสรร งปม.'!G33 -> 0 | I5: ='จัดสรร งปม.'!H33 -> 0 | J5: ='จัดสรร งปม.'!I33 -> 0 | K5: ='จัดสรร งปม.'!J33 -> 0 | L5: ='จัดสรร งปม.'!K33 -> 0 | ... Q5: ='จัดสรร งปม.'!P33 -> 130
D6: ใช้ไปแล้ว | E6: =SUM(E11:E45) -> 30 | F6: =SUM(F11:F45) -> 0 | G6: =SUM(G11:G45) -> 0 | H6: =SUM(H11:H45) -> 0 | I6: =SUM(I11:I45) -> 0 | J6: =SUM(J11:J45) -> 0 | K6: =SUM(K11:K45) -> 0 | L6: =SUM(L11:L45) -> 0 | ... Q6: =SUM(Q11:Q45) -> 30
B7: งบดำเนินงาน (ค่าใช้สอย) | D7: เหลือ | E7: =E5-E6 -> 100 | F7: =F5-F6 -> 0 | G7: =G5-G6 -> 0 | H7: =H5-H6 -> 0 | I7: =I5-I6 -> 0 | J7: =J5-J6 -> 0 | K7: =K5-K6 -> 0 | L7: =L5-L6 -> 0 | ... Q7: =Q5-Q6 -> 100
B8: รหัสรายการจ่าย | C8: ='จัดสรร งปม.'!$B$33 -> 303
B9: รายการจ่าย | C9: ='จัดสรร งปม.'!$C$33 -> ค่าจ้างติดตั้ง ซ่อมแซมระบบสาธารณูปโภค
A10: รหัส | B10: วันที่ | C10: ชื่อผู้ขอใช้ | D10: แผนก/งาน | E10: ปวช. | F10: ปวส. | G10: ระยะสั้น | H10: อุดหนุน | I10: หนังสือ | J10: เครื่องแบบ | K10: กิจกรรม | L10: อุปกรณ์ | M10: เครื่องมือ | N10: โครงการ | O10: เงินรายได้ | P10: เงินรับฝาก | Q10: รวม
A11: 001 | E11: 30 | Q11: =SUM(E11:P11) -> 30
A12: 002 | Q12: =SUM(E12:P12) -> 0
A13: 003 | Q13: =SUM(E13:P13) -> 0
A14: 004 | Q14: =SUM(E14:P14) -> 0
A15: 005 | Q15: =SUM(E15:P15) -> 0
A16: 006 | Q16: =SUM(E16:P16) -> 0
A17: 007 | Q17: =SUM(E17:P17) -> 0
A18: 008 | Q18: =SUM(E18:P18) -> 0
A19: 009 | Q19: =SUM(E19:P19) -> 0
A20: 010 | Q20: =SUM(E20:P20) -> 0
A21: 011 | Q21: =SUM(E21:P21) -> 0
A22: 012 | Q22: =SUM(E22:P22) -> 0
A23: 013 | Q23: =SUM(E23:P23) -> 0
... A45: 035 | Q45: =SUM(E45:P45) -> 0

Sheet 304
A1: กลับไปที่หน้าจัดสรร งปม.
E2: =Note!$B$1 -> วิทยาลัยการอาชีพแม่สะเรียง
E3: เงินงบประมาณ | H3: เงินอุดหนุน | N3: งบรายจ่ายอื่น | O3: เงิน บกศ. | Q3: รวม
E4: ปวช. | F4: ปวส. | G4: ระยะสั้น | H4: อุดหนุน | I4: หนังสือ | J4: เครื่องแบบ | K4: กิจกรรม | L4: อุปกรณ์ | M4: เครื่องมือ | N4: โครงการ | O4: เงินรายได้ | P4: เงินรับฝาก
D5: ได้รับมา | E5: ='จัดสรร งปม.'!D34 -> 140 | F5: ='จัดสรร งปม.'!E34 -> 0 | G5: ='จัดสรร งปม.'!F34 -> 0 | H5: ='จัดสรร งปม.'!G34 -> 0 | I5: ='จัดสรร งปม.'!H34 -> 0 | J5: ='จัดสรร งปม.'!I34 -> 0 | K5: ='จัดสรร งปม.'!J34 -> 0 | L5: ='จัดสรร งปม.'!K34 -> 0 | ... Q5: ='จัดสรร งปม.'!P34 -> 140
D6: ใช้ไปแล้ว | E6: =SUM(E11:E45) -> 40 | F6: =SUM(F11:F45) -> 0 | G6: =SUM(G11:G45) -> 0 | H6: =SUM(H11:H45) -> 0 | I6: =SUM(I11:I45) -> 0 | J6: =SUM(J11:J45) -> 0 | K6: =SUM(K11:K45) -> 0 | L6: =SUM(L11:L45) -> 0 | ... Q6: =SUM(Q11:Q45) -> 40
B7: งบดำเนินงาน (ค่าใช้สอย) | D7: เหลือ | E7: =E5-E6 -> 100 | F7: =F5-F6 -> 0 | G7: =G5-G6 -> 0 | H7: =H5-H6 -> 0 | I7: =I5-I6 -> 0 | J7: =J5-J6 -> 0 | K7: =K5-K6 -> 0 | L7: =L5-L6 -> 0 | ... Q7: =Q5-Q6 -> 100
B8: รหัสรายการจ่าย | C8: ='จัดสรร งปม.'!$B$34 -> 304
B9: รายการจ่าย | C9: ='จัดสรร งปม.'!$C$34 -> ค่าจ้างซ่อมอาคารสถานที่/พัฒนาสิ่งแวดล้อม
A10: รหัส | B10: วันที่ | C10: ชื่อผู้ขอใช้ | D10: แผนก/งาน | E10: ปวช. | F10: ปวส. | G10: ระยะสั้น | H10: อุดหนุน | I10: หนังสือ | J10: เครื่องแบบ | K10: กิจกรรม | L10: อุปกรณ์ | M10: เครื่องมือ | N10: โครงการ | O10: เงินรายได้ | P10: เงินรับฝาก | Q10: รวม
A11: 001 | E11: 40 | Q11: =SUM(E11:P11) -> 40
A12: 002 | Q12: =SUM(E12:P12) -> 0
A13: 003 | Q13: =SUM(E13:P13) -> 0
A14: 004 | Q14: =SUM(E14:P14) -> 0
A15: 005 | Q15: =SUM(E15:P15) -> 0
A16: 006 | Q16: =SUM(E16:P16) -> 0
A17: 007 | Q17: =SUM(E17:P17) -> 0
A18: 008 | Q18: =SUM(E18:P18) -> 0
A19: 009 | Q19: =SUM(E19:P19) -> 0
A20: 010 | Q20: =SUM(E20:P20) -> 0
A21: 011 | Q21: =SUM(E21:P21) -> 0
A22: 012 | Q22: =SUM(E22:P22) -> 0
A23: 013 | Q23: =SUM(E23:P23) -> 0
... A45: 035 | Q45: =SUM(E45:P45) -> 0

Sheet 305
A1: กลับไปที่หน้าจัดสรร งปม.
E2: =Note!$B$1 -> วิทยาลัยการอาชีพแม่สะเรียง
E3: เงินงบประมาณ | H3: เงินอุดหนุน | N3: งบรายจ่ายอื่น | O3: เงิน บกศ. | Q3: รวม
E4: ปวช. | F4: ปวส. | G4: ระยะสั้น | H4: อุดหนุน | I4: หนังสือ | J4: เครื่องแบบ | K4: กิจกรรม | L4: อุปกรณ์ | M4: เครื่องมือ | N4: โครงการ | O4: เงินรายได้ | P4: เงินรับฝาก
D5: ได้รับมา | E5: ='จัดสรร งปม.'!D35 -> 150 | F5: ='จัดสรร งปม.'!E35 -> 0 | G5: ='จัดสรร งปม.'!F35 -> 0 | H5: ='จัดสรร งปม.'!G35 -> 0 | I5: ='จัดสรร งปม.'!H35 -> 0 | J5: ='จัดสรร งปม.'!I35 -> 0 | K5: ='จัดสรร งปม.'!J35 -> 0 | L5: ='จัดสรร งปม.'!K35 -> 0 | ... Q5: ='จัดสรร งปม.'!P35 -> 150
D6: ใช้ไปแล้ว | E6: =SUM(E11:E45) -> 50 | F6: =SUM(F11:F45) -> 0 | G6: =SUM(G11:G45) -> 0 | H6: =SUM(H11:H45) -> 0 | I6: =SUM(I11:I45) -> 0 | J6: =SUM(J11:J45) -> 0 | K6: =SUM(K11:K45) -> 0 | L6: =SUM(L11:L45) -> 0 | ... Q6: =SUM(Q11:Q45) -> 50
B7: งบดำเนินงาน (ค่าใช้สอย) | D7: เหลือ | E7: =E5-E6 -> 100 | F7: =F5-F6 -> 0 | G7: =G5-G6 -> 0 | H7: =H5-H6 -> 0 | I7: =I5-I6 -> 0 | J7: =J5-J6 -> 0 | K7: =K5-K6 -> 0 | L7: =L5-L6 -> 0 | ... Q7: =Q5-Q6 -> 100
B8: รหัสรายการจ่าย | C8: ='จัดสรร งปม.'!$B$35 -> 305
B9: รายการจ่าย | C9: ='จัดสรร งปม.'!$C$35 -> ค่าเบี้ยเลี้ยง พาหนะเดิอนทาง และที่พัก
A10: รหัส | B10: วันที่ | C10: ชื่อผู้ขอใช้ | D10: แผนก/งาน | E10: ปวช. | F10: ปวส. | G10: ระยะสั้น | H10: อุดหนุน | I10: หนังสือ | J10: เครื่องแบบ | K10: กิจกรรม | L10: อุปกรณ์ | M10: เครื่องมือ | N10: โครงการ | O10: เงินรายได้ | P10: เงินรับฝาก | Q10: รวม
A11: 001 | E11: 50 | Q11: =SUM(E11:P11) -> 50
A12: 002 | Q12: =SUM(E12:P12) -> 0
A13: 003 | Q13: =SUM(E13:P13) -> 0
A14: 004 | Q14: =SUM(E14:P14) -> 0
A15: 005 | Q15: =SUM(E15:P15) -> 0
A16: 006 | Q16: =SUM(E16:P16) -> 0
A17: 007 | Q17: =SUM(E17:P17) -> 0
A18: 008 | Q18: =SUM(E18:P18) -> 0
A19: 009 | Q19: =SUM(E19:P19) -> 0
A20: 010 | Q20: =SUM(E20:P20) -> 0
A21: 011 | Q21: =SUM(E21:P21) -> 0
A22: 012 | Q22: =SUM(E22:P22) -> 0
