Workbook

Sheet Note
A1: ชื่อสถานศึกษา | B1: วิทยาลัยการอาชีพนวมินทราชินีแม่ฮ่องสอน
A2: ปีงบประมาณ | B2: 2565

Sheet ประมาณการายจ่าย
D1: ประมาณการรายจ่าย ปีงบประมาณ | F1: =Note!$B$2 -> 2565 | G1: =Note!$B$1 -> วิทยาลัยการอาชีพนวมินทราชินีแม่ฮ่องสอน
D2: เงินงบประมาณ | G2: เงินอุดหนุน | M2: งบรายจ่ายอื่น | N2: เงิน บกศ. | P2: รวม
D3: ปวช. | E3: ปวส. | F3: ระยะสั้น | G3: อุดหนุน | H3: หนังสือ | I3: เครื่องแบบ | J3: กิจกรรม | K3: อุปกรณ์ | L3: เครื่องมือ | M3: โครงการ | N3: เงินรายได้ | O3: เงินรับฝาก
C4: รับมา | P4: =SUM(D4:O4) -> 0
C5: จัดสรรไป | D5: =SUM(D9:D120) -> 0 | E5: =SUM(E9:E120) -> 0 | F5: =SUM(F9:F120) -> 0 | G5: =SUM(G9:G120) -> 0 | H5: =SUM(H9:H120) -> 0 | I5: =SUM(I9:I120) -> 0 | J5: =SUM(J9:J120) -> 0 | K5: =SUM(K9:K120) -> 0 | ... O5: =SUM(O9:O120) -> 0 | P5: =SUM(D5:O5) -> 0
C6: คงเหลือ | D6: =D4-D5 -> 0 | E6: =E4-E5 -> 0 | F6: =F4-F5 -> 0 | G6: =G4-G5 -> 0 | H6: =H4-H5 -> 0 | I6: =I4-I5 -> 0 | J6: =J4-J5 -> 0 | K6: =K4-K5 -> 0 | ... P6: =P4-P5 -> 0
D8: ปวช. | E8: ปวส. | F8: ระยะสั้น | G8: อุดหนุน | H8: หนังสือ | I8: เครื่องแบบ | J8: กิจกรรม | K8: อุปกรณ์ | L8: เครื่องมือ | M8: โครงการ | N8: เงินรายได้ | O8: เงินรับฝาก | P8: รวม
A9: 1. งบบุคลากร
A10: =Note!$B$2 -> 2565 | B10: 101 | C10: เงินเดือนพนักงานราชการ
A11: =Note!$B$2 -> 2565 | B11: 102
A12: =Note!$B$2 -> 2565 | B12: 103
A13: =Note!$B$2 -> 2565 | B13: 104
A14: =Note!$B$2 -> 2565 | B14: 105
A15: 2. งบดำเนินงาน (ค่าตอบแทน)
A16: =Note!$B$2 -> 2565 | B16: 201 | C16: ค่าตอบแทนพิเศษพนักงานราชการ
A17: =Note!$B$2 -> 2565 | B17: 202 | C17: ค่าสอนเกินภาระงาน
A18: =Note!$B$2 -> 2565 | B18: 203 | C18: ค่าธุรการนอกเวลา
A19: =Note!$B$2 -> 2565 | B19: 204 | C19: ค่าสอนภาคฤดูร้อน
A20: =Note!$B$2 -> 2565 | B20: 205 | C20: ค่าสอนเทียบโอน
A21: =Note!$B$2 -> 2565 | B21: 206 | C21: ค่าจ้างครูรายเดือน
A22: =Note!$B$2 -> 2565 | B22: 207 | C22: ค่าจ้างเจ้าหน้าที่รายเดือน
A23: =Note!$B$2 -> 2565 | B23: 208 | C23: ค่าครองชีพครูรายเดือน
A24: =Note!$B$2 -> 2565 | B24: 209 | C24: ค่าครองชีพเจ้าหน้าที่รายเดือน
A25: =Note!$B$2 -> 2565 | B25: 210
A26: =Note!$B$2 -> 2565 | B26: 211
A27: =Note!$B$2 -> 2565 | B27: 212
A28: =Note!$B$2 -> 2565 | B28: 213
A29: =Note!$B$2 -> 2565 | B29: 214
A30: 3. งบดำเนินงาน (ค่าใช้สอย)
A31: =Note!$B$2 -> 2565 | B31: 301 | C31: ค่าจ้างซ่อมครุภัณฑ์การศึกษาและสำนักงาน
A32: =Note!$B$2 -> 2565 | B32: 302 | C32: ค่าซ่อมยานพาหนะ
A33: =Note!$B$2 -> 2565 | B33: 303 | C33: ค่าจ้างติดตั้ง ซ่อมแซมระบบสาธารณูปโภค
A34: =Note!$B$2 -> 2565 | B34: 304 | C34: ค่าจ้างซ่อมอาคารสถานที่/พัฒนาสิ่งแวดล้อม
A35: =Note!$B$2 -> 2565 | B35: 305 | C35: ค่าเบี้ยเลี้ยง พาหนะเดิอนทาง และที่พัก
A36: =Note!$B$2 -> 2565 | B36: 306 | C36: ค่าสมทบประกันสังคม(พนักงานราชการ)
A37: =Note!$B$2 -> 2565 | B37: 307 | C37: ค่าสมทบประกันสังคม(ครูรายเดือน)
A38: =Note!$B$2 -> 2565 | B38: 308 | C38: ค่าสมทบประกันสังคม(เจ้าหน้าที่รายเดือน)
A39: =Note!$B$2 -> 2565 | B39: 309 | C39: ค่าใช้สอยอื่นๆ(ไม่เกิน50,000/ครั้ง/รายการ)
A40: =Note!$B$2 -> 2565 | B40: 310
A41: =Note!$B$2 -> 2565 | B41: 311
...

Sheet รายการจัดสรร
A2: รายการจัดสรรงบประมาณ 65
A3: ลำดับที่ | B3: รายการ | E3: ไตรมาสที่ 1 | H3: ไตรมาสที่ 2 | K3: ไตรมาสที่ 3 | N3: ไตรมาสที่ 4 | Q3: รวม | R3: จัดสรรไป | S3: คงเหลือ
E4: ต.ค. | F4: พ.ย. | G4: ธ.ค. | H4: ม.ค. | I4: ก.พ. | J4: มี.ค. | K4: เม.ย. | L4: พ.ค. | M4: มิ.ย. | N4: ก.ค. | O4: ส.ค. | P4: ก.ย.
A5: 1 | B5: ปวช | F5: 176100 | Q5: =SUM(E5:P5) -> 176100
A6: 2 | B6: ปวส. | F6: 312200 | Q6: =SUM(E6:P6) -> 312200
A7: 3 | B7: ค่าสาธารณูปโภค | F7: 240000 | Q7: =SUM(E7:P7) -> 240000
A8: 4 | B8: ระยะสั้น | F8: 272000 | Q8: =SUM(E8:P8) -> 272000
A9: 5 | B9: สมทบประกันสังคม | F9: 24040 | Q9: =SUM(E9:P9) -> 24040
A10: 6 | B10: เงินเดือนพนักงานราชการ | E10: 765050 | Q10: =SUM(E10:P10) -> 765050
A11: 7 | B11: ทุนเฉลิมราชกุมารี | J11: 85000 | Q11: =SUM(E11:P11) -> 85000
A12: 8 | B12: กิจกรรมพัฒนาผู้เรียน | F12: 286900 | Q12: =SUM(E12:P12) -> 286900
A13: 9 | B13: อุปกรณ์การเรียน | F13: 138920 | Q13: =SUM(E13:P13) -> 138920
A14: 10 | B14: ค่าเครื่องแบบนักเรียน | Q14: =SUM(E14:P14) -> 0
A15: 11 | B15: ค่าจัดการเรียนการสอน | F15: 1907050 | Q15: =SUM(E15:P15) -> 1907050
A16: 12 | B16: ค่าหนังสือเรียน | F16: 604000 | Q16: =SUM(E16:P16) -> 604000
A17: 13 | B17: ค่าเครื่องมือ | Q17: =SUM(E17:P17) -> 0
A18: 14 | B18: ชุดปฎิบัติการเขียนแบบด้วยคอมพิวเตอร์ | E18: 1500000 | Q18: =SUM(E18:P18) -> 1500000
A19: 15 | B19: ชุดครุภัณฑ์ห้องเรียนอัจฉริยะ | E19: 2000000 | Q19: =SUM(E19:P19) -> 2000000
A20: 16 | B20: อุดหนุนรายได้ระหว่างเรียน | Q20: =SUM(E20:P20) -> 0
A21: 17 | B21: อุดหนุนสิ่งประดิษฐ์ | Q21: =SUM(E21:P21) -> 0
A22: 18 | B22: อุดหนุน อวท. | Q22: =SUM(E22:P22) -> 0
A23: 19 | B23: ทวิศึกษา | I23: 89900 | Q23: =SUM(E23:P23) -> 89900
A24: 20 | B24: ทวิภาคี | Q24: =SUM(E24:P24) -> 0
A25: 21 | B25: Fixit center | Q25: =SUM(E25:P25) -> 0
A26: 22 | B26: คืนครูให้นักเรียน | G26: 58800 | Q26: =SUM(E26:P26) -> 58800
A27: 23 | B27: เร่งประสิทธิภาพการสอนครู | G27: 94800 | Q27: =SUM(E27:P27) -> 94800
A28: 24 | B28: สถานศึกษาตามรอยฯ | Q28: =SUM(E28:P28) -> 0
A29: 25 | B29: ส่งเสริมการประกอบอาชีพอิสระ | Q29: =SUM(E29:P29) -> 0
A30: 26 | B30: ลดเวลาเรียนเพิ่มเวลารู้ | Q30: =SUM(E30:P30) -> 0
A31: 27 | B31: ภูมิภาคเอเชียตะวันออกเฉียงใต้ | Q31: =SUM(E31:P31) -> 0
A32: 28 | B32: รณรงค์ลดอุบัติเหตุ | Q32: =SUM(E32:P32) -> 0
A33: 29 | B33: ออกกลางคัน | Q33: =SUM(E33:P33) -> 0
A34: 30 | B34: โครงการอาชีวะอาษา | Q34: =SUM(E34:P34) -> 0
A35: 31 | B35: โครงการตั้งจุดบริการอำนวยความสะดวก | Q35: =SUM(E35:P35) -> 0
A36: 32 | C36: โครงการอาชีวะต้านยาเสพติด | Q36: =SUM(E36:P36) -> 0
A37: 33 | B37: โครงการการประกันฯ | Q37: =SUM(E37:P37) -> 0
A38: 34 | B38: เสริมสร้างพัฒนาศักยภาพครู | Q38: =SUM(E38:P38) -> 0
A39: 35 | B39: โครงการประกันคุณภาพ | Q39: =SUM(E39:P39) -> 0
A40: รวมทั้งสิ้น | E40: =SUM(E5:E39) -> 4265050 | F40: =SUM(F5:F39) -> 3961210 | G40: =SUM(G5:G39) -> 153600 | H40: =SUM(H5:H39) -> 0 | I40: =SUM(I5:I39) -> 89900 | J40: =SUM(J5:J39) -> 85000 | K40: =SUM(K5:K39) -> 0 | L40: =SUM(L5:L39) -> 0 | ... P40: =SUM(P5:P39) -> 0 | Q40: =SUM(E40:P40) -> 8554760

Sheet งปม.เข้า
E1: รายการรายรับ ปีงบประมาณ | G1: =Note!$B$2 -> 2565 | H1: =Note!$B$1 -> วิทยาลัยการอาชีพนวมินทราชินีแม่ฮ่องสอน
E2: เงินงบประมาณ | H2: เงินอุดหนุน | O2: งบรายจ่ายอื่น | Q2: เงิน บกศ. | S2: รวม
E3: ปวช. | F3: ปวส. | G3: ระยะสั้น | H3: จัดการเรียน | I3: หนังสือ | J3: เครื่องแบบ | K3: กิจกรรม | L3: อุปกรณ์ | M3: เครื่องมือ | N3: ทั่วไป | O3: โครงการ | P3: เงินนอก | Q3: เงินรายได้ | R3: เงินรับฝาก
D4: รวมรายรับ | E4: =SUM(E7:E107) -> 12525890 | F4: =SUM(F7:F107) -> 312200 | G4: =SUM(G7:G107) -> 272000 | H4: =SUM(H7:H107) -> 1907050 | I4: =SUM(I7:I107) -> 604000 | J4: =SUM(J7:J107) -> 0 | K4: =SUM(K7:K107) -> 286900 | L4: =SUM(L7:L107) -> 138920 | N4: =SUM(N7:N107) -> 85000 | O4: =SUM(O7:O107) -> 599500 | P4: =SUM(P7:P107) -> 2554.4 | Q4: =SUM(Q7:Q107) -> 728817.83 | R4: =SUM(R7:R107) -> 0 | S4: =SUM(E4:R4) -> 17462832
A6: ลำดับ | B6: วันที่ เดือน พ.ศ. | C6: เอกสารการจัดสรร | D6: รหัสเอกสาร | E6: ปวช. | F6: ปวส. | G6: ระยะสั้น | H6: อุดหนุน | I6: หนังสือ | J6: เครื่องแบบ | K6: กิจกรรม | L6: อุปกรณ์ | N6: เครื่องมือ | O6: โครงการ | P6: =+P3 -> เงินนอก | Q6: เงินรายได้ | R6: เงินรับฝาก | S6: รวม
A7: 1 | C7: เงิน บกศ. | Q7: =79431.83+192977.83+456408.17 -> 728817.83
A8: 2 | B8: 14 ตุลาคม 2564 | C8: ชุดปฏิบัติการเขียนแบบด้วยคอมพิวเตอร์ | D8: 2565001 | E8: 1500000 | S8: =SUM(E8:R8) -> 1500000
A9: 3 | C9: ชุดครุภัณฑ์ห้องเรียนอัจฉริยะ | E9: 2000000 | S9: =SUM(E9:R9) -> 2000000
A10: 4 | B10: 18 ตุลาคม 2564 | C10: วัสดุมุงหลังคาเมทัลชีท | D10: 2565002 | E10: 5660700 | S10: =SUM(E10:R10) -> 5660700
A11: 5 | B11: 18 ตุลาคม 2564 | C11: ค่าตอบแทนพนักงานราชการ | D11: 2565003 | E11: 765050 | S11: =SUM(E11:R11) -> 765050
A12: 6 | B12: 2 พ.ย.64 | C12: ค่าประกันสังคม | D12: 2565004 | E12: 24040 | S12: =SUM(E12:R12) -> 24040
A13: 7 | B13: 22 พ.ย.64 | C13: ปวช+ปวส+ระยะสั้น | D13: 2565005 | E13: 176100 | F13: 312200 | G13: 272000 | S13: =SUM(E13:R13) -> 760300
A14: 8 | C14: ค่าสาธารณูปโภค | E14: 2400000 | S14: =SUM(E14:R14) -> 2400000
A15: 9 | B15: 30 พ.ย 64 | D15: 2565006 | H15: 1907050 | I15: 604000 | K15: 286900 | L15: 138920 | S15: =SUM(E15:R15) -> 2936870
A16: 10 | B16: 21 ธ.ค.65 | C16: โครงการเร่งประสิทธิภาพครู | D16: 2565007 | O16: 94800 | S16: =SUM(E16:R16) -> 94800
A17: 11 | B17: 21 ธ.ค.65 | C17: โครงการคืนครู | D17: 2565008 | O17: 58800 | S17: =SUM(E17:R17) -> 58800
A18: 12 | C18: เงินนอกงบประมาณ | P18: 2554.4 | S18: =SUM(E18:R18) -> 2554.4
A19: 13 | B19: 17 ก.พ.65 | C19: โครงการ Fix it Center | D19: 2565009 | O19: 291000 | S19: =SUM(E19:R19) -> 291000
A20: 14 | B20: 23 ก.พ.65 | C20: โครงการจัดการศึกษาเรียนร่วม ทวิศึกษา | D20: 2565010 | O20: 89900 | S20: =SUM(E20:R20) -> 89900
A21: 15 | B21: 7 มี.ค.65 | C21: ทุนหารศึกษาเฉลิมราชกุมารี | D21: 2565011 | N21: 85000 | S21: =SUM(E21:R21) -> 85000
A22: 16 | B22: 7 มี.ค.65 | C22: โครงการพัฒนาศักยภาพผู้เรียนอาชีวศึกษาในการเป็นผู้ประกอบการ | D22: 2565012 | O22: 65000 | S22: =SUM(E22:R22) -> 65000
A23: 17 | S23: =SUM(E23:R23) -> 0
A24: 18 | S24: =SUM(E24:R24) -> 0
A25: 19 | S25: =SUM(E25:R25) -> 0
A26: 20 | S26: =SUM(E26:R26) -> 0
A27: 21 | S27: =SUM(E27:R27) -> 0
A28: 22 | S28: =SUM(E28:R28) -> 0
A29: 23 | S29: =SUM(E29:R29) -> 0
A30: 24 | S30: =SUM(E30:R30) -> 0
A31: 25 | S31: =SUM(E31:R31) -> 0
A32: 26 | S32: =SUM(E32:R32) -> 0
A33: 27 | S33: =SUM(E33:R33) -> 0
A34: 28 | S34: =SUM(E34:R34) -> 0
... A107: 101 | S107: =SUM(E107:R107) -> 0

Sheet จัดสรร งปม.
D1: รายการจัดสรรรายจ่ายปี งปม. | F1: =Note!$B$2 -> 2565 | G1: =Note!$B$1 -> วิทยาลัยการอาชีพนวมินทราชินีแม่ฮ่องสอน
D2: เงินงบประมาณ | G2: เงินอุดหนุน | N2: งบรายจ่ายอื่น | P2: เงิน บกศ. | R2: รวม | S2: =NOW() -> 44648.644
D3: ปวช. | E3: ปวส. | F3: ระยะสั้น | G3: จัดการเรียน | H3: หนังสือ | I3: เครื่องแบบ | J3: กิจกรรม | K3: อุปกรณ์ | L3: เครื่องมือ | M3: ทั่วไป | N3: โครงการ | O3: เงินนอก | P3: เงินรายได้ | Q3: เงินรับฝาก | S3: สรุปรายการจ่ายจากยอดจัดสสร
C4: รับมา | D4: =งปม.เข้า!E4 -> 12525890 | E4: =งปม.เข้า!F4 -> 312200 | F4: =งปม.เข้า!G4 -> 272000 | G4: =งปม.เข้า!H4 -> 1907050 | H4: =งปม.เข้า!I4 -> 604000 | I4: =งปม.เข้า!J4 -> 0 | J4: =งปม.เข้า!K4 -> 286900 | K4: =งปม.เข้า!L4 -> 138920 | ... Q4: =งปม.เข้า!R4 -> 0 | R4: =SUM(D4:Q4) -> 17462832 | S4: ใช้ไปแล้ว | T4: ร้อยละ | U4: เหลือ
C5: จัดสรรไป | D5: =SUM(D9:D120) -> 10365953 | E5: =SUM(E9:E120) -> 310768 | F5: =SUM(F9:F120) -> 158347.3 | G5: =SUM(G9:G120) -> 1984939.4 | H5: =SUM(H9:H120) -> 0 | I5: =SUM(I9:I120) -> 0 | J5: =SUM(J9:J120) -> 267218 | K5: =SUM(K9:K120) -> 135240 | ... Q5: =SUM(Q9:Q120) -> 0 | R5: =SUM(D5:Q5) -> 14236526 | S5: =SUM(S10:S120) -> 8548554.4 | T5: =(100/R5)*S5 -> 60.046631 | U5: =SUM(U10:U120) -> 5687972
C6: คงเหลือ | D6: =D4-D5 -> 2159936.8 | E6: =E4-E5 -> 1432 | F6: =F4-F5 -> 113652.7 | G6: =G4-G5 -> -77889.45 | H6: =H4-H5 -> 604000 | I6: =I4-I5 -> 0 | J6: =J4-J5 -> 19682 | K6: =K4-K5 -> 3680 | M6: =M4-M5 -> 0 | N6: =N4-N5 -> -9605.5 | O6: =O4-O5 -> 296.48 | P6: =P4-P5 -> 411120.85 | Q6: =Q4-Q5 -> 0 | R6: =R4-R5 -> 3226305.8
D8: ปวช. | E8: ปวส. | F8: ระยะสั้น | G8: อุดหนุน | H8: หนังสือ | I8: เครื่องแบบ | J8: กิจกรรม | K8: อุปกรณ์ | L8: เครื่องมือ | M8: =M3 -> ทั่วไป | N8: โครงการ | O8: =+O3 -> เงินนอก | P8: เงินรายได้ | Q8: เงินรับฝาก | R8: รวม | S8: ใช้ไปแล้ว | T8: ร้อยละ | U8: เหลือ
A9: 1. งบบุคลากร
A10: =Note!$B$2 -> 2565 | B10: 101 | C10: เงินเดือนพนักงานราชการ | D10: 765050 | R10: =SUM(D10:Q10) -> 765050 | S10: ='101'!$S$6 -> 765000 | T10: =(100/R10)*S10 -> 99.993464 | U10: =R10-S10 -> 50
A11: =Note!$B$2 -> 2565 | B11: 102 | C11: สำรอง 1 | R11: =SUM(D11:Q11) -> 0 | S11: ='102'!$S$6 -> 0 | T11: =(100/R11)*S11 -> #DIV/0! | U11: =R11-S11 -> 0
A12: =Note!$B$2 -> 2565 | B12: 103 | C12: สำรอง 2 | R12: =SUM(D12:Q12) -> 0 | S12: ='103'!$S$6 -> 0 | T12: =(100/R12)*S12 -> #DIV/0! | U12: =R12-S12 -> 0
A13: =Note!$B$2 -> 2565 | B13: 104 | C13: สำรอง 3 | R13: =SUM(D13:Q13) -> 0 | S13: ='104'!$S$6 -> 0 | T13: =(100/R13)*S13 -> #DIV/0! | U13: =R13-S13 -> 0
A14: =Note!$B$2 -> 2565 | B14: 105 | C14: สำรอง 4 | R14: =SUM(D14:Q14) -> 0 | S14: ='105'!$S$6 -> 0 | T14: =(100/R14)*S14 -> #DIV/0! | U14: =R14-S14 -> 0
A15: 2. งบดำเนินงาน (ค่าตอบแทน)
A16: =Note!$B$2 -> 2565 | B16: 201 | C16: ค่าตอบแทนพิเศษพนักงานราชการ | R16: =SUM(D16:Q16) -> 0 | S16: ='201'!$S$6 -> 0 | T16: =(100/R16)*S16 -> #DIV/0! | U16: =R16-S16 -> 0
A17: =Note!$B$2 -> 2565 | B17: 202 | C17: ค่าสอนเกินภาระงาน | G17: =169920 -> 169920 | R17: =SUM(D17:Q17) -> 169920 | S17: ='202'!$S$6 -> 169920 | T17: =(100/R17)*S17 -> 100 | U17: =R17-S17 -> 0
A18: =Note!$B$2 -> 2565 | B18: 203 | C18: ค่าธุรการนอกเวลา | R18: =SUM(D18:Q18) -> 0 | S18: ='203'!$S$6 -> 0 | T18: =(100/R18)*S18 -> #DIV/0! | U18: =R18-S18 -> 0
A19: =Note!$B$2 -> 2565 | B19: 204 | C19: ค่าสอนภาคฤดูร้อน | R19: =SUM(D19:Q19) -> 0 | S19: ='204'!$S$6 -> 0 | T19: =(100/R19)*S19 -> #DIV/0! | U19: =R19-S19 -> 0
A20: =Note!$B$2 -> 2565 | B20: 205 | C20: ค่าสอนเทียบโอน | R20: =SUM(D20:Q20) -> 0 | S20: ='205'!$S$6 -> 0 | T20: =(100/R20)*S20 -> #DIV/0! | U20: =R20-S20 -> 0
A21: =Note!$B$2 -> 2565 | B21: 206 | C21: ค่าจ้างครูรายเดือน | G21: =238200+260540+260540+260540 -> 1019820 | R21: =SUM(D21:Q21) -> 1019820 | S21: ='206'!$S$6 -> 1019820 | T21: =(100/R21)*S21 -> 100 | U21: =R21-S21 -> 0
A22: =Note!$B$2 -> 2565 | B22: 207 | C22: ค่าจ้างเจ้าหน้าที่รายเดือน | G22: =171026.45+167120.67+169600.33+149090 -> 656837.45 | R22: =SUM(D22:Q22) -> 656837.45 | S22: ='207'!$S$6 -> 656837.45 | T22: =(100/R22)*S22 -> 100 | U22: =R22-S22 -> 0
A23: =Note!$B$2 -> 2565 | B23: 208 | C23: ค่าครองชีพครูรายเดือน | R23: =SUM(D23:Q23) -> 0 | S23: ='208'!$S$6 -> 0 | T23: =(100/R23)*S23 -> #DIV/0! | U23: =R23-S23 -> 0
A24: =Note!$B$2 -> 2565 | B24: 209 | C24: ค่าครองชีพเจ้าหน้าที่รายเดือน | R24: =SUM(D24:Q24) -> 0 | S24: ='209'!$S$6 -> 0 | T24: =(100/R24)*S24 -> #DIV/0! | U24: =R24-S24 -> 0
A25: =Note!$B$2 -> 2565 | B25: 210 | C25: สำรอง 1 | R25: =SUM(D25:Q25) -> 0 | S25: ='210'!$S$6 -> 0 | T25: =(100/R25)*S25 -> #DIV/0! | U25: =R25-S25 -> 0
A26: =Note!$B$2 -> 2565 | B26: 211 | C26: สำรอง 2 | R26: =SUM(D26:Q26) -> 0 | S26: ='211'!$S$6 -> 0 | T26: =(100/R26)*S26 -> #DIV/0! | U26: =R26-S26 -> 0
A27: =Note!$B$2 -> 2565 | B27: 212 | C27: สำรอง 3 | R27: =SUM(D27:Q27) -> 0 | S27: ='212'!$S$6 -> 0 | T27: =(100/R27)*S27 -> #DIV/0! | U27: =R27-S27 -> 0
A28: =Note!$B$2 -> 2565 | B28: 213 | C28: สำรอง 4 | R28: =SUM(D28:Q28) -> 0 | S28: ='213'!$S$6 -> 0 | T28: =(100/R28)*S28 -> #DIV/0! | U28: =R28-S28 -> 0
A29: =Note!$B$2 -> 2565 | B29: 214 | C29: สำรอง 5 | R29: =SUM(D29:Q29) -> 0 | S29: ='214'!$S$6 -> 0 | T29: =(100/R29)*S29 -> #DIV/0! | U29: =R29-S29 -> 0
A30: 3. งบดำเนินงาน (ค่าใช้สอย)
A31: =Note!$B$2 -> 2565 | B31: 301 | C31: ค่าจ้างซ่อมครุภัณฑ์การศึกษาและสำนักงาน | R31: =SUM(D31:Q31) -> 0 | S31: ='301'!$S$6 -> 10 | T31: =(100/R31)*S31 -> #DIV/0! | U31: =R31-S31 -> -10
A32: =Note!$B$2 -> 2565 | B32: 302 | C32: ค่าซ่อมยานพาหนะ | F32: =4920 -> 4920 | R32: =SUM(D32:Q32) -> 4920 | S32: ='302'!$S$6 -> 4920 | T32: =(100/R32)*S32 -> 100 | U32: =R32-S32 -> 0
A33: =Note!$B$2 -> 2565 | B33: 303 | C33: ค่าจ้างติดตั้ง ซ่อมแซมระบบสาธารณูปโภค | R33: =SUM(D33:Q33) -> 0 | S33: ='303'!$S$6 -> 30 | T33: =(100/R33)*S33 -> #DIV/0! | U33: =R33-S33 -> -30
A34: =Note!$B$2 -> 2565 | B34: 304 | C34: ค่าจ้างซ่อมอาคารสถานที่/พัฒนาสิ่งแวดล้อม | F34: =48768.7 -> 48768.7 | G34: 9670 | R34: =SUM(D34:Q34) -> 58438.7 | S34: ='304'!$S$6 -> 58438.7 | T34: =(100/R34)*S34 -> 100 | U34: =R34-S34 -> 0
A35: =Note!$B$2 -> 2565 | B35: 305 | C35: ค่าเบี้ยเลี้ยง พาหนะเดินทาง และที่พัก | F35: =27400 -> 27400 | G35: =2760+5020 -> 7780 | J35: =27980+8880+16440+8740+82118+30040+23500 -> 197698 | P35: 71780 | R35: =SUM(D35:Q35) -> 304658 | S35: ='305'!$S$6 -> 304658 | T35: =(100/R35)*S35 -> 100 | U35: =R35-S35 -> 0
A36: =Note!$B$2 -> 2565 | B36: 306 | C36: ค่าสมทบประกันสังคม(พนักงานราชการ) | D36: 24040 | R36: =SUM(D36:Q36) -> 24040 | S36: ='306'!$S$6 -> 23450 | T36: =(100/R36)*S36 -> 97.545757 | U36: =R36-S36 -> 590
A37: =Note!$B$2 -> 2565 | B37: 307 | C37: ค่าสมทบประกันสังคม(ครูรายเดือน) | G37: =38539+13027+12452 -> 64018 | R37: =SUM(D37:Q37) -> 64018 | S37: ='307'!$S$6 -> 64018 | T37: =(100/R37)*S37 -> 100 | U37: =R37-S37 -> 0
A38: =Note!$B$2 -> 2565 | B38: 308 | C38: ค่าสมทบประกันสังคม(เจ้าหน้าที่รายเดือน) | G38: =24758+7962+7458 -> 40178 | R38: =SUM(D38:Q38) -> 40178 | S38: ='308'!$S$6 -> 40178 | T38: =(100/R38)*S38 -> 100 | U38: =R38-S38 -> 0
A39: =Note!$B$2 -> 2565 | B39: 309 | C39: ค่าใช้สอยอื่นๆ(ไม่เกิน50,000/ครั้ง/รายการ) | R39: =SUM(D39:Q39) -> 0 | S39: ='309'!$S$6 -> 90 | T39: =(100/R39)*S39 -> #DIV/0! | U39: =R39-S39 -> -90
A40: =Note!$B$2 -> 2565 | B40: 310 | C40: ค่าน้ำมัน | F40: =21445.6 -> 21445.6 | N40: =4141+2464.5 -> 6605.5 | R40: =SUM(D40:Q40) -> 28051.1 | S40: ='310'!$S$6 -> 28051.1 | T40: =(100/R40)*S40 -> 100 | U40: =R40-S40 -> 0
A41: =Note!$B$2 -> 2565 | B41: 311 | C41: ค่าขยะมูลฝอย | P41: =4000+1000+1000 -> 6000 | R41: =SUM(D41:Q41) -> 6000 | S41: ='311'!$S$6 -> 6000 | T41: =(100/R41)*S41 -> 100 | U41: =R41-S41 -> 0
...

Sheet 101
A1: กลับไปที่หน้าจัดสรร งปม.
E2: =Note!$B$1 -> วิทยาลัยการอาชีพนวมินทราชินีแม่ฮ่องสอน
E3: เงินงบประมาณ | H3: เงินอุดหนุน | O3: งบรายจ่ายอื่น | Q3: เงิน บกศ. | S3: รวม
E4: ปวช. | F4: ปวส. | G4: ระยะสั้น | H4: จัดการเรียน | I4: หนังสือ | J4: เครื่องแบบ | K4: กิจกรรม | L4: อุปกรณ์ | M4: เครื่องมือ | N4: ทั่วไป | O4: โครงการ | P4: เงินนอกงบ | Q4: เงินรายได้ | R4: เงินรับฝาก
D5: ได้รับมา | E5: ='จัดสรร งปม.'!D10 -> 765050 | F5: ='จัดสรร งปม.'!E10 -> 0 | G5: ='จัดสรร งปม.'!F10 -> 0 | H5: ='จัดสรร งปม.'!G10 -> 0 | I5: ='จัดสรร งปม.'!H10 -> 0 | J5: ='จัดสรร งปม.'!I10 -> 0 | K5: ='จัดสรร งปม.'!J10 -> 0 | L5: ='จัดสรร งปม.'!K10 -> 0 | N5: ='จัดสรร งปม.'!L10 -> 0 | P5: ='จัดสรร งปม.'!N10 -> 0 | Q5: ='จัดสรร งปม.'!P10 -> 0 | R5: ='จัดสรร งปม.'!Q10 -> 0 | S5: ='จัดสรร งปม.'!R10 -> 765050
D6: ใช้ไปแล้ว | E6: =SUM(E11:E45) -> 765000 | F6: =SUM(F11:F45) -> 0 | G6: =SUM(G11:G45) -> 0 | H6: =SUM(H11:H45) -> 0 | I6: =SUM(I11:I45) -> 0 | J6: =SUM(J11:J45) -> 0 | K6: =SUM(K11:K45) -> 0 | L6: =SUM(L11:L45) -> 0 | N6: =SUM(N11:N45) -> 0 | P6: =SUM(P11:P45) -> 0 | Q6: =SUM(Q11:Q45) -> 0 | R6: =SUM(R11:R45) -> 0 | S6: =SUM(S11:S45) -> 765000
B7: งบบุคลากร | D7: เหลือ | E7: =E5-E6 -> 50 | F7: =F5-F6 -> 0 | G7: =G5-G6 -> 0 | H7: =H5-H6 -> 0 | I7: =I5-I6 -> 0 | J7: =J5-J6 -> 0 | K7: =K5-K6 -> 0 | L7: =L5-L6 -> 0 | N7: =N5-N6 -> 0 | P7: =P5-P6 -> 0 | Q7: =Q5-Q6 -> 0 | R7: =R5-R6 -> 0 | S7: =S5-S6 -> 50
B8: รหัสรายการจ่าย | C8: ='จัดสรร งปม.'!$B$10 -> 101
B9: รายการจ่าย | C9: ='จัดสรร งปม.'!$C$10 -> เงินเดือนพนักงานราชการ
A10: รหัส | B10: วันที่ | C10: ชื่อผู้ขอใช้ | D10: แผนก/งาน | E10: ปวช. | F10: ปวส. | G10: ระยะสั้น | H10: อุดหนุน | I10: หนังสือ | J10: เครื่องแบบ | K10: กิจกรรม | L10: อุปกรณ์ | M10: =M4 -> เครื่องมือ | N10: =N4 -> ทั่วไป | O10: =+O4 -> โครงการ | P10: =+P4 -> เงินนอกงบ | Q10: เงินรายได้ | R10: เงินรับฝาก | S10: รวม
A11: 001 | B11: 26 ต.ค. 64 | C11: นางอำโนญ พัฒนกสิกร | D11: การเงิน | E11: 147120 | S11: =SUM(E11:R11) -> 147120
A12: 002 | B12: 17 พ.ย.64 | C12: นางอำโนญ พัฒนกสิกร | D12: การเงิน | E12: 147120 | S12: =SUM(E12:R12) -> 147120
A13: 003 | B13: 9 ธ.ค. 64 | C13: นางอำโนญ พัฒนกสิกร | D13: การเงิน | E13: 147120 | S13: =SUM(E13:R13) -> 147120
A14: 004 | B14: 17 ม.ค. 65 | C14: นางอำโนญ พัฒนกสิกร | D14: การเงิน | E14: 147120 | S14: =SUM(E14:R14) -> 147120
A15: 005 | B15: 21 ก.พ.65 | C15: นางอำโนญ พัฒนกสิกร | D15: การเงิน | E15: 147120 | S15: =SUM(E15:R15) -> 147120
A16: 006 | B16: 4 มี.ค. 65 | C16: นางอำโนญ พัฒนกสิกร | D16: การเงิน | E16: 29400 | S16: =SUM(E16:R16) -> 29400
A17: 007 | S17: =SUM(E17:R17) -> 0
A18: 008 | S18: =SUM(E18:R18) -> 0
A19: 009 | S19: =SUM(E19:R19) -> 0
A20: 010 | S20: =SUM(E20:R20) -> 0
A21: 011 | S21: =SUM(E21:R21) -> 0
A22: 012 | S22: =SUM(E22:R22) -> 0
A23: 013 | S23: =SUM(E23:R23) -> 0
A24: 014 | S24: =SUM(E24:R24) -> 0
A25: 015 | S25: =SUM(E25:R25) -> 0
A26: 016 | S26: =SUM(E26:R26) -> 0
A27: 017 | S27: =SUM(E27:R27) -> 0
A28: 018 | S28: =SUM(E28:R28) -> 0
... A45: 035 | S45: =SUM(E45:R45) -> 0

Sheet 102
A1: กลับไปที่หน้าจัดสรร งปม.
E2: =Note!$B$1 -> วิทยาลัยการอาชีพนวมินทราชินีแม่ฮ่องสอน
E3: เงินงบประมาณ | H3: เงินอุดหนุน | O3: งบรายจ่ายอื่น | Q3: เงิน บกศ. | S3: รวม
E4: ปวช. | F4: ปวส. | G4: ระยะสั้น | H4: จัดการเรียน | I4: หนังสือ | J4: เครื่องแบบ | K4: กิจกรรม | L4: อุปกรณ์ | M4: เครื่องมือ | N4: ทั่วไป | O4: โครงการ | P4: เงินนอกงบ | Q4: เงินรายได้ | R4: เงินรับฝาก
D5: ได้รับมา | E5: ='จัดสรร งปม.'!D11 -> 0 | F5: ='จัดสรร งปม.'!E11 -> 0 | G5: ='จัดสรร งปม.'!F11 -> 0 | H5: ='จัดสรร งปม.'!G11 -> 0 | I5: ='จัดสรร งปม.'!H11 -> 0 | J5: ='จัดสรร งปม.'!I11 -> 0 | K5: ='จัดสรร งปม.'!J11 -> 0 | L5: ='จัดสรร งปม.'!K11 -> 0 | N5: ='จัดสรร งปม.'!L11 -> 0 | P5: ='จัดสรร งปม.'!N11 -> 0 | Q5: ='จัดสรร งปม.'!P11 -> 0 | R5: ='จัดสรร งปม.'!Q11 -> 0 | S5: ='จัดสรร งปม.'!R11 -> 0
D6: ใช้ไปแล้ว | E6: =SUM(E11:E45) -> 0 | F6: =SUM(F11:F45) -> 0 | G6: =SUM(G11:G45) -> 0 | H6: =SUM(H11:H45) -> 0 | I6: =SUM(I11:I45) -> 0 | J6: =SUM(J11:J45) -> 0 | K6: =SUM(K11:K45) -> 0 | L6: =SUM(L11:L45) -> 0 | N6: =SUM(N11:N45) -> 0 | P6: =SUM(P11:P45) -> 0 | Q6: =SUM(Q11:Q45) -> 0 | R6: =SUM(R11:R45) -> 0 | S6: =SUM(S11:S45) -> 0
B7: งบบุคลากร | D7: เหลือ | E7: =E5-E6 -> 0 | F7: =F5-F6 -> 0 | G7: =G5-G6 -> 0 | H7: =H5-H6 -> 0 | I7: =I5-I6 -> 0 | J7: =J5-J6 -> 0 | K7: =K5-K6 -> 0 | L7: =L5-L6 -> 0 | N7: =N5-N6 -> 0 | P7: =P5-P6 -> 0 | Q7: =Q5-Q6 -> 0 | R7: =R5-R6 -> 0 | S7: =S5-S6 -> 0
B8: รหัสรายการจ่าย | C8: ='จัดสรร งปม.'!$B$11 -> 102
B9: รายการจ่าย | C9: ='จัดสรร งปม.'!$C$11 -> สำรอง 1
A10: รหัส | B10: วันที่ | C10: ชื่อผู้ขอใช้ | D10: แผนก/งาน | E10: ปวช. | F10: ปวส. | G10: ระยะสั้น | H10: อุดหนุน | I10: หนังสือ | J10: เครื่องแบบ | K10: กิจกรรม | L10: อุปกรณ์ | M10: เครื่องมือ | N10: ทั่วไป | O10: =+O4 -> โครงการ | P10: =+P4 -> เงินนอกงบ | Q10: เงินรายได้ | R10: เงินรับฝาก | S10: รวม
A11: 001 | S11: =SUM(E11:R11) -> 0
A12: 002 | S12: =SUM(E12:R12) -> 0
A13: 003 | S13: =SUM(E13:R13) -> 0
A14: 004 | S14: =SUM(E14:R14) -> 0
A15: 005 | S15: =SUM(E15:R15) -> 0
A16: 006 | S16: =SUM(E16:R16) -> 0
A17: 007 | S17: =SUM(E17:R17) -> 0
A18: 008 | S18: =SUM(E18:R18) -> 0
A19: 009 | S19: =SUM(E19:R19) -> 0
A20: 010 | S20: =SUM(E20:R20) -> 0
A21: 011 | S21: =SUM(E21:R21) -> 0
A22: 012 | S22: =SUM(E22:R22) -> 0
... A45: 035 | S45: =SUM(E45:R45) -> 0

Sheet 103
A1: กลับไปที่หน้าจัดสรร งปม.
E2: =Note!$B$1 -> วิทยาลัยการอาชีพนวมินทราชินีแม่ฮ่องสอน
E3: เงินงบประมาณ | H3: เงินอุดหนุน | O3: งบรายจ่ายอื่น | Q3: เงิน บกศ. | S3: รวม
E4: ปวช. | F4: ปวส. | G4: ระยะสั้น | H4: จัดการเรียน | I4: หนังสือ | J4: เครื่องแบบ | K4: กิจกรรม | L4: อุปกรณ์ | M4: เครื่องมือ | N4: ทั่วไป | O4: โครงการ | P4: เงินนอกงบ | Q4: เงินรายได้ | R4: เงินรับฝาก
D5: ได้รับมา | E5: ='จัดสรร งปม.'!D12 -> 0 | F5: ='จัดสรร งปม.'!E12 -> 0 | G5: ='จัดสรร งปม.'!F12 -> 0 | H5: ='จัดสรร งปม.'!G12 -> 0 | I5: ='จัดสรร งปม.'!H12 -> 0 | J5: ='จัดสรร งปม.'!I12 -> 0 | K5: ='จัดสรร งปม.'!J12 -> 0 | L5: ='จัดสรร งปม.'!K12 -> 0 | N5: ='จัดสรร งปม.'!L12 -> 0 | P5: ='จัดสรร งปม.'!N12 -> 0 | Q5: ='จัดสรร งปม.'!P12 -> 0 | R5: ='จัดสรร งปม.'!Q12 -> 0 | S5: ='จัดสรร งปม.'!R12 -> 0
D6: ใช้ไปแล้ว | E6: =SUM(E11:E45) -> 0 | F6: =SUM(F11:F45) -> 0 | G6: =SUM(G11:G45) -> 0 | H6: =SUM(H11:H45) -> 0 | I6: =SUM(I11:I45) -> 0 | J6: =SUM(J11:J45) -> 0 | K6: =SUM(K11:K45) -> 0 | L6: =SUM(L11:L45) -> 0 | N6: =SUM(N11:N45) -> 0 | P6: =SUM(P11:P45) -> 0 | Q6: =SUM(Q11:Q45) -> 0 | R6: =SUM(R11:R45) -> 0 | S6: =SUM(S11:S45) -> 0
B7: งบบุคลากร | D7: เหลือ | E7: =E5-E6 -> 0 | F7: =F5-F6 -> 0 | G7: =G5-G6 -> 0 | H7: =H5-H6 -> 0 | I7: =I5-I6 -> 0 | J7: =J5-J6 -> 0 | K7: =K5-K6 -> 0 | L7: =L5-L6 -> 0 | N7: =N5-N6 -> 0 | P7: =P5-P6 -> 0 | Q7: =Q5-Q6 -> 0 | R7: =R5-R6 -> 0 | S7: =S5-S6 -> 0
B8: รหัสรายการจ่าย | C8: ='จัดสรร งปม.'!$B$12 -> 103
B9: รายการจ่าย | C9: ='จัดสรร งปม.'!$C$12 -> สำรอง 2
A10: รหัส | B10: วันที่ | C10: ชื่อผู้ขอใช้ | D10: แผนก/งาน | E10: ปวช. | F10: ปวส. | G10: ระยะสั้น | H10: อุดหนุน | I10: หนังสือ | J10: เครื่องแบบ | K10: กิจกรรม | L10: อุปกรณ์ | M10: เครื่องมือ | N10: ทั่วไป | O10: =+O4 -> โครงการ | P10: =+P4 -> เงินนอกงบ | Q10: เงินรายได้ | R10: เงินรับฝาก | S10: รวม
A11: 001 | S11: =SUM(E11:R11) -> 0
A12: 002 | S12: =SUM(E12:R12) -> 0
A13: 003 | S13: =SUM(E13:R13) -> 0
A14: 004 | S14: =SUM(E14:R14) -> 0
A15: 005 | S15: =SUM(E15:R15) -> 0
A16: 006 | S16: =SUM(E16:R16) -> 0
A17: 007 | S17: =SUM(E17:R17) -> 0
A18: 008 | S18: =SUM(E18:R18) -> 0
A19: 009 | S19: =SUM(E19:R19) -> 0
A20: 010 | S20: =SUM(E20:R20) -> 0
A21: 011 | S21: =SUM(E21:R21) -> 0
A22: 012 | S22: =SUM(E22:R22) -> 0
... A45: 035 | S45: =SUM(E45:R45) -> 0

Sheet 104
A1: กลับไปที่หน้าจัดสรร งปม.
E2: =Note!$B$1 -> วิทยาลัยการอาชีพนวมินทราชินีแม่ฮ่องสอน
E3: เงินงบประมาณ | H3: เงินอุดหนุน | O3: งบรายจ่ายอื่น | Q3: เงิน บกศ. | S3: รวม
E4: ปวช. | F4: ปวส. | G4: ระยะสั้น | H4: จัดการเรียน | I4: หนังสือ | J4: เครื่องแบบ | K4: กิจกรรม | L4: อุปกรณ์ | M4: เครื่องมือ | N4: ทั่วไป | O4: โครงการ | P4: เงินนอกงบ | Q4: เงินรายได้ | R4: เงินรับฝาก
D5: ได้รับมา | E5: ='จัดสรร งปม.'!D13 -> 0 | F5: ='จัดสรร งปม.'!E13 -> 0 | G5: ='จัดสรร งปม.'!F13 -> 0 | H5: ='จัดสรร งปม.'!G13 -> 0 | I5: ='จัดสรร งปม.'!H13 -> 0 | J5: ='จัดสรร งปม.'!I13 -> 0 | K5: ='จัดสรร งปม.'!J13 -> 0 | L5: ='จัดสรร งปม.'!K13 -> 0 | N5: ='จัดสรร งปม.'!L13 -> 0 | P5: ='จัดสรร งปม.'!N13 -> 0 | Q5: ='จัดสรร งปม.'!P13 -> 0 | R5: ='จัดสรร งปม.'!Q13 -> 0 | S5: ='จัดสรร งปม.'!R13 -> 0
D6: ใช้ไปแล้ว | E6: =SUM(E11:E45) -> 0 | F6: =SUM(F11:F45) -> 0 | G6: =SUM(G11:G45) -> 0 | H6: =SUM(H11:H45) -> 0 | I6: =SUM(I11:I45) -> 0 | J6: =SUM(J11:J45) -> 0 | K6: =SUM(K11:K45) -> 0 | L6: =SUM(L11:L45) -> 0 | N6: =SUM(N11:N45) -> 0 | P6: =SUM(P11:P45) -> 0 | Q6: =SUM(Q11:Q45) -> 0 | R6: =SUM(R11:R45) -> 0 | S6: =SUM(S11:S45) -> 0
B7: งบบุคลากร | D7: เหลือ | E7: =E5-E6 -> 0 | F7: =F5-F6 -> 0 | G7: =G5-G6 -> 0 | H7: =H5-H6 -> 0 | I7: =I5-I6 -> 0 | J7: =J5-J6 -> 0 | K7: =K5-K6 -> 0 | L7: =L5-L6 -> 0 | N7: =N5-N6 -> 0 | P7: =P5-P6 -> 0 | Q7: =Q5-Q6 -> 0 | R7: =R5-R6 -> 0 | S7: =S5-S6 -> 0
B8: รหัสรายการจ่าย | C8: ='จัดสรร งปม.'!$B$13 -> 104
B9: รายการจ่าย | C9: ='จัดสรร งปม.'!$C$13 -> สำรอง 3
A10: รหัส | B10: วันที่ | C10: ชื่อผู้ขอใช้ | D10: แผนก/งาน | E10: ปวช. | F10: ปวส. | G10: ระยะสั้น | H10: อุดหนุน | I10: หนังสือ | J10: เครื่องแบบ | K10: กิจกรรม | L10: อุปกรณ์ | M10: เครื่องมือ | N10: ทั่วไป | O10: =+O4 -> โครงการ | P10: =+P4 -> เงินนอกงบ | Q10: เงินรายได้ | R10: เงินรับฝาก | S10: รวม
A11: 001 | S11: =SUM(E11:R11) -> 0
A12: 002 | S12: =SUM(E12:R12) -> 0
A13: 003 | S13: =SUM(E13:R13) -> 0
A14: 004 | S14: =SUM(E14:R14) -> 0
A15: 005 | S15: =SUM(E15:R15) -> 0
A16: 006 | S16: =SUM(E16:R16) -> 0
A17: 007 | S17: =SUM(E17:R17) -> 0
A18: 008 | S18: =SUM(E18:R18) -> 0
A19: 009 | S19: =SUM(E19:R19) -> 0
A20: 010 | S20: =SUM(E20:R20) -> 0
A21: 011 | S21: =SUM(E21:R21) -> 0
A22: 012 | S22: =SUM(E22:R22) -> 0
... A45: 035 | S45: =SUM(E45:R45) -> 0

Sheet 105
A1: กลับไปที่หน้าจัดสรร งปม.
E2: =Note!$B$1 -> วิทยาลัยการอาชีพนวมินทราชินีแม่ฮ่องสอน
E3: เงินงบประมาณ | H3: เงินอุดหนุน | O3: งบรายจ่ายอื่น | Q3: เงิน บกศ. | S3: รวม
E4: ปวช. | F4: ปวส. | G4: ระยะสั้น | H4: จัดการเรียน | I4: หนังสือ | J4: เครื่องแบบ | K4: กิจกรรม | L4: อุปกรณ์ | M4: เครื่องมือ | N4: ทั่วไป | O4: โครงการ | P4: เงินนอกงบ | Q4: เงินรายได้ | R4: เงินรับฝาก
D5: ได้รับมา | E5: ='จัดสรร งปม.'!D14 -> 0 | F5: ='จัดสรร งปม.'!E14 -> 0 | G5: ='จัดสรร งปม.'!F14 -> 0 | H5: ='จัดสรร งปม.'!G14 -> 0 | I5: ='จัดสรร งปม.'!H14 -> 0 | J5: ='จัดสรร งปม.'!I14 -> 0 | K5: ='จัดสรร งปม.'!J14 -> 0 | L5: ='จัดสรร งปม.'!K14 -> 0 | N5: ='จัดสรร งปม.'!L14 -> 0 | P5: ='จัดสรร งปม.'!N14 -> 0 | Q5: ='จัดสรร งปม.'!P14 -> 0 | R5: ='จัดสรร งปม.'!Q14 -> 0 | S5: ='จัดสรร งปม.'!R14 -> 0
D6: ใช้ไปแล้ว | E6: =SUM(E11:E45) -> 0 | F6: =SUM(F11:F45) -> 0 | G6: =SUM(G11:G45) -> 0 | H6: =SUM(H11:H45) -> 0 | I6: =SUM(I11:I45) -> 0 | J6: =SUM(J11:J45) -> 0 | K6: =SUM(K11:K45) -> 0 | L6: =SUM(L11:L45) -> 0 | N6: =SUM(N11:N45) -> 0 | P6: =SUM(P11:P45) -> 0 | Q6: =SUM(Q11:Q45) -> 0 | R6: =SUM(R11:R45) -> 0 | S6: =SUM(S11:S45) -> 0
B7: งบบุคลากร | D7: เหลือ | E7: =E5-E6 -> 0 | F7: =F5-F6 -> 0 | G7: =G5-G6 -> 0 | H7: =H5-H6 -> 0 | I7: =I5-I6 -> 0 | J7: =J5-J6 -> 0 | K7: =K5-K6 -> 0 | L7: =L5-L6 -> 0 | N7: =N5-N6 -> 0 | P7: =P5-P6 -> 0 | Q7: =Q5-Q6 -> 0 | R7: =R5-R6 -> 0 | S7: =S5-S6 -> 0
B8: รหัสรายการจ่าย | C8: ='จัดสรร งปม.'!$B$14 -> 105
B9: รายการจ่าย | C9: ='จัดสรร งปม.'!$C$14 -> สำรอง 4
A10: รหัส | B10: วันที่ | C10: ชื่อผู้ขอใช้ | D10: แผนก/งาน | E10: ปวช. | F10: ปวส. | G10: ระยะสั้น | H10: อุดหนุน | I10: หนังสือ | J10: เครื่องแบบ | K10: กิจกรรม | L10: อุปกรณ์ | M10: เครื่องมือ | N10: ทั่วไป | O10: =+O4 -> โครงการ | P10: =+P4 -> เงินนอกงบ | Q10: เงินรายได้ | R10: เงินรับฝาก | S10: รวม
A11: 001 | S11: =SUM(E11:R11) -> 0
A12: 002 | S12: =SUM(E12:R12) -> 0
A13: 003 | S13: =SUM(E13:R13) -> 0
A14: 004 | S14: =SUM(E14:R14) -> 0
A15: 005 | S15: =SUM(E15:R15) -> 0
A16: 006 | S16: =SUM(E16:R16) -> 0
A17: 007 | S17: =SUM(E17:R17) -> 0
A18: 008 | S18: =SUM(E18:R18) -> 0
A19: 009 | S19: =SUM(E19:R19) -> 0
A20: 010 | S20: =SUM(E20:R20) -> 0
A21: 011 | S21: =SUM(E21:R21) -> 0
A22: 012 | S22: =SUM(E22:R22) -> 0
... A45: 035 | S45: =SUM(E45:R45) -> 0

Sheet 201
A1: กลับไปที่หน้าจัดสรร งปม.
E2: =Note!$B$1 -> วิทยาลัยการอาชีพนวมินทราชินีแม่ฮ่องสอน
E3: เงินงบประมาณ | H3: เงินอุดหนุน | O3: งบรายจ่ายอื่น | Q3: เงิน บกศ. | S3: รวม
E4: ปวช. | F4: ปวส. | G4: ระยะสั้น | H4: จัดการเรียน | I4: หนังสือ | J4: เครื่องแบบ | K4: กิจกรรม | L4: อุปกรณ์ | M4: เครื่องมือ | N4: ทั่วไป | O4: โครงการ | P4: เงินนอกงบ | Q4: เงินรายได้ | R4: เงินรับฝาก
D5: ได้รับมา | E5: ='จัดสรร งปม.'!D16 -> 0 | F5: ='จัดสรร งปม.'!E16 -> 0 | G5: ='จัดสรร งปม.'!F16 -> 0 | H5: ='จัดสรร งปม.'!G16 -> 0 | I5: ='จัดสรร งปม.'!H16 -> 0 | J5: ='จัดสรร งปม.'!I16 -> 0 | K5: ='จัดสรร งปม.'!J16 -> 0 | L5: ='จัดสรร งปม.'!K16 -> 0 | N5: ='จัดสรร งปม.'!L16 -> 0 | P5: ='จัดสรร งปม.'!N16 -> 0 | Q5: ='จัดสรร งปม.'!P16 -> 0 | R5: ='จัดสรร งปม.'!Q16 -> 0 | S5: ='จัดสรร งปม.'!R16 -> 0
D6: ใช้ไปแล้ว | E6: =SUM(E11:E45) -> 0 | F6: =SUM(F11:F45) -> 0 | G6: =SUM(G11:G45) -> 0 | H6: =SUM(H11:H45) -> 0 | I6: =SUM(I11:I45) -> 0 | J6: =SUM(J11:J45) -> 0 | K6: =SUM(K11:K45) -> 0 | L6: =SUM(L11:L45) -> 0 | N6: =SUM(N11:N45) -> 0 | P6: =SUM(P11:P45) -> 0 | Q6: =SUM(Q11:Q45) -> 0 | R6: =SUM(R11:R45) -> 0 | S6: =SUM(S11:S45) -> 0
B7: งบดำเนินงาน (ค่าตอบแทน) | D7: เหลือ | E7: =E5-E6 -> 0 | F7: =F5-F6 -> 0 | G7: =G5-G6 -> 0 | H7: =H5-H6 -> 0 | I7: =I5-I6 -> 0 | J7: =J5-J6 -> 0 | K7: =K5-K6 -> 0 | L7: =L5-L6 -> 0 | N7: =N5-N6 -> 0 | P7: =P5-P6 -> 0 | Q7: =Q5-Q6 -> 0 | R7: =R5-R6 -> 0 | S7: =S5-S6 -> 0
B8: รหัสรายการจ่าย | C8: ='จัดสรร งปม.'!$B$16 -> 201
B9: รายการจ่าย | C9: ='จัดสรร งปม.'!$C$16 -> ค่าตอบแทนพิเศษพนักงานราชการ
A10: รหัส | B10: วันที่ | C10: ชื่อผู้ขอใช้ | D10: แผนก/งาน | E10: ปวช. | F10: ปวส. | G10: ระยะสั้น | H10: อุดหนุน | I10: หนังสือ | J10: เครื่องแบบ | K10: กิจกรรม | L10: อุปกรณ์ | M10: เครื่องมือ | N10: ทั่วไป | O10: =+O4 -> โครงการ | P10: =+P4 -> เงินนอกงบ | Q10: เงินรายได้ | R10: เงินรับฝาก | S10: รวม
A11: 001 | S11: =SUM(E11:R11) -> 0
A12: 002 | S12: =SUM(E12:R12) -> 0
A13: 003 | S13: =SUM(E13:R13) -> 0
A14: 004 | S14: =SUM(E14:R14) -> 0
A15: 005 | S15: =SUM(E15:R15) -> 0
A16: 006 | S16: =SUM(E16:R16) -> 0
A17: 007 | S17: =SUM(E17:R17) -> 0
A18: 008 | S18: =SUM(E18:R18) -> 0
A19: 009 | S19: =SUM(E19:R19) -> 0
A20: 010 | S20: =SUM(E20:R20) -> 0
A21: 011 | S21: =SUM(E21:R21) -> 0
A22: 012 | S22: =SUM(E22:R22) -> 0
... A45: 035 | S45: =SUM(E45:R45) -> 0

Sheet 202
A1: กลับไปที่หน้าจัดสรร งปม.
E2: =Note!$B$1 -> วิทยาลัยการอาชีพนวมินทราชินีแม่ฮ่องสอน
E3: เงินงบประมาณ | H3: เงินอุดหนุน | O3: งบรายจ่ายอื่น | Q3: เงิน บกศ. | S3: รวม
E4: ปวช. | F4: ปวส. | G4: ระยะสั้น | H4: จัดการเรียน | I4: หนังสือ | J4: เครื่องแบบ | K4: กิจกรรม | L4: อุปกรณ์ | M4: เครื่องมือ | N4: ทั่วไป | O4: โครงการ | P4: เงินนอกงบ | Q4: เงินรายได้ | R4: เงินรับฝาก
D5: ได้รับมา | E5: ='จัดสรร งปม.'!D17 -> 0 | F5: ='จัดสรร งปม.'!E17 -> 0 | G5: ='จัดสรร งปม.'!F17 -> 0 | H5: ='จัดสรร งปม.'!G17 -> 169920 | I5: ='จัดสรร งปม.'!H17 -> 0 | J5: ='จัดสรร งปม.'!I17 -> 0 | K5: ='จัดสรร งปม.'!J17 -> 0 | L5: ='จัดสรร งปม.'!K17 -> 0 | N5: ='จัดสรร งปม.'!L17 -> 0 | P5: ='จัดสรร งปม.'!N17 -> 0 | Q5: ='จัดสรร งปม.'!P17 -> 0 | R5: ='จัดสรร งปม.'!Q17 -> 0 | S5: ='จัดสรร งปม.'!R17 -> 169920
D6: ใช้ไปแล้ว | E6: =SUM(E11:E45) -> 0 | F6: =SUM(F11:F45) -> 0 | G6: =SUM(G11:G45) -> 0 | H6: =SUM(H11:H45) -> 169920 | I6: =SUM(I11:I45) -> 0 | J6: =SUM(J11:J45) -> 0 | K6: =SUM(K11:K45) -> 0 | L6: =SUM(L11:L45) -> 0 | N6: =SUM(N11:N45) -> 0 | P6: =SUM(P11:P45) -> 0 | Q6: =SUM(Q11:Q45) -> 0 | R6: =SUM(R11:R45) -> 0 | S6: =SUM(S11:S45) -> 169920
B7: งบดำเนินงาน (ค่าตอบแทน) | D7: เหลือ | E7: =E5-E6 -> 0 | F7: =F5-F6 -> 0 | G7: =G5-G6 -> 0 | H7: =H5-H6 -> 0 | I7: =I5-I6 -> 0 | J7: =J5-J6 -> 0 | K7: =K5-K6 -> 0 | L7: =L5-L6 -> 0 | N7: =N5-N6 -> 0 | P7: =P5-P6 -> 0 | Q7: =Q5-Q6 -> 0 | R7: =R5-R6 -> 0 | S7: =S5-S6 -> 0
B8: รหัสรายการจ่าย | C8: ='จัดสรร งปม.'!$B$17 -> 202
B9: รายการจ่าย | C9: ='จัดสรร งปม.'!$C$17 -> ค่าสอนเกินภาระงาน
A10: รหัส | B10: วันที่ | C10: ชื่อผู้ขอใช้ | D10: แผนก/งาน | E10: ปวช. | F10: ปวส. | G10: ระยะสั้น | H10: อุดหนุน | I10: หนังสือ | J10: เครื่องแบบ | K10: กิจกรรม | L10: อุปกรณ์ | M10: เครื่องมือ | N10: ทั่วไป | O10: =+O4 -> โครงการ | P10: =+P4 -> เงินนอกงบ | Q10: เงินรายได้ | R10: เงินรับฝาก | S10: รวม
A11: 001 | B11: 21 ธ.ค.64 | C11: นางกานดา เอี่ยมกระสินธ์ | D11: สามัญ | H11: 169920 | S11: =SUM(E11:R11) -> 169920
A12: 002 | S12: =SUM(E12:R12) -> 0
A13: 003 | S13: =SUM(E13:R13) -> 0
A14: 004 | S14: =SUM(E14:R14) -> 0
A15: 005 | S15: =SUM(E15:R15) -> 0
A16: 006 | S16: =SUM(E16:R16) -> 0
A17: 007 | S17: =SUM(E17:R17) -> 0
A18: 008 | S18: =SUM(E18:R18) -> 0
A19: 009 | S19: =SUM(E19:R19) -> 0
A20: 010 | S20: =SUM(E20:R20) -> 0
A21: 011 | S21: =SUM(E21:R21) -> 0
A22: 012 | S22: =SUM(E22:R22) -> 0
A23: 013 | S23: =SUM(E23:R23) -> 0
... A45: 035 | S45: =SUM(E45:R45) -> 0

Sheet 203
A1: กลับไปที่หน้าจัดสรร งปม.
E2: =Note!$B$1 -> วิทยาลัยการอาชีพนวมินทราชินีแม่ฮ่องสอน
E3: เงินงบประมาณ | H3: เงินอุดหนุน | O3: งบรายจ่ายอื่น | Q3: เงิน บกศ. | S3: รวม
E4: ปวช. | F4: ปวส. | G4: ระยะสั้น | H4: จัดการเรียน | I4: หนังสือ | J4: เครื่องแบบ | K4: กิจกรรม | L4: อุปกรณ์ | M4: เครื่องมือ | N4: ทั่วไป | O4: โครงการ | P4: เงินนอกงบ | Q4: เงินรายได้ | R4: เงินรับฝาก
D5: ได้รับมา | E5: ='จัดสรร งปม.'!D18 -> 0 | F5: ='จัดสรร งปม.'!E18 -> 0 | G5: ='จัดสรร งปม.'!F18 -> 0 | H5: ='จัดสรร งปม.'!G18 -> 0 | I5: ='จัดสรร งปม.'!H18 -> 0 | J5: ='จัดสรร งปม.'!I18 -> 0 | K5: ='จัดสรร งปม.'!J18 -> 0 | L5: ='จัดสรร งปม.'!K18 -> 0 | N5: ='จัดสรร งปม.'!L18 -> 0 | P5: ='จัดสรร งปม.'!N18 -> 0 | Q5: ='จัดสรร งปม.'!P18 -> 0 | R5: ='จัดสรร งปม.'!Q18 -> 0 | S5: ='จัดสรร งปม.'!R18 -> 0
D6: ใช้ไปแล้ว | E6: =SUM(E11:E45) -> 0 | F6: =SUM(F11:F45) -> 0 | G6: =SUM(G11:G45) -> 0 | H6: =SUM(H11:H45) -> 0 | I6: =SUM(I11:I45) -> 0 | J6: =SUM(J11:J45) -> 0 | K6: =SUM(K11:K45) -> 0 | L6: =SUM(L11:L45) -> 0 | N6: =SUM(N11:N45) -> 0 | P6: =SUM(P11:P45) -> 0 | Q6: =SUM(Q11:Q45) -> 0 | R6: =SUM(R11:R45) -> 0 | S6: =SUM(S11:S45) -> 0
B7: งบดำเนินงาน (ค่าตอบแทน) | D7: เหลือ | E7: =E5-E6 -> 0 | F7: =F5-F6 -> 0 | G7: =G5-G6 -> 0 | H7: =H5-H6 -> 0 | I7: =I5-I6 -> 0 | J7: =J5-J6 -> 0 | K7: =K5-K6 -> 0 | L7: =L5-L6 -> 0 | N7: =N5-N6 -> 0 | P7: =P5-P6 -> 0 | Q7: =Q5-Q6 -> 0 | R7: =R5-R6 -> 0 | S7: =S5-S6 -> 0
B8: รหัสรายการจ่าย | C8: ='จัดสรร งปม.'!$B$18 -> 203
B9: รายการจ่าย | C9: ='จัดสรร งปม.'!$C$18 -> ค่าธุรการนอกเวลา
A10: รหัส | B10: วันที่ | C10: ชื่อผู้ขอใช้ | D10: แผนก/งาน | E10: ปวช. | F10: ปวส. | G10: ระยะสั้น | H10: อุดหนุน | I10: หนังสือ | J10: เครื่องแบบ | K10: กิจกรรม | L10: อุปกรณ์ | M10: เครื่องมือ | N10: ทั่วไป | O10: =+O4 -> โครงการ | P10: =+P4 -> เงินนอกงบ | Q10: เงินรายได้ | R10: เงินรับฝาก | S10: รวม
A11: 001 | S11: =SUM(E11:R11) -> 0
A12: 002 | S12: =SUM(E12:R12) -> 0
A13: 003 | S13: =SUM(E13:R13) -> 0
A14: 004 | S14: =SUM(E14:R14) -> 0
A15: 005 | S15: =SUM(E15:R15) -> 0
A16: 006 | S16: =SUM(E16:R16) -> 0
A17: 007 | S17: =SUM(E17:R17) -> 0
A18: 008 | S18: =SUM(E18:R18) -> 0
A19: 009 | S19: =SUM(E19:R19) -> 0
A20: 010 | S20: =SUM(E20:R20) -> 0
A21: 011 | S21: =SUM(E21:R21) -> 0
A22: 012 | S22: =SUM(E22:R22) -> 0
... A45: 035 | S45: =SUM(E45:R45) -> 0

Sheet 204
A1: กลับไปที่หน้าจัดสรร งปม.
E2: =Note!$B$1 -> วิทยาลัยการอาชีพนวมินทราชินีแม่ฮ่องสอน
E3: เงินงบประมาณ | H3: เงินอุดหนุน | O3: งบรายจ่ายอื่น | Q3: เงิน บกศ. | S3: รวม
E4: ปวช. | F4: ปวส. | G4: ระยะสั้น | H4: จัดการเรียน | I4: หนังสือ | J4: เครื่องแบบ | K4: กิจกรรม | L4: อุปกรณ์ | M4: เครื่องมือ | N4: ทั่วไป | O4: โครงการ | P4: เงินนอกงบ | Q4: เงินรายได้ | R4: เงินรับฝาก
D5: ได้รับมา | E5: ='จัดสรร งปม.'!D19 -> 0 | F5: ='จัดสรร งปม.'!E19 -> 0 | G5: ='จัดสรร งปม.'!F19 -> 0 | H5: ='จัดสรร งปม.'!G19 -> 0 | I5: ='จัดสรร งปม.'!H19 -> 0 | J5: ='จัดสรร งปม.'!I19 -> 0 | K5: ='จัดสรร งปม.'!J19 -> 0 | L5: ='จัดสรร งปม.'!K19 -> 0 | N5: ='จัดสรร งปม.'!L19 -> 0 | P5: ='จัดสรร งปม.'!N19 -> 0 | Q5: ='จัดสรร งปม.'!P19 -> 0 | R5: ='จัดสรร งปม.'!Q19 -> 0 | S5: ='จัดสรร งปม.'!R19 -> 0
D6: ใช้ไปแล้ว | E6: =SUM(E11:E45) -> 0 | F6: =SUM(F11:F45) -> 0 | G6: =SUM(G11:G45) -> 0 | H6: =SUM(H11:H45) -> 0 | I6: =SUM(I11:I45) -> 0 | J6: =SUM(J11:J45) -> 0 | K6: =SUM(K11:K45) -> 0 | L6: =SUM(L11:L45) -> 0 | N6: =SUM(N11:N45) -> 0 | P6: =SUM(P11:P45) -> 0 | Q6: =SUM(Q11:Q45) -> 0 | R6: =SUM(R11:R45) -> 0 | S6: =SUM(S11:S45) -> 0
B7: งบดำเนินงาน (ค่าตอบแทน) | D7: เหลือ | E7: =E5-E6 -> 0 | F7: =F5-F6 -> 0 | G7: =G5-G6 -> 0 | H7: =H5-H6 -> 0 | I7: =I5-I6 -> 0 | J7: =J5-J6 -> 0 | K7: =K5-K6 -> 0 | L7: =L5-L6 -> 0 | N7: =N5-N6 -> 0 | P7: =P5-P6 -> 0 | Q7: =Q5-Q6 -> 0 | R7: =R5-R6 -> 0 | S7: =S5-S6 -> 0
B8: รหัสรายการจ่าย | C8: ='จัดสรร งปม.'!$B$19 -> 204
B9: รายการจ่าย | C9: ='จัดสรร งปม.'!$C$19 -> ค่าสอนภาคฤดูร้อน
A10: รหัส | B10: วันที่ | C10: ชื่อผู้ขอใช้ | D10: แผนก/งาน | E10: ปวช. | F10: ปวส. | G10: ระยะสั้น | H10: อุดหนุน | I10: หนังสือ | J10: เครื่องแบบ | K10: กิจกรรม | L10: อุปกรณ์ | M10: เครื่องมือ | N10: ทั่วไป | O10: =+O4 -> โครงการ | P10: =+P4 -> เงินนอกงบ | Q10: เงินรายได้ | R10: เงินรับฝาก | S10: รวม
A11: 001 | S11: =SUM(E11:R11) -> 0
A12: 002 | S12: =SUM(E12:R12) -> 0
A13: 003 | S13: =SUM(E13:R13) -> 0
A14: 004 | S14: =SUM(E14:R14) -> 0
A15: 005 | S15: =SUM(E15:R15) -> 0
A16: 006 | S16: =SUM(E16:R16) -> 0
A17: 007 | S17: =SUM(E17:R17) -> 0
A18: 008 | S18: =SUM(E18:R18) -> 0
A19: 009 | S19: =SUM(E19:R19) -> 0
A20: 010 | S20: =SUM(E20:R20) -> 0
A21: 011 | S21: =SUM(E21:R21) -> 0
A22: 012 | S22: =SUM(E22:R22) -> 0
... A45: 035 | S45: =SUM(E45:R45) -> 0

Sheet 205
A1: กลับไปที่หน้าจัดสรร งปม.
E2: =Note!$B$1 -> วิทยาลัยการอาชีพนวมินทราชินีแม่ฮ่องสอน
E3: เงินงบประมาณ | H3: เงินอุดหนุน | O3: งบรายจ่ายอื่น | Q3: เงิน บกศ. | S3: รวม
E4: ปวช. | F4: ปวส. | G4: ระยะสั้น | H4: จัดการเรียน | I4: หนังสือ | J4: เครื่องแบบ | K4: กิจกรรม | L4: อุปกรณ์ | M4: เครื่องมือ | N4: ทั่วไป | O4: โครงการ | P4: เงินนอกงบ | Q4: เงินรายได้ | R4: เงินรับฝาก
D5: ได้รับมา | E5: ='จัดสรร งปม.'!D20 -> 0 | F5: ='จัดสรร งปม.'!E20 -> 0 | G5: ='จัดสรร งปม.'!F20 -> 0 | H5: ='จัดสรร งปม.'!G20 -> 0 | I5: ='จัดสรร งปม.'!H20 -> 0 | J5: ='จัดสรร งปม.'!I20 -> 0 | K5: ='จัดสรร งปม.'!J20 -> 0 | L5: ='จัดสรร งปม.'!K20 -> 0 | N5: ='จัดสรร งปม.'!L20 -> 0 | P5: ='จัดสรร งปม.'!N20 -> 0 | Q5: ='จัดสรร งปม.'!P20 -> 0 | R5: ='จัดสรร งปม.'!Q20 -> 0 | S5: ='จัดสรร งปม.'!R20 -> 0
D6: ใช้ไปแล้ว | E6: =SUM(E11:E45) -> 0 | F6: =SUM(F11:F45) -> 0 | G6: =SUM(G11:G45) -> 0 | H6: =SUM(H11:H45) -> 0 | I6: =SUM(I11:I45) -> 0 | J6: =SUM(J11:J45) -> 0 | K6: =SUM(K11:K45) -> 0 | L6: =SUM(L11:L45) -> 0 | N6: =SUM(N11:N45) -> 0 | P6: =SUM(P11:P45) -> 0 | Q6: =SUM(Q11:Q45) -> 0 | R6: =SUM(R11:R45) -> 0 | S6: =SUM(S11:S45) -> 0
B7: งบดำเนินงาน (ค่าตอบแทน) | D7: เหลือ | E7: =E5-E6 -> 0 | F7: =F5-F6 -> 0 | G7: =G5-G6 -> 0 | H7: =H5-H6 -> 0 | I7: =I5-I6 -> 0 | J7: =J5-J6 -> 0 | K7: =K5-K6 -> 0 | L7: =L5-L6 -> 0 | N7: =N5-N6 -> 0 | P7: =P5-P6 -> 0 | Q7: =Q5-Q6 -> 0 | R7: =R5-R6 -> 0 | S7: =S5-S6 -> 0
B8: รหัสรายการจ่าย | C8: ='จัดสรร งปม.'!$B$20 -> 205
B9: รายการจ่าย | C9: ='จัดสรร งปม.'!$C$20 -> ค่าสอนเทียบโอน
A10: รหัส | B10: วันที่ | C10: ชื่อผู้ขอใช้ | D10: แผนก/งาน | E10: ปวช. | F10: ปวส. | G10: ระยะสั้น | H10: อุดหนุน | I10: หนังสือ | J10: เครื่องแบบ | K10: กิจกรรม | L10: อุปกรณ์ | M10: เครื่องมือ | N10: ทั่วไป | O10: =+O4 -> โครงการ | P10: =+P4 -> เงินนอกงบ | Q10: เงินรายได้ | R10: เงินรับฝาก | S10: รวม
A11: 001 | S11: =SUM(E11:R11) -> 0
A12: 002 | S12: =SUM(E12:R12) -> 0
A13: 003 | S13: =SUM(E13:R13) -> 0
A14: 004 | S14: =SUM(E14:R14) -> 0
A15: 005 | S15: =SUM(E15:R15) -> 0
A16: 006 | S16: =SUM(E16:R16) -> 0
A17: 007 | S17: =SUM(E17:R17) -> 0
A18: 008 | S18: =SUM(E18:R18) -> 0
A19: 009 | S19: =SUM(E19:R19) -> 0
A20: 010 | S20: =SUM(E20:R20) -> 0
A21: 011 | S21: =SUM(E21:R21) -> 0
A22: 012 | S22: =SUM(E22:R22) -> 0
... A45: 035 | S45: =SUM(E45:R45) -> 0

Sheet 206
A1: กลับไปที่หน้าจัดสรร งปม.
E2: =Note!$B$1 -> วิทยาลัยการอาชีพนวมินทราชินีแม่ฮ่องสอน
E3: เงินงบประมาณ | H3: เงินอุดหนุน | O3: งบรายจ่ายอื่น | Q3: เงิน บกศ. | S3: รวม
E4: ปวช. | F4: ปวส. | G4: ระยะสั้น | H4: จัดการเรียน | I4: หนังสือ | J4: เครื่องแบบ | K4: กิจกรรม | L4: อุปกรณ์ | M4: เครื่องมือ | N4: ทั่วไป | O4: โครงการ | P4: เงินนอกงบ | Q4: เงินรายได้ | R4: เงินรับฝาก
D5: ได้รับมา | E5: ='จัดสรร งปม.'!D21 -> 0 | F5: ='จัดสรร งปม.'!E21 -> 0 | G5: ='จัดสรร งปม.'!F21 -> 0 | H5: ='จัดสรร งปม.'!G21 -> 1019820 | I5: ='จัดสรร งปม.'!H21 -> 0 | J5: ='จัดสรร งปม.'!I21 -> 0 | K5: ='จัดสรร งปม.'!J21 -> 0 | L5: ='จัดสรร งปม.'!K21 -> 0 | N5: ='จัดสรร งปม.'!L21 -> 0 | P5: ='จัดสรร งปม.'!N21 -> 0 | Q5: ='จัดสรร งปม.'!P21 -> 0 | R5: ='จัดสรร งปม.'!Q21 -> 0 | S5: ='จัดสรร งปม.'!R21 -> 1019820
D6: ใช้ไปแล้ว | E6: =SUM(E11:E45) -> 0 | F6: =SUM(F11:F45) -> 0 | G6: =SUM(G11:G45) -> 0 | H6: =SUM(H11:H45) -> 1019820 | I6: =SUM(I11:I45) -> 0 | J6: =SUM(J11:J45) -> 0 | K6: =SUM(K11:K45) -> 0 | L6: =SUM(L11:L45) -> 0 | N6: =SUM(N11:N45) -> 0 | P6: =SUM(P11:P45) -> 0 | Q6: =SUM(Q11:Q45) -> 0 | R6: =SUM(R11:R45) -> 0 | S6: =SUM(S11:S45) -> 1019820
B7: งบดำเนินงาน (ค่าตอบแทน) | D7: เหลือ | E7: =E5-E6 -> 0 | F7: =F5-F6 -> 0 | G7: =G5-G6 -> 0 | H7: =H5-H6 -> 0 | I7: =I5-I6 -> 0 | J7: =J5-J6 -> 0 | K7: =K5-K6 -> 0 | L7: =L5-L6 -> 0 | N7: =N5-N6 -> 0 | P7: =P5-P6 -> 0 | Q7: =Q5-Q6 -> 0 | R7: =R5-R6 -> 0 | S7: =S5-S6 -> 0
B8: รหัสรายการจ่าย | C8: ='จัดสรร งปม.'!$B$21 -> 206
B9: รายการจ่าย | C9: ='จัดสรร งปม.'!$C$21 -> ค่าจ้างครูรายเดือน
A10: รหัส | B10: วันที่ | C10: ชื่อผู้ขอใช้ | D10: แผนก/งาน | E10: ปวช. | F10: ปวส. | G10: ระยะสั้น | H10: อุดหนุน | I10: หนังสือ | J10: เครื่องแบบ | K10: กิจกรรม | L10: อุปกรณ์ | M10: เครื่องมือ | N10: ทั่วไป | O10: =+O4 -> โครงการ | P10: =+P4 -> เงินนอกงบ | Q10: เงินรายได้ | R10: เงินรับฝาก | S10: รวม
A11: 001 | B11: 8 ธ.ค.64 | C11: นางอำโนญ พัฒนกสิกร | D11: การเงิน | H11: 238200 | S11: =SUM(E11:R11) -> 238200
A12: 002 | B12: 8 ธ.ค.64 | C12: นางอำโนญ พัฒนกสิกร | D12: การเงิน | H12: 260540 | S12: =SUM(E12:R12) -> 260540
A13: 003 | B13: 9 ธ.ค.64 | C13: นางอำโนญ พัฒนกสิกร | D13: การเงิน | H13: 260540 | S13: =SUM(E13:R13) -> 260540
A14: 004 | B14: 18 ม.ค.65 | C14: นางอำโนญ พัฒนกสิกร | D14: การเงิน | H14: 260540 | S14: =SUM(E14:R14) -> 260540
A15: 005 | S15: =SUM(E15:R15) -> 0
A16: 006 | S16: =SUM(E16:R16) -> 0
A17: 007 | S17: =SUM(E17:R17) -> 0
A18: 008 | S18: =SUM(E18:R18) -> 0
A19: 009 | S19: =SUM(E19:R19) -> 0
A20: 010 | S20: =SUM(E20:R20) -> 0
A21: 011 | S21: =SUM(E21:R21) -> 0
A22: 012 | S22: =SUM(E22:R22) -> 0
A23: 013 | S23: =SUM(E23:R23) -> 0
A24: 014 | S24: =SUM(E24:R24) -> 0
A25: 015 | S25: =SUM(E25:R25) -> 0
A26: 016 | S26: =SUM(E26:R26) -> 0
... A45: 035 | S45: =SUM(E45:R45) -> 0

Sheet 207
A1: กลับไปที่หน้าจัดสรร งปม.
E2: =Note!$B$1 -> วิทยาลัยการอาชีพนวมินทราชินีแม่ฮ่องสอน
E3: เงินงบประมาณ | H3: เงินอุดหนุน | O3: งบรายจ่ายอื่น | Q3: เงิน บกศ. | S3: รวม
E4: ปวช. | F4: ปวส. | G4: ระยะสั้น | H4: จัดการเรียน | I4: หนังสือ | J4: เครื่องแบบ | K4: กิจกรรม | L4: อุปกรณ์ | M4: เครื่องมือ | N4: ทั่วไป | O4: โครงการ | P4: เงินนอกงบ | Q4: เงินรายได้ | R4: เงินรับฝาก
D5: ได้รับมา | E5: ='จัดสรร งปม.'!D22 -> 0 | F5: ='จัดสรร งปม.'!E22 -> 0 | G5: ='จัดสรร งปม.'!F22 -> 0 | H5: ='จัดสรร งปม.'!G22 -> 656837.45 | I5: ='จัดสรร งปม.'!H22 -> 0 | J5: ='จัดสรร งปม.'!I22 -> 0 | K5: ='จัดสรร งปม.'!J22 -> 0 | L5: ='จัดสรร งปม.'!K22 -> 0 | N5: ='จัดสรร งปม.'!L22 -> 0 | P5: ='จัดสรร งปม.'!N22 -> 0 | Q5: ='จัดสรร งปม.'!P22 -> 0 | R5: ='จัดสรร งปม.'!Q22 -> 0 | S5: ='จัดสรร งปม.'!R22 -> 656837.45
D6: ใช้ไปแล้ว | E6: =SUM(E11:E45) -> 0 | F6: =SUM(F11:F45) -> 0 | G6: =SUM(G11:G45) -> 0 | H6: =SUM(H11:H45) -> 656837.45 | I6: =SUM(I11:I45) -> 0 | J6: =SUM(J11:J45) -> 0 | K6: =SUM(K11:K45) -> 0 | L6: =SUM(L11:L45) -> 0 | N6: =SUM(N11:N45) -> 0 | P6: =SUM(P11:P45) -> 0 | Q6: =SUM(Q11:Q45) -> 0 | R6: =SUM(R11:R45) -> 0 | S6: =SUM(S11:S45) -> 656837.45
B7: งบดำเนินงาน (ค่าตอบแทน) | D7: เหลือ | E7: =E5-E6 -> 0 | F7: =F5-F6 -> 0 | G7: =G5-G6 -> 0 | H7: =H5-H6 -> 0 | I7: =I5-I6 -> 0 | J7: =J5-J6 -> 0 | K7: =K5-K6 -> 0 | L7: =L5-L6 -> 0 | N7: =N5-N6 -> 0 | P7: =P5-P6 -> 0 | Q7: =Q5-Q6 -> 0 | R7: =R5-R6 -> 0 | S7: =S5-S6 -> 0
B8: รหัสรายการจ่าย | C8: ='จัดสรร งปม.'!$B$22 -> 207
B9: รายการจ่าย | C9: ='จัดสรร งปม.'!$C$22 -> ค่าจ้างเจ้าหน้าที่รายเดือน
A10: รหัส | B10: วันที่ | C10: ชื่อผู้ขอใช้ | D10: แผนก/งาน | E10: ปวช. | F10: ปวส. | G10: ระยะสั้น | H10: =+H4 -> จัดการเรียน | I10: หนังสือ | J10: เครื่องแบบ | K10: กิจกรรม | L10: อุปกรณ์ | M10: เครื่องมือ | N10: ทั่วไป | O10: =+O4 -> โครงการ | P10: =+P4 -> เงินนอกงบ | Q10: เงินรายได้ | R10: เงินรับฝาก | S10: รวม
A11: 001 | B11: 8 ธ.ค. 64 | C11: นางอำโนญ พัฒนากสิกร | D11: การเงิน | H11: 171026.45 | S11: =SUM(E11:R11) -> 171026.45
A12: 002 | B12: 8 ธ.ค. 64 | C12: นางอำโนญ พัฒนากสิกร | D12: การเงิน | H12: 167120.67 | S12: =SUM(E12:R12) -> 167120.67
A13: 003 | B13: 9 ธ.ค. 64 | C13: นางอำโนญ พัฒนากสิกร | D13: การเงิน | H13: 169600.33 | S13: =SUM(E13:R13) -> 169600.33
A14: 004 | B14: 15 มี.ค. 65 | C14: นางอำโนญ พัฒนากสิกร | D14: การเงิน | H14: 149090 | S14: =SUM(E14:R14) -> 149090
A15: 005 | S15: =SUM(E15:R15) -> 0
A16: 006 | S16: =SUM(E16:R16) -> 0
A17: 007 | S17: =SUM(E17:R17) -> 0
A18: 008 | S18: =SUM(E18:R18) -> 0
A19: 009 | S19: =SUM(E19:R19) -> 0
A20: 010 | S20: =SUM(E20:R20) -> 0
A21: 011 | S21: =SUM(E21:R21) -> 0
A22: 012 | S22: =SUM(E22:R22) -> 0
A23: 013 | S23: =SUM(E23:R23) -> 0
A24: 014 | S24: =SUM(E24:R24) -> 0
A25: 015 | S25: =SUM(E25:R25) -> 0
A26: 016 | S26: =SUM(E26:R26) -> 0
... A45: 035 | S45: =SUM(E45:R45) -> 0

Sheet 208
A1: กลับไปที่หน้าจัดสรร งปม.
E2: =Note!$B$1 -> วิทยาลัยการอาชีพนวมินทราชินีแม่ฮ่องสอน
E3: เงินงบประมาณ | H3: เงินอุดหนุน | O3: งบรายจ่ายอื่น | Q3: เงิน บกศ. | S3: รวม
E4: ปวช. | F4: ปวส. | G4: ระยะสั้น | H4: จัดการเรียน | I4: หนังสือ | J4: เครื่องแบบ | K4: กิจกรรม | L4: อุปกรณ์ | M4: เครื่องมือ | N4: ทั่วไป | O4: โครงการ | P4: เงินนอกงบ | Q4: เงินรายได้ | R4: เงินรับฝาก
D5: ได้รับมา | E5: ='จัดสรร งปม.'!D23 -> 0 | F5: ='จัดสรร งปม.'!E23 -> 0 | G5: ='จัดสรร งปม.'!F23 -> 0 | H5: ='จัดสรร งปม.'!G23 -> 0 | I5: ='จัดสรร งปม.'!H23 -> 0 | J5: ='จัดสรร งปม.'!I23 -> 0 | K5: ='จัดสรร งปม.'!J23 -> 0 | L5: ='จัดสรร งปม.'!K23 -> 0 | N5: ='จัดสรร งปม.'!L23 -> 0 | P5: ='จัดสรร งปม.'!N23 -> 0 | Q5: ='จัดสรร งปม.'!P23 -> 0 | R5: ='จัดสรร งปม.'!Q23 -> 0 | S5: ='จัดสรร งปม.'!R23 -> 0
D6: ใช้ไปแล้ว | E6: =SUM(E11:E45) -> 0 | F6: =SUM(F11:F45) -> 0 | G6: =SUM(G11:G45) -> 0 | H6: =SUM(H11:H45) -> 0 | I6: =SUM(I11:I45) -> 0 | J6: =SUM(J11:J45) -> 0 | K6: =SUM(K11:K45) -> 0 | L6: =SUM(L11:L45) -> 0 | N6: =SUM(N11:N45) -> 0 | P6: =SUM(P11:P45) -> 0 | Q6: =SUM(Q11:Q45) -> 0 | R6: =SUM(R11:R45) -> 0 | S6: =SUM(S11:S45) -> 0
B7: งบดำเนินงาน (ค่าตอบแทน) | D7: เหลือ | E7: =E5-E6 -> 0 | F7: =F5-F6 -> 0 | G7: =G5-G6 -> 0 | H7: =H5-H6 -> 0 | I7: =I5-I6 -> 0 | J7: =J5-J6 -> 0 | K7: =K5-K6 -> 0 | L7: =L5-L6 -> 0 | N7: =N5-N6 -> 0 | P7: =P5-P6 -> 0 | Q7: =Q5-Q6 -> 0 | R7: =R5-R6 -> 0 | S7: =S5-S6 -> 0
B8: รหัสรายการจ่าย | C8: ='จัดสรร งปม.'!$B$23 -> 208
B9: รายการจ่าย | C9: ='จัดสรร งปม.'!$C$23 -> ค่าครองชีพครูรายเดือน
A10: รหัส | B10: วันที่ | C10: ชื่อผู้ขอใช้ | D10: แผนก/งาน | E10: ปวช. | F10: ปวส. | G10: ระยะสั้น | H10: อุดหนุน | I10: หนังสือ | J10: เครื่องแบบ | K10: กิจกรรม | L10: อุปกรณ์ | M10: เครื่องมือ | N10: ทั่วไป | O10: =+O4 -> โครงการ | P10: =+P4 -> เงินนอกงบ | Q10: เงินรายได้ | R10: เงินรับฝาก | S10: รวม
A11: 001 | S11: =SUM(E11:R11) -> 0
A12: 002 | S12: =SUM(E12:R12) -> 0
A13: 003 | S13: =SUM(E13:R13) -> 0
A14: 004 | S14: =SUM(E14:R14) -> 0
A15: 005 | S15: =SUM(E15:R15) -> 0
A16: 006 | S16: =SUM(E16:R16) -> 0
A17: 007 | S17: =SUM(E17:R17) -> 0
A18: 008 | S18: =SUM(E18:R18) -> 0
A19: 009 | S19: =SUM(E19:R19) -> 0
A20: 010 | S20: =SUM(E20:R20) -> 0
A21: 011 | S21: =SUM(E21:R21) -> 0
A22: 012 | S22: =SUM(E22:R22) -> 0
... A45: 035 | S45: =SUM(E45:R45) -> 0

Sheet 209
A1: กลับไปที่หน้าจัดสรร งปม.
E2: =Note!$B$1 -> วิทยาลัยการอาชีพนวมินทราชินีแม่ฮ่องสอน
E3: เงินงบประมาณ | H3: เงินอุดหนุน | O3: งบรายจ่ายอื่น | Q3: เงิน บกศ. | S3: รวม
E4: ปวช. | F4: ปวส. | G4: ระยะสั้น | H4: จัดการเรียน | I4: หนังสือ | J4: เครื่องแบบ | K4: กิจกรรม | L4: อุปกรณ์ | M4: เครื่องมือ | N4: ทั่วไป | O4: โครงการ | P4: เงินนอกงบ | Q4: เงินรายได้ | R4: เงินรับฝาก
D5: ได้รับมา | E5: ='จัดสรร งปม.'!D24 -> 0 | F5: ='จัดสรร งปม.'!E24 -> 0 | G5: ='จัดสรร งปม.'!F24 -> 0 | H5: ='จัดสรร งปม.'!G24 -> 0 | I5: ='จัดสรร งปม.'!H24 -> 0 | J5: ='จัดสรร งปม.'!I24 -> 0 | K5: ='จัดสรร งปม.'!J24 -> 0 | L5: ='จัดสรร งปม.'!K24 -> 0 | N5: ='จัดสรร งปม.'!L24 -> 0 | P5: ='จัดสรร งปม.'!N24 -> 0 | Q5: ='จัดสรร งปม.'!P24 -> 0 | R5: ='จัดสรร งปม.'!Q24 -> 0 | S5: ='จัดสรร งปม.'!R24 -> 0
D6: ใช้ไปแล้ว | E6: =SUM(E11:E45) -> 0 | F6: =SUM(F11:F45) -> 0 | G6: =SUM(G11:G45) -> 0 | H6: =SUM(H11:H45) -> 0 | I6: =SUM(I11:I45) -> 0 | J6: =SUM(J11:J45) -> 0 | K6: =SUM(K11:K45) -> 0 | L6: =SUM(L11:L45) -> 0 | N6: =SUM(N11:N45) -> 0 | P6: =SUM(P11:P45) -> 0 | Q6: =SUM(Q11:Q45) -> 0 | R6: =SUM(R11:R45) -> 0 | S6: =SUM(S11:S45) -> 0
B7: งบดำเนินงาน (ค่าตอบแทน) | D7: เหลือ | E7: =E5-E6 -> 0 | F7: =F5-F6 -> 0 | G7: =G5-G6 -> 0 | H7: =H5-H6 -> 0 | I7: =I5-I6 -> 0 | J7: =J5-J6 -> 0 | K7: =K5-K6 -> 0 | L7: =L5-L6 -> 0 | N7: =N5-N6 -> 0 | P7: =P5-P6 -> 0 | Q7: =Q5-Q6 -> 0 | R7: =R5-R6 -> 0 | S7: =S5-S6 -> 0
B8: รหัสรายการจ่าย | C8: ='จัดสรร งปม.'!$B$24 -> 209
B9: รายการจ่าย | C9: ='จัดสรร งปม.'!$C$24 -> ค่าครองชีพเจ้าหน้าที่รายเดือน
A10: รหัส | B10: วันที่ | C10: ชื่อผู้ขอใช้ | D10: แผนก/งาน | E10: ปวช. | F10: ปวส. | G10: ระยะสั้น | H10: อุดหนุน | I10: หนังสือ | J10: เครื่องแบบ | K10: กิจกรรม | L10: อุปกรณ์ | M10: เครื่องมือ | N10: ทั่วไป | O10: =+O4 -> โครงการ | P10: =+P4 -> เงินนอกงบ | Q10: เงินรายได้ | R10: เงินรับฝาก | S10: รวม
A11: 001 | S11: =SUM(E11:R11) -> 0
A12: 002 | S12: =SUM(E12:R12) -> 0
A13: 003 | S13: =SUM(E13:R13) -> 0
A14: 004 | S14: =SUM(E14:R14) -> 0
A15: 005 | S15: =SUM(E15:R15) -> 0
A16: 006 | S16: =SUM(E16:R16) -> 0
A17: 007 | S17: =SUM(E17:R17) -> 0
A18: 008 | S18: =SUM(E18:R18) -> 0
A19: 009 | S19: =SUM(E19:R19) -> 0
A20: 010 | S20: =SUM(E20:R20) -> 0
A21: 011 | S21: =SUM(E21:R21) -> 0
A22: 012 | S22: =SUM(E22:R22) -> 0
... A45: 035 | S45: =SUM(E45:R45) -> 0

Sheet 210
A1: กลับไปที่หน้าจัดสรร งปม.
E2: =Note!$B$1 -> วิทยาลัยการอาชีพนวมินทราชินีแม่ฮ่องสอน
E3: เงินงบประมาณ | H3: เงินอุดหนุน | O3: งบรายจ่ายอื่น | Q3: เงิน บกศ. | S3: รวม
E4: ปวช. | F4: ปวส. | G4: ระยะสั้น | H4: จัดการเรียน | I4: หนังสือ | J4: เครื่องแบบ | K4: กิจกรรม | L4: อุปกรณ์ | M4: เครื่องมือ | N4: ทั่วไป | O4: โครงการ | P4: เงินนอกงบ | Q4: เงินรายได้ | R4: เงินรับฝาก
D5: ได้รับมา | E5: ='จัดสรร งปม.'!D25 -> 0 | F5: ='จัดสรร งปม.'!E25 -> 0 | G5: ='จัดสรร งปม.'!F25 -> 0 | H5: ='จัดสรร งปม.'!G25 -> 0 | I5: ='จัดสรร งปม.'!H25 -> 0 | J5: ='จัดสรร งปม.'!I25 -> 0 | K5: ='จัดสรร งปม.'!J25 -> 0 | L5: ='จัดสรร งปม.'!K25 -> 0 | N5: ='จัดสรร งปม.'!L25 -> 0 | P5: ='จัดสรร งปม.'!N25 -> 0 | Q5: ='จัดสรร งปม.'!P25 -> 0 | R5: ='จัดสรร งปม.'!Q25 -> 0 | S5: ='จัดสรร งปม.'!R25 -> 0
D6: ใช้ไปแล้ว | E6: =SUM(E11:E45) -> 0 | F6: =SUM(F11:F45) -> 0 | G6: =SUM(G11:G45) -> 0 | H6: =SUM(H11:H45) -> 0 | I6: =SUM(I11:I45) -> 0 | J6: =SUM(J11:J45) -> 0 | K6: =SUM(K11:K45) -> 0 | L6: =SUM(L11:L45) -> 0 | N6: =SUM(N11:N45) -> 0 | P6: =SUM(P11:P45) -> 0 | Q6: =SUM(Q11:Q45) -> 0 | R6: =SUM(R11:R45) -> 0 | S6: =SUM(S11:S45) -> 0
B7: งบดำเนินงาน (ค่าตอบแทน) | D7: เหลือ | E7: =E5-E6 -> 0 | F7: =F5-F6 -> 0 | G7: =G5-G6 -> 0 | H7: =H5-H6 -> 0 | I7: =I5-I6 -> 0 | J7: =J5-J6 -> 0 | K7: =K5-K6 -> 0 | L7: =L5-L6 -> 0 | N7: =N5-N6 -> 0 | P7: =P5-P6 -> 0 | Q7: =Q5-Q6 -> 0 | R7: =R5-R6 -> 0 | S7: =S5-S6 -> 0
B8: รหัสรายการจ่าย | C8: ='จัดสรร งปม.'!$B$25 -> 210
B9: รายการจ่าย | C9: ='จัดสรร งปม.'!$C$25 -> สำรอง 1
A10: รหัส | B10: วันที่ | C10: ชื่อผู้ขอใช้ | D10: แผนก/งาน | E10: ปวช. | F10: ปวส. | G10: ระยะสั้น | H10: อุดหนุน | I10: หนังสือ | J10: เครื่องแบบ | K10: กิจกรรม | L10: อุปกรณ์ | M10: เครื่องมือ | N10: ทั่วไป | O10: =+O4 -> โครงการ | P10: =+P4 -> เงินนอกงบ | Q10: เงินรายได้ | R10: เงินรับฝาก | S10: รวม
A11: 001 | S11: =SUM(E11:R11) -> 0
A12: 002 | S12: =SUM(E12:R12) -> 0
A13: 003 | S13: =SUM(E13:R13) -> 0
A14: 004 | S14: =SUM(E14:R14) -> 0
A15: 005 | S15: =SUM(E15:R15) -> 0
A16: 006 | S16: =SUM(E16:R16) -> 0
A17: 007 | S17: =SUM(E17:R17) -> 0
A18: 008 | S18: =SUM(E18:R18) -> 0
A19: 009 | S19: =SUM(E19:R19) -> 0
A20: 010 | S20: =SUM(E20:R20) -> 0
A21: 011 | S21: =SUM(E21:R21) -> 0
A22: 012 | S22: =SUM(E22:R22) -> 0
... A45: 035 | S45: =SUM(E45:R45) -> 0

Sheet 211
A1: กลับไปที่หน้าจัดสรร งปม.
E2: =Note!$B$1 -> วิทยาลัยการอาชีพนวมินทราชินีแม่ฮ่องสอน
E3: เงินงบประมาณ | H3: เงินอุดหนุน | O3: งบรายจ่ายอื่น | Q3: เงิน บกศ. | S3: รวม
E4: ปวช. | F4: ปวส. | G4: ระยะสั้น | H4: จัดการเรียน | I4: หนังสือ | J4: เครื่องแบบ | K4: กิจกรรม | L4: อุปกรณ์ | M4: เครื่องมือ | N4: ทั่วไป | O4: โครงการ | P4: เงินนอกงบ | Q4: เงินรายได้ | R4: เงินรับฝาก
D5: ได้รับมา | E5: ='จัดสรร งปม.'!D26 -> 0 | F5: ='จัดสรร งปม.'!E26 -> 0 | G5: ='จัดสรร งปม.'!F26 -> 0 | H5: ='จัดสรร งปม.'!G26 -> 0 | I5: ='จัดสรร งปม.'!H26 -> 0 | J5: ='จัดสรร งปม.'!I26 -> 0 | K5: ='จัดสรร งปม.'!J26 -> 0 | L5: ='จัดสรร งปม.'!K26 -> 0 | N5: ='จัดสรร งปม.'!L26 -> 0 | P5: ='จัดสรร งปม.'!N26 -> 0 | Q5: ='จัดสรร งปม.'!P26 -> 0 | R5: ='จัดสรร งปม.'!Q26 -> 0 | S5: ='จัดสรร งปม.'!R26 -> 0
D6: ใช้ไปแล้ว | E6: =SUM(E11:E45) -> 0 | F6: =SUM(F11:F45) -> 0 | G6: =SUM(G11:G45) -> 0 | H6: =SUM(H11:H45) -> 0 | I6: =SUM(I11:I45) -> 0 | J6: =SUM(J11:J45) -> 0 | K6: =SUM(K11:K45) -> 0 | L6: =SUM(L11:L45) -> 0 | N6: =SUM(N11:N45) -> 0 | P6: =SUM(P11:P45) -> 0 | Q6: =SUM(Q11:Q45) -> 0 | R6: =SUM(R11:R45) -> 0 | S6: =SUM(S11:S45) -> 0
B7: งบดำเนินงาน (ค่าตอบแทน) | D7: เหลือ | E7: =E5-E6 -> 0 | F7: =F5-F6 -> 0 | G7: =G5-G6 -> 0 | H7: =H5-H6 -> 0 | I7: =I5-I6 -> 0 | J7: =J5-J6 -> 0 | K7: =K5-K6 -> 0 | L7: =L5-L6 -> 0 | N7: =N5-N6 -> 0 | P7: =P5-P6 -> 0 | Q7: =Q5-Q6 -> 0 | R7: =R5-R6 -> 0 | S7: =S5-S6 -> 0
B8: รหัสรายการจ่าย | C8: ='จัดสรร งปม.'!$B$26 -> 211
B9: รายการจ่าย | C9: ='จัดสรร งปม.'!$C$26 -> สำรอง 2
A10: รหัส | B10: วันที่ | C10: ชื่อผู้ขอใช้ | D10: แผนก/งาน | E10: ปวช. | F10: ปวส. | G10: ระยะสั้น | H10: อุดหนุน | I10: หนังสือ | J10: เครื่องแบบ | K10: กิจกรรม | L10: อุปกรณ์ | M10: เครื่องมือ | N10: ทั่วไป | O10: =+O4 -> โครงการ | P10: =+P4 -> เงินนอกงบ | Q10: เงินรายได้ | R10: เงินรับฝาก | S10: รวม
A11: 001 | S11: =SUM(E11:R11) -> 0
A12: 002 | S12: =SUM(E12:R12) -> 0
A13: 003 | S13: =SUM(E13:R13) -> 0
A14: 004 | S14: =SUM(E14:R14) -> 0
A15: 005 | S15: =SUM(E15:R15) -> 0
A16: 006 | S16: =SUM(E16:R16) -> 0
A17: 007 | S17: =SUM(E17:R17) -> 0
A18: 008 | S18: =SUM(E18:R18) -> 0
A19: 009 | S19: =SUM(E19:R19) -> 0
A20: 010 | S20: =SUM(E20:R20) -> 0
A21: 011 | S21: =SUM(E21:R21) -> 0
A22: 012 | S22: =SUM(E22:R22) -> 0
... A45: 035 | S45: =SUM(E45:R45) -> 0

Sheet 212
A1: กลับไปที่หน้าจัดสรร งปม.
E2: =Note!$B$1 -> วิทยาลัยการอาชีพนวมินทราชินีแม่ฮ่องสอน
E3: เงินงบประมาณ | H3: เงินอุดหนุน | O3: งบรายจ่ายอื่น | Q3: เงิน บกศ. | S3: รวม
E4: ปวช. | F4: ปวส. | G4: ระยะสั้น | H4: จัดการเรียน | I4: หนังสือ | J4: เครื่องแบบ | K4: กิจกรรม | L4: อุปกรณ์ | M4: เครื่องมือ | N4: ทั่วไป | O4: โครงการ | P4: เงินนอกงบ | Q4: เงินรายได้ | R4: เงินรับฝาก
D5: ได้รับมา | E5: ='จัดสรร งปม.'!D27 -> 0 | F5: ='จัดสรร งปม.'!E27 -> 0 | G5: ='จัดสรร งปม.'!F27 -> 0 | H5: ='จัดสรร งปม.'!G27 -> 0 | I5: ='จัดสรร งปม.'!H27 -> 0 | J5: ='จัดสรร งปม.'!I27 -> 0 | K5: ='จัดสรร งปม.'!J27 -> 0 | L5: ='จัดสรร งปม.'!K27 -> 0 | N5: ='จัดสรร งปม.'!L27 -> 0 | P5: ='จัดสรร งปม.'!N27 -> 0 | Q5: ='จัดสรร งปม.'!P27 -> 0 | R5: ='จัดสรร งปม.'!Q27 -> 0 | S5: ='จัดสรร งปม.'!R27 -> 0
D6: ใช้ไปแล้ว | E6: =SUM(E11:E45) -> 0 | F6: =SUM(F11:F45) -> 0 | G6: =SUM(G11:G45) -> 0 | H6: =SUM(H11:H45) -> 0 | I6: =SUM(I11:I45) -> 0 | J6: =SUM(J11:J45) -> 0 | K6: =SUM(K11:K45) -> 0 | L6: =SUM(L11:L45) -> 0 | N6: =SUM(N11:N45) -> 0 | P6: =SUM(P11:P45) -> 0 | Q6: =SUM(Q11:Q45) -> 0 | R6: =SUM(R11:R45) -> 0 | S6: =SUM(S11:S45) -> 0
B7: งบดำเนินงาน (ค่าตอบแทน) | D7: เหลือ | E7: =E5-E6 -> 0 | F7: =F5-F6 -> 0 | G7: =G5-G6 -> 0 | H7: =H5-H6 -> 0 | I7: =I5-I6 -> 0 | J7: =J5-J6 -> 0 | K7: =K5-K6 -> 0 | L7: =L5-L6 -> 0 | N7: =N5-N6 -> 0 | P7: =P5-P6 -> 0 | Q7: =Q5-Q6 -> 0 | R7: =R5-R6 -> 0 | S7: =S5-S6 -> 0
B8: รหัสรายการจ่าย | C8: ='จัดสรร งปม.'!$B$27 -> 212
B9: รายการจ่าย | C9: ='จัดสรร งปม.'!$C$27 -> สำรอง 3
A10: รหัส | B10: วันที่ | C10: ชื่อผู้ขอใช้ | D10: แผนก/งาน | E10: ปวช. | F10: ปวส. | G10: ระยะสั้น | H10: อุดหนุน | I10: หนังสือ | J10: เครื่องแบบ | K10: กิจกรรม | L10: อุปกรณ์ | M10: เครื่องมือ | N10: ทั่วไป | O10: =+O4 -> โครงการ | P10: =+P4 -> เงินนอกงบ | Q10: เงินรายได้ | R10: เงินรับฝาก | S10: รวม
A11: 001 | S11: =SUM(E11:R11) -> 0
A12: 002 | S12: =SUM(E12:R12) -> 0
A13: 003 | S13: =SUM(E13:R13) -> 0
A14: 004 | S14: =SUM(E14:R14) -> 0
A15: 005 | S15: =SUM(E15:R15) -> 0
A16: 006 | S16: =SUM(E16:R16) -> 0
A17: 007 | S17: =SUM(E17:R17) -> 0
A18: 008 | S18: =SUM(E18:R18) -> 0
A19: 009 | S19: =SUM(E19:R19) -> 0
A20: 010 | S20: =SUM(E20:R20) -> 0
A21: 011 | S21: =SUM(E21:R21) -> 0
A22: 012 | S22: =SUM(E22:R22) -> 0
... A45: 035 | S45: =SUM(E45:R45) -> 0

Sheet 213
A1: กลับไปที่หน้าจัดสรร งปม.
E2: =Note!$B$1 -> วิทยาลัยการอาชีพนวมินทราชินีแม่ฮ่องสอน
E3: เงินงบประมาณ | H3: เงินอุดหนุน | O3: งบรายจ่ายอื่น | Q3: เงิน บกศ. | S3: รวม
E4: ปวช. | F4: ปวส. | G4: ระยะสั้น | H4: จัดการเรียน | I4: หนังสือ | J4: เครื่องแบบ | K4: กิจกรรม | L4: อุปกรณ์ | M4: เครื่องมือ | N4: ทั่วไป | O4: โครงการ | P4: เงินนอกงบ | Q4: เงินรายได้ | R4: เงินรับฝาก
D5: ได้รับมา | E5: ='จัดสรร งปม.'!D28 -> 0 | F5: ='จัดสรร งปม.'!E28 -> 0 | G5: ='จัดสรร งปม.'!F28 -> 0 | H5: ='จัดสรร งปม.'!G28 -> 0 | I5: ='จัดสรร งปม.'!H28 -> 0 | J5: ='จัดสรร งปม.'!I28 -> 0 | K5: ='จัดสรร งปม.'!J28 -> 0 | L5: ='จัดสรร งปม.'!K28 -> 0 | N5: ='จัดสรร งปม.'!L28 -> 0 | P5: ='จัดสรร งปม.'!N28 -> 0 | Q5: ='จัดสรร งปม.'!P28 -> 0 | R5: ='จัดสรร งปม.'!Q28 -> 0 | S5: ='จัดสรร งปม.'!R28 -> 0
D6: ใช้ไปแล้ว | E6: =SUM(E11:E45) -> 0 | F6: =SUM(F11:F45) -> 0 | G6: =SUM(G11:G45) -> 0 | H6: =SUM(H11:H45) -> 0 | I6: =SUM(I11:I45) -> 0 | J6: =SUM(J11:J45) -> 0 | K6: =SUM(K11:K45) -> 0 | L6: =SUM(L11:L45) -> 0 | N6: =SUM(N11:N45) -> 0 | P6: =SUM(P11:P45) -> 0 | Q6: =SUM(Q11:Q45) -> 0 | R6: =SUM(R11:R45) -> 0 | S6: =SUM(S11:S45) -> 0
B7: งบดำเนินงาน (ค่าตอบแทน) | D7: เหลือ | E7: =E5-E6 -> 0 | F7: =F5-F6 -> 0 | G7: =G5-G6 -> 0 | H7: =H5-H6 -> 0 | I7: =I5-I6 -> 0 | J7: =J5-J6 -> 0 | K7: =K5-K6 -> 0 | L7: =L5-L6 -> 0 | N7: =N5-N6 -> 0 | P7: =P5-P6 -> 0 | Q7: =Q5-Q6 -> 0 | R7: =R5-R6 -> 0 | S7: =S5-S6 -> 0
B8: รหัสรายการจ่าย | C8: ='จัดสรร งปม.'!$B$28 -> 213
B9: รายการจ่าย | C9: ='จัดสรร งปม.'!$C$28 -> สำรอง 4
A10: รหัส | B10: วันที่ | C10: ชื่อผู้ขอใช้ | D10: แผนก/งาน | E10: ปวช. | F10: ปวส. | G10: ระยะสั้น | H10: อุดหนุน | I10: หนังสือ | J10: เครื่องแบบ | K10: กิจกรรม | L10: อุปกรณ์ | M10: เครื่องมือ | N10: ทั่วไป | O10: =+O4 -> โครงการ | P10: =+P4 -> เงินนอกงบ | Q10: เงินรายได้ | R10: เงินรับฝาก | S10: รวม
A11: 001 | S11: =SUM(E11:R11) -> 0
A12: 002 | S12: =SUM(E12:R12) -> 0
A13: 003 | S13: =SUM(E13:R13) -> 0
A14: 004 | S14: =SUM(E14:R14) -> 0
A15: 005 | S15: =SUM(E15:R15) -> 0
A16: 006 | S16: =SUM(E16:R16) -> 0
A17: 007 | S17: =SUM(E17:R17) -> 0
A18: 008 | S18: =SUM(E18:R18) -> 0
A19: 009 | S19: =SUM(E19:R19) -> 0
A20: 010 | S20: =SUM(E20:R20) -> 0
A21: 011 | S21: =SUM(E21:R21) -> 0
A22: 012 | S22: =SUM(E22:R22) -> 0
... A45: 035 | S45: =SUM(E45:R45) -> 0

Sheet 214
A1: กลับไปที่หน้าจัดสรร งปม.
E2: =Note!$B$1 -> วิทยาลัยการอาชีพนวมินทราชินีแม่ฮ่องสอน
E3: เงินงบประมาณ | H3: เงินอุดหนุน | O3: งบรายจ่ายอื่น | Q3: เงิน บกศ. | S3: รวม
E4: ปวช. | F4: ปวส. | G4: ระยะสั้น | H4: จัดการเรียน | I4: หนังสือ | J4: เครื่องแบบ | K4: กิจกรรม | L4: อุปกรณ์ | M4: เครื่องมือ | N4: ทั่วไป | O4: โครงการ | P4: เงินนอกงบ | Q4: เงินรายได้ | R4: เงินรับฝาก
